<?xml version="1.0" ?>
<!-- =================================================================================== -->
<!-- |    This document was autogenerated by xacro from urdf/robot/v10.urdf.xacro      | -->
<!-- |    EDITING THIS FILE BY HAND IS NOT RECOMMENDED                                 | -->
<!-- =================================================================================== -->
<robot name="openarm">
  <link name="world"/>
  <joint name="openarm_body_world_joint" type="fixed">
    <parent link="world"/>
    <child link="openarm_body_link0"/>
    <origin rpy="0 0 0" xyz="0 0 0"/>
  </joint>
  <link name="openarm_body_link0">
    <visual name="openarm_body_link0_visual">
      <origin rpy="0.0 0.0 0.0" xyz="0.0 0.0 0.0"/>
      <geometry>
        <mesh filename="./meshes/body/v10/visual/body_link0.dae" scale="0.001 0.001 0.001"/>
      </geometry>
    </visual>
    <collision name="openarm_body_link0_collision">
      <origin rpy="0.0 0.0 0.0" xyz="0.0 0.0 0.0"/>
      <geometry>
        <mesh filename="./meshes/body/v10/collision/body_link0_symp.stl" scale="0.001 0.001 0.001"/>
        <!-- <mesh filename="${mesh_prefix}/meshes/arm/${arm_type}/collision/${name}.stl" scale="0.001 0.001 0.001" /> -->
      </geometry>
    </collision>
    <inertial>
      <origin rpy="0.0 0.0 0.0" xyz="0.0 0.0 0.0"/>
      <mass value="13.89"/>
      <inertia ixx="1.653" ixy="0.0" ixz="0.0" iyy="1.653" iyz="0.0" izz="0.051"/>
    </inertial>
  </link>
  <link name="head_base_link">
    <inertial>
      <origin rpy="0 0 0" xyz="0.0026203635436640627 9.06133544157364e-15 0.003991777276961831"/>
      <mass value="0.15752081080534908"/>
      <inertia ixx="4.8e-05" ixy="0.0" ixz="-0.0" iyy="2.6e-05" iyz="-0.0" izz="7.3e-05"/>
    </inertial>
    <visual>
      <origin rpy="0 0 0" xyz="0 0 0"/>
      <geometry>
        <mesh filename="./meshes/head/visual/head_base_link.stl" scale="0.001 0.001 0.001"/>
      </geometry>
    </visual>
    <collision>
      <origin rpy="0 0 0" xyz="0 0 0"/>
      <geometry>
        <mesh filename="./meshes/head/visual/head_base_link.stl" scale="0.001 0.001 0.001"/>
      </geometry>
    </collision>
  </link>
  <link name="pitch_motor_rotor_1">
    <inertial>
      <origin rpy="0 0 0" xyz="-0.003737234840155715 4.216739847323039e-09 -7.936074089553991e-10"/>
      <mass value="0.04790732030032129"/>
      <inertia ixx="8e-06" ixy="0.0" ixz="-0.0" iyy="4e-06" iyz="-0.0" izz="4e-06"/>
    </inertial>
    <visual>
      <origin rpy="0 0 0" xyz="0.0125 0.0 -0.0415"/>
      <geometry>
        <mesh filename="./meshes/head/visual/pitch_motor_rotor_1.stl" scale="0.001 0.001 0.001"/>
      </geometry>
    </visual>
    <collision>
      <origin rpy="0 0 0" xyz="0.0125 0.0 -0.0415"/>
      <geometry>
        <mesh filename="./meshes/head/visual/pitch_motor_rotor_1.stl" scale="0.001 0.001 0.001"/>
      </geometry>
    </collision>
  </link>
  <link name="pitch_motor_case_1">
    <inertial>
      <origin rpy="0 0 0" xyz="-0.02365457038760069 0.0015631002328282656 -0.01903835002780154"/>
      <mass value="0.7274632351161315"/>
      <inertia ixx="0.000313" ixy="1e-06" ixz="2e-06" iyy="0.000249" iyz="-1e-06" izz="0.000249"/>
    </inertial>
    <visual>
      <origin rpy="0 0 0" xyz="-0.025 0.001656 -0.060428"/>
      <geometry>
        <mesh filename="./meshes/head/visual/pitch_motor_case_1.stl" scale="0.001 0.001 0.001"/>
      </geometry>
    </visual>
    <collision>
      <origin rpy="0 0 0" xyz="-0.025 0.001656 -0.060428"/>
      <geometry>
        <mesh filename="./meshes/head/visual/pitch_motor_case_1.stl" scale="0.001 0.001 0.001"/>
      </geometry>
    </collision>
  </link>
  <link name="pitch_motor_case_2">
    <inertial>
      <origin rpy="0 0 0" xyz="0.013290752155116443 -0.013435233719801938 0.02365457038760796"/>
      <mass value="0.7274632351161315"/>
      <inertia ixx="0.000248" ixy="0.0" ixz="-2e-06" iyy="0.00025" iyz="-0.0" izz="0.000313"/>
    </inertial>
    <visual>
      <origin rpy="0 0 0" xyz="0.013435 -0.013435 -0.0785"/>
      <geometry>
        <mesh filename="./meshes/head/visual/pitch_motor_case_2.stl" scale="0.001 0.001 0.001"/>
      </geometry>
    </visual>
    <collision>
      <origin rpy="0 0 0" xyz="0.013435 -0.013435 -0.0785"/>
      <geometry>
        <mesh filename="./meshes/head/visual/pitch_motor_case_2.stl" scale="0.001 0.001 0.001"/>
      </geometry>
    </collision>
  </link>
  <link name="pitch_motor_rotor_2">
    <inertial>
      <origin rpy="0 0 0" xyz="2.1025221699785333e-09 3.740338630878902e-09 0.003737234840162862"/>
      <mass value="0.04790732030032129"/>
      <inertia ixx="4e-06" ixy="-0.0" ixz="-0.0" iyy="4e-06" iyz="-0.0" izz="8e-06"/>
    </inertial>
    <visual>
      <origin rpy="0 0 0" xyz="0.0 -0.0 -0.116"/>
      <geometry>
        <mesh filename="./meshes/head/visual/pitch_motor_rotor_2.stl" scale="0.001 0.001 0.001"/>
      </geometry>
    </visual>
    <collision>
      <origin rpy="0 0 0" xyz="0.0 -0.0 -0.116"/>
      <geometry>
        <mesh filename="./meshes/head/visual/pitch_motor_rotor_2.stl" scale="0.001 0.001 0.001"/>
      </geometry>
    </collision>
  </link>
  <link name="Body1_1">
    <inertial>
      <origin rpy="0 0 0" xyz="-0.006750000000004441 0.0034904296859870794 0.0025342015065007995"/>
      <mass value="0.5149600630136327"/>
      <inertia ixx="0.000182" ixy="-0.0" ixz="-0.0" iyy="0.001854" iyz="0.0" izz="0.002032"/>
    </inertial>
    <visual>
      <origin rpy="0 0 0" xyz="-0.00675 -0.011691 -0.1245"/>
      <geometry>
        <mesh filename="./meshes/head/visual/Body1_1.stl" scale="0.001 0.001 0.001"/>
      </geometry>
    </visual>
    <collision>
      <origin rpy="0 0 0" xyz="-0.00675 -0.011691 -0.1245"/>
      <geometry>
        <mesh filename="./meshes/head/visual/Body1_1.stl" scale="0.001 0.001 0.001"/>
      </geometry>
    </collision>
  </link>
  <link name="camera">
    <inertial>
      <origin rpy="0 0 0" xyz="-4.476419235288631e-15 -0.016096492802925383 0.014964449995599954"/>
      <mass value="1.2916673327792563"/>
      <inertia ixx="0.000206" ixy="-0.0" ixz="0.0" iyy="0.003218" iyz="-1e-06" izz="0.003236"/>
    </inertial>
    <visual>
      <origin rpy="0 0 0" xyz="0.0 -0.047 -0.1295"/>
      <geometry>
        <mesh filename="./meshes/head/visual/camera.stl" scale="0.001 0.001 0.001"/>
      </geometry>
    </visual>
    <collision>
      <origin rpy="0 0 0" xyz="0.0 -0.047 -0.1295"/>
      <geometry>
        <mesh filename="./meshes/head/visual/camera.stl" scale="0.001 0.001 0.001"/>
      </geometry>
    </collision>
  </link>
  <joint name="openarm_head_base_to_pitch_case_1" type="fixed">
    <origin rpy="0 0 0" xyz="0.025 -0.002 0.06"/>
    <parent link="head_base_link"/>
    <child link="pitch_motor_case_1"/>
  </joint>
  <joint name="openarm_head_pitch" type="revolute">
    <origin rpy="0 0 0" xyz="-0.0375 0.001656 -0.018928"/>
    <parent link="pitch_motor_case_1"/>
    <child link="pitch_motor_rotor_1"/>
    <axis xyz="-1.0 -0.0 -0.0"/>
    <limit effort="10.0" lower="0.0" upper="1.5708" velocity="10.0"/>
  </joint>
  <joint name="openarm_head_pitch_to_yaw_case" type="fixed">
    <origin rpy="0 0 0" xyz="-0.000935 0.0134 0.037"/>
    <parent link="pitch_motor_rotor_1"/>
    <child link="pitch_motor_case_2"/>
  </joint>
  <joint name="openarm_head_yaw" type="revolute">
    <origin rpy="0 0 0" xyz="0.013435 -0.013435 0.0375"/>
    <parent link="pitch_motor_case_2"/>
    <child link="pitch_motor_rotor_2"/>
    <axis xyz="-0.0 0.0 1.0"/>
    <limit effort="10.0" lower="-1.5708" upper="1.5708" velocity="10.0"/>
  </joint>
  <joint name="openarm_head_yaw_to_body1" type="fixed">
    <origin rpy="0 0 0" xyz="0.00675 0.011691 0.0085"/>
    <parent link="pitch_motor_rotor_2"/>
    <child link="Body1_1"/>
  </joint>
  <joint name="openarm_head_body1_to_body1_inner" type="fixed">
    <origin rpy="0 0 0" xyz="-0.00675 0.035309 0.005"/>
    <parent link="Body1_1"/>
    <child link="camera"/>
  </joint>
  <joint name="openarm_head_mount" type="fixed">
    <parent link="openarm_body_link0"/>
    <child link="head_base_link"/>
    <origin rpy="0 0 -1.5708" xyz="-0.0025 0 0.750"/>
  </joint>
  <joint name="openarm_left_openarm_body_link0_joint" type="fixed">
    <parent link="openarm_body_link0"/>
    <child link="openarm_left_link0"/>
    <origin rpy="-1.5708 0 0" xyz="0.0 0.031 0.698"/>
  </joint>
  <link name="openarm_left_link0">
    <visual name="openarm_left_link0_visual">
      <origin rpy="0.0 0.0 0.0" xyz="0.0 0.0 0.0"/>
      <geometry>
        <mesh filename="./meshes/arm/v10/visual/link0.dae" scale="0.001 -0.001 0.001"/>
      </geometry>
    </visual>
    <collision name="openarm_left_link0_collision">
      <origin rpy="0.0 0.0 0.0" xyz="0.0 0.0 0.0"/>
      <geometry>
        <mesh filename="./meshes/arm/v10/collision/link0_symp.stl" scale="0.001 -0.001 0.001"/>
        <!-- <mesh filename="${mesh_prefix}/meshes/arm/${arm_type}/collision/${name}.stl" scale="0.001 0.001 0.001" /> -->
      </geometry>
    </collision>
    <inertial>
      <origin rpy="0.0 0.0 0.0" xyz="-0.0009483362816297526 -0.0001580207020448382 0.03076860287587199"/>
      <mass value="1.1432284943239561"/>
      <inertia ixx="0.001128" ixy="-4e-06" ixz="-3.3e-05" iyy="0.000962" iyz="-7e-06" izz="0.00147"/>
    </inertial>
  </link>
  <link name="openarm_left_link1">
    <visual name="openarm_left_link1_visual">
      <origin rpy="0.0 0.0 0.0" xyz="-0.0 0.0 -0.0625"/>
      <geometry>
        <mesh filename="./meshes/arm/v10/visual/link1.dae" scale="0.001 -0.001 0.001"/>
      </geometry>
    </visual>
    <collision name="openarm_left_link1_collision">
      <origin rpy="0.0 0.0 0.0" xyz="-0.0 0.0 -0.0625"/>
      <geometry>
        <mesh filename="./meshes/arm/v10/collision/link1_symp.stl" scale="0.001 -0.001 0.001"/>
        <!-- <mesh filename="${mesh_prefix}/meshes/arm/${arm_type}/collision/${name}.stl" scale="0.001 0.001 0.001" /> -->
      </geometry>
    </collision>
    <inertial>
      <origin rpy="0.0 0.0 0.0" xyz="0.0011467657911800769 -3.319987657026362e-05 0.05395284380736254"/>
      <mass value="1.1416684646202298"/>
      <inertia ixx="0.001567" ixy="-1e-06" ixz="-2.9e-05" iyy="0.001273" iyz="1e-06" izz="0.001016"/>
    </inertial>
  </link>
  <joint name="openarm_left_joint1" type="revolute">
    <origin rpy="0 0 0" xyz="0.0 0.0 0.0625"/>
    <parent link="openarm_left_link0"/>
    <child link="openarm_left_link1"/>
    <axis xyz="0 0 1"/>
    <limit effort="40" lower="-3.490659" upper="1.3962629999999998" velocity="16.754666"/>
  </joint>
  <link name="openarm_left_link2">
    <visual name="openarm_left_link2_visual">
      <origin rpy="0.0 0.0 0.0" xyz="0.0301 0.0 -0.1225"/>
      <geometry>
        <mesh filename="./meshes/arm/v10/visual/link2.dae" scale="0.001 -0.001 0.001"/>
      </geometry>
    </visual>
    <collision name="openarm_left_link2_collision">
      <origin rpy="0.0 0.0 0.0" xyz="0.0301 0.0 -0.1225"/>
      <geometry>
        <mesh filename="./meshes/arm/v10/collision/link2_symp.stl" scale="0.001 -0.001 0.001"/>
        <!-- <mesh filename="${mesh_prefix}/meshes/arm/${arm_type}/collision/${name}.stl" scale="0.001 0.001 0.001" /> -->
      </geometry>
    </collision>
    <inertial>
      <origin rpy="0.0 0.0 0.0" xyz="0.00839629182351943 2.0145102027597523e-08 0.03256649300522363"/>
      <mass value="0.2775092746011571"/>
      <inertia ixx="0.000359" ixy="1e-06" ixz="-0.000109" iyy="0.000376" iyz="1e-06" izz="0.000232"/>
    </inertial>
  </link>
  <joint name="openarm_left_joint2" type="revolute">
    <origin rpy="-1.57079632679 0 0" xyz="-0.0301 0.0 0.06"/>
    <parent link="openarm_left_link1"/>
    <child link="openarm_left_link2"/>
    <axis xyz="-1 0 0"/>
    <limit effort="40" lower="-3.3161253267948965" upper="0.17453267320510335" velocity="16.754666"/>
  </joint>
  <link name="openarm_left_link3">
    <visual name="openarm_left_link3_visual">
      <origin rpy="0.0 0.0 0.0" xyz="-0.0 -0.0 -0.18875"/>
      <geometry>
        <mesh filename="./meshes/arm/v10/visual/link3.dae" scale="0.001 -0.001 0.001"/>
      </geometry>
    </visual>
    <collision name="openarm_left_link3_collision">
      <origin rpy="0.0 0.0 0.0" xyz="-0.0 -0.0 -0.18875"/>
      <geometry>
        <mesh filename="./meshes/arm/v10/collision/link3_symp.stl" scale="0.001 -0.001 0.001"/>
        <!-- <mesh filename="${mesh_prefix}/meshes/arm/${arm_type}/collision/${name}.stl" scale="0.001 0.001 0.001" /> -->
      </geometry>
    </collision>
    <inertial>
      <origin rpy="0.0 0.0 0.0" xyz="-0.002104752099628911 -0.0005549085042607548 0.09047470545721961"/>
      <mass value="1.073863338202347"/>
      <inertia ixx="0.004372" ixy="1e-06" ixz="1.1e-05" iyy="0.004319" iyz="-3.6e-05" izz="0.000661"/>
    </inertial>
  </link>
  <joint name="openarm_left_joint3" type="revolute">
    <origin rpy="0 0 0" xyz="0.0301 0.0 0.06625"/>
    <parent link="openarm_left_link2"/>
    <child link="openarm_left_link3"/>
    <axis xyz="0 0 1"/>
    <limit effort="27" lower="-1.570796" upper="1.570796" velocity="5.445426"/>
  </joint>
  <link name="openarm_left_link4">
    <visual name="openarm_left_link4_visual">
      <origin rpy="0.0 0.0 0.0" xyz="0.0 -0.0315 -0.3425"/>
      <geometry>
        <mesh filename="./meshes/arm/v10/visual/link4.dae" scale="0.001 0.001 0.001"/>
      </geometry>
    </visual>
    <collision name="openarm_left_link4_collision">
      <origin rpy="0.0 0.0 0.0" xyz="0.0 -0.0315 -0.3425"/>
      <geometry>
        <mesh filename="./meshes/arm/v10/collision/link4_symp.stl" scale="0.001 0.001 0.001"/>
        <!-- <mesh filename="${mesh_prefix}/meshes/arm/${arm_type}/collision/${name}.stl" scale="0.001 0.001 0.001" /> -->
      </geometry>
    </collision>
    <inertial>
      <origin rpy="0.0 0.0 0.0" xyz="-0.0029006831074562967 -0.03030575826634669 0.06339637422196209"/>
      <mass value="0.6348534566833373"/>
      <inertia ixx="0.000623" ixy="-1e-06" ixz="-1.9e-05" iyy="0.000511" iyz="3.8e-05" izz="0.000334"/>
    </inertial>
  </link>
  <joint name="openarm_left_joint4" type="revolute">
    <origin rpy="0 0 0" xyz="-0.0 0.0315 0.15375"/>
    <parent link="openarm_left_link3"/>
    <child link="openarm_left_link4"/>
    <axis xyz="0 1 0"/>
    <limit effort="27" lower="0.0" upper="2.443461" velocity="5.445426"/>
  </joint>
  <link name="openarm_left_link5">
    <visual name="openarm_left_link5_visual">
      <origin rpy="0.0 0.0 0.0" xyz="-0.0 -0.0 -0.438"/>
      <geometry>
        <mesh filename="./meshes/arm/v10/visual/link5.dae" scale="0.001 -0.001 0.001"/>
      </geometry>
    </visual>
    <collision name="openarm_left_link5_collision">
      <origin rpy="0.0 0.0 0.0" xyz="-0.0 -0.0 -0.438"/>
      <geometry>
        <mesh filename="./meshes/arm/v10/collision/link5_symp.stl" scale="0.001 -0.001 0.001"/>
        <!-- <mesh filename="${mesh_prefix}/meshes/arm/${arm_type}/collision/${name}.stl" scale="0.001 0.001 0.001" /> -->
      </geometry>
    </collision>
    <inertial>
      <origin rpy="0.0 0.0 0.0" xyz="-0.003049665024221911 -0.0008866902457326625 0.043079803024980934"/>
      <mass value="0.6156588026168502"/>
      <inertia ixx="0.000423" ixy="-8e-06" ixz="6e-06" iyy="0.000445" iyz="-6e-06" izz="0.000324"/>
    </inertial>
  </link>
  <joint name="openarm_left_joint5" type="revolute">
    <origin rpy="0 0 0" xyz="0.0 -0.0315 0.0955"/>
    <parent link="openarm_left_link4"/>
    <child link="openarm_left_link5"/>
    <axis xyz="0 0 1"/>
    <limit effort="7" lower="-1.570796" upper="1.570796" velocity="20.943946"/>
  </joint>
  <link name="openarm_left_link6">
    <visual name="openarm_left_link6_visual">
      <origin rpy="0.0 0.0 0.0" xyz="-0.0375 -0.0 -0.5585"/>
      <geometry>
        <mesh filename="./meshes/arm/v10/visual/link6.dae" scale="0.001 -0.001 0.001"/>
      </geometry>
    </visual>
    <collision name="openarm_left_link6_collision">
      <origin rpy="0.0 0.0 0.0" xyz="-0.0375 -0.0 -0.5585"/>
      <geometry>
        <mesh filename="./meshes/arm/v10/collision/link6_symp.stl" scale="0.001 -0.001 0.001"/>
        <!-- <mesh filename="${mesh_prefix}/meshes/arm/${arm_type}/collision/${name}.stl" scale="0.001 0.001 0.001" /> -->
      </geometry>
    </collision>
    <inertial>
      <origin rpy="0.0 0.0 0.0" xyz="-0.037136587005447405 -0.00033230528343419053 -9.498374522309838e-05"/>
      <mass value="0.475202773187987"/>
      <inertia ixx="0.000143" ixy="1e-06" ixz="1e-06" iyy="0.000157" iyz="1e-06" izz="0.000159"/>
    </inertial>
  </link>
  <joint name="openarm_left_joint6" type="revolute">
    <origin rpy="0 0 0" xyz="0.0375 0.0 0.1205"/>
    <parent link="openarm_left_link5"/>
    <child link="openarm_left_link6"/>
    <axis xyz="1 0 0"/>
    <limit effort="7" lower="-0.785398" upper="0.785398" velocity="20.943946"/>
  </joint>
  <link name="openarm_left_link7">
    <visual name="openarm_left_link7_visual">
      <origin rpy="0.0 0.0 0.0" xyz="0.0 -0.0 -0.5585"/>
      <geometry>
        <mesh filename="./meshes/arm/v10/visual/link7.dae" scale="0.001 -0.001 0.001"/>
      </geometry>
    </visual>
    <collision name="openarm_left_link7_collision">
      <origin rpy="0.0 0.0 0.0" xyz="0.0 -0.0 -0.5585"/>
      <geometry>
        <mesh filename="./meshes/arm/v10/collision/link7_symp.stl" scale="0.001 -0.001 0.001"/>
        <!-- <mesh filename="${mesh_prefix}/meshes/arm/${arm_type}/collision/${name}.stl" scale="0.001 0.001 0.001" /> -->
      </geometry>
    </collision>
    <inertial>
      <origin rpy="0.0 0.0 0.0" xyz="6.875510271106056e-05 -0.01266175250761268 0.06951945409987448"/>
      <mass value="0.4659771327380578"/>
      <inertia ixx="0.000639" ixy="1e-06" ixz="1e-06" iyy="0.000497" iyz="8.9e-05" izz="0.000342"/>
    </inertial>
  </link>
  <joint name="openarm_left_joint7" type="revolute">
    <origin rpy="0 0 0" xyz="-0.0375 0.0 0.0"/>
    <parent link="openarm_left_link6"/>
    <child link="openarm_left_link7"/>
    <axis xyz="0 -1 0"/>
    <limit effort="7" lower="-1.570796" upper="1.570796" velocity="20.943946"/>
  </joint>
  <!-- <link name="${prefix}link8"/>

    <joint name="${prefix}joint8" type="fixed">
      <xacro:openarm-kinematics name="joint8" config="${kinematics}" />
      <parent link="${prefix}link7" />
      <child link="${prefix}link8" />
    </joint> -->
  <joint name="openarm_right_openarm_body_link0_joint" type="fixed">
    <parent link="openarm_body_link0"/>
    <child link="openarm_right_link0"/>
    <origin rpy="1.5708 0 0" xyz="0.0 -0.031 0.698"/>
  </joint>
  <link name="openarm_right_link0">
    <visual name="openarm_right_link0_visual">
      <origin rpy="0.0 0.0 0.0" xyz="0.0 0.0 0.0"/>
      <geometry>
        <mesh filename="./meshes/arm/v10/visual/link0.dae" scale="0.001 0.001 0.001"/>
      </geometry>
    </visual>
    <collision name="openarm_right_link0_collision">
      <origin rpy="0.0 0.0 0.0" xyz="0.0 0.0 0.0"/>
      <geometry>
        <mesh filename="./meshes/arm/v10/collision/link0_symp.stl" scale="0.001 0.001 0.001"/>
        <!-- <mesh filename="${mesh_prefix}/meshes/arm/${arm_type}/collision/${name}.stl" scale="0.001 0.001 0.001" /> -->
      </geometry>
    </collision>
    <inertial>
      <origin rpy="0.0 0.0 0.0" xyz="-0.0009483362816297526 0.0001580207020448382 0.03076860287587199"/>
      <mass value="1.1432284943239561"/>
      <inertia ixx="0.001128" ixy="-4e-06" ixz="-3.3e-05" iyy="0.000962" iyz="-7e-06" izz="0.00147"/>
    </inertial>
  </link>
  <link name="openarm_right_link1">
    <visual name="openarm_right_link1_visual">
      <origin rpy="0.0 0.0 0.0" xyz="-0.0 0.0 -0.0625"/>
      <geometry>
        <mesh filename="./meshes/arm/v10/visual/link1.dae" scale="0.001 0.001 0.001"/>
      </geometry>
    </visual>
    <collision name="openarm_right_link1_collision">
      <origin rpy="0.0 0.0 0.0" xyz="-0.0 0.0 -0.0625"/>
      <geometry>
        <mesh filename="./meshes/arm/v10/collision/link1_symp.stl" scale="0.001 0.001 0.001"/>
        <!-- <mesh filename="${mesh_prefix}/meshes/arm/${arm_type}/collision/${name}.stl" scale="0.001 0.001 0.001" /> -->
      </geometry>
    </collision>
    <inertial>
      <origin rpy="0.0 0.0 0.0" xyz="0.0011467657911800769 3.319987657026362e-05 0.05395284380736254"/>
      <mass value="1.1416684646202298"/>
      <inertia ixx="0.001567" ixy="-1e-06" ixz="-2.9e-05" iyy="0.001273" iyz="1e-06" izz="0.001016"/>
    </inertial>
  </link>
  <joint name="openarm_right_joint1" type="revolute">
    <origin rpy="0 0 0" xyz="0.0 0.0 0.0625"/>
    <parent link="openarm_right_link0"/>
    <child link="openarm_right_link1"/>
    <axis xyz="0 0 1"/>
    <limit effort="40" lower="-1.396263" upper="3.490659" velocity="16.754666"/>
  </joint>
  <link name="openarm_right_link2">
    <visual name="openarm_right_link2_visual">
      <origin rpy="0.0 0.0 0.0" xyz="0.0301 0.0 -0.1225"/>
      <geometry>
        <mesh filename="./meshes/arm/v10/visual/link2.dae" scale="0.001 0.001 0.001"/>
      </geometry>
    </visual>
    <collision name="openarm_right_link2_collision">
      <origin rpy="0.0 0.0 0.0" xyz="0.0301 0.0 -0.1225"/>
      <geometry>
        <mesh filename="./meshes/arm/v10/collision/link2_symp.stl" scale="0.001 0.001 0.001"/>
        <!-- <mesh filename="${mesh_prefix}/meshes/arm/${arm_type}/collision/${name}.stl" scale="0.001 0.001 0.001" /> -->
      </geometry>
    </collision>
    <inertial>
      <origin rpy="0.0 0.0 0.0" xyz="0.00839629182351943 -2.0145102027597523e-08 0.03256649300522363"/>
      <mass value="0.2775092746011571"/>
      <inertia ixx="0.000359" ixy="1e-06" ixz="-0.000109" iyy="0.000376" iyz="1e-06" izz="0.000232"/>
    </inertial>
  </link>
  <joint name="openarm_right_joint2" type="revolute">
    <origin rpy="1.57079632679 0 0" xyz="-0.0301 0.0 0.06"/>
    <parent link="openarm_right_link1"/>
    <child link="openarm_right_link2"/>
    <axis xyz="-1 0 0"/>
    <limit effort="40" lower="-0.17453267320510335" upper="3.3161253267948965" velocity="16.754666"/>
  </joint>
  <link name="openarm_right_link3">
    <visual name="openarm_right_link3_visual">
      <origin rpy="0.0 0.0 0.0" xyz="-0.0 -0.0 -0.18875"/>
      <geometry>
        <mesh filename="./meshes/arm/v10/visual/link3.dae" scale="0.001 0.001 0.001"/>
      </geometry>
    </visual>
    <collision name="openarm_right_link3_collision">
      <origin rpy="0.0 0.0 0.0" xyz="-0.0 -0.0 -0.18875"/>
      <geometry>
        <mesh filename="./meshes/arm/v10/collision/link3_symp.stl" scale="0.001 0.001 0.001"/>
        <!-- <mesh filename="${mesh_prefix}/meshes/arm/${arm_type}/collision/${name}.stl" scale="0.001 0.001 0.001" /> -->
      </geometry>
    </collision>
    <inertial>
      <origin rpy="0.0 0.0 0.0" xyz="-0.002104752099628911 0.0005549085042607548 0.09047470545721961"/>
      <mass value="1.073863338202347"/>
      <inertia ixx="0.004372" ixy="1e-06" ixz="1.1e-05" iyy="0.004319" iyz="-3.6e-05" izz="0.000661"/>
    </inertial>
  </link>
  <joint name="openarm_right_joint3" type="revolute">
    <origin rpy="0 0 0" xyz="0.0301 0.0 0.06625"/>
    <parent link="openarm_right_link2"/>
    <child link="openarm_right_link3"/>
    <axis xyz="0 0 1"/>
    <limit effort="27" lower="-1.570796" upper="1.570796" velocity="5.445426"/>
  </joint>
  <link name="openarm_right_link4">
    <visual name="openarm_right_link4_visual">
      <origin rpy="0.0 0.0 0.0" xyz="0.0 -0.0315 -0.3425"/>
      <geometry>
        <mesh filename="./meshes/arm/v10/visual/link4.dae" scale="0.001 0.001 0.001"/>
      </geometry>
    </visual>
    <collision name="openarm_right_link4_collision">
      <origin rpy="0.0 0.0 0.0" xyz="0.0 -0.0315 -0.3425"/>
      <geometry>
        <mesh filename="./meshes/arm/v10/collision/link4_symp.stl" scale="0.001 0.001 0.001"/>
        <!-- <mesh filename="${mesh_prefix}/meshes/arm/${arm_type}/collision/${name}.stl" scale="0.001 0.001 0.001" /> -->
      </geometry>
    </collision>
    <inertial>
      <origin rpy="0.0 0.0 0.0" xyz="-0.0029006831074562967 -0.03030575826634669 0.06339637422196209"/>
      <mass value="0.6348534566833373"/>
      <inertia ixx="0.000623" ixy="-1e-06" ixz="-1.9e-05" iyy="0.000511" iyz="3.8e-05" izz="0.000334"/>
    </inertial>
  </link>
  <joint name="openarm_right_joint4" type="revolute">
    <origin rpy="0 0 0" xyz="-0.0 0.0315 0.15375"/>
    <parent link="openarm_right_link3"/>
    <child link="openarm_right_link4"/>
    <axis xyz="0 1 0"/>
    <limit effort="27" lower="0.0" upper="2.443461" velocity="5.445426"/>
  </joint>
  <link name="openarm_right_link5">
    <visual name="openarm_right_link5_visual">
      <origin rpy="0.0 0.0 0.0" xyz="-0.0 -0.0 -0.438"/>
      <geometry>
        <mesh filename="./meshes/arm/v10/visual/link5.dae" scale="0.001 0.001 0.001"/>
      </geometry>
    </visual>
    <collision name="openarm_right_link5_collision">
      <origin rpy="0.0 0.0 0.0" xyz="-0.0 -0.0 -0.438"/>
      <geometry>
        <mesh filename="./meshes/arm/v10/collision/link5_symp.stl" scale="0.001 0.001 0.001"/>
        <!-- <mesh filename="${mesh_prefix}/meshes/arm/${arm_type}/collision/${name}.stl" scale="0.001 0.001 0.001" /> -->
      </geometry>
    </collision>
    <inertial>
      <origin rpy="0.0 0.0 0.0" xyz="-0.003049665024221911 0.0008866902457326625 0.043079803024980934"/>
      <mass value="0.6156588026168502"/>
      <inertia ixx="0.000423" ixy="-8e-06" ixz="6e-06" iyy="0.000445" iyz="-6e-06" izz="0.000324"/>
    </inertial>
  </link>
  <joint name="openarm_right_joint5" type="revolute">
    <origin rpy="0 0 0" xyz="0.0 -0.0315 0.0955"/>
    <parent link="openarm_right_link4"/>
    <child link="openarm_right_link5"/>
    <axis xyz="0 0 1"/>
    <limit effort="7" lower="-1.570796" upper="1.570796" velocity="20.943946"/>
  </joint>
  <link name="openarm_right_link6">
    <visual name="openarm_right_link6_visual">
      <origin rpy="0.0 0.0 0.0" xyz="-0.0375 -0.0 -0.5585"/>
      <geometry>
        <mesh filename="./meshes/arm/v10/visual/link6.dae" scale="0.001 0.001 0.001"/>
      </geometry>
    </visual>
    <collision name="openarm_right_link6_collision">
      <origin rpy="0.0 0.0 0.0" xyz="-0.0375 -0.0 -0.5585"/>
      <geometry>
        <mesh filename="./meshes/arm/v10/collision/link6_symp.stl" scale="0.001 0.001 0.001"/>
        <!-- <mesh filename="${mesh_prefix}/meshes/arm/${arm_type}/collision/${name}.stl" scale="0.001 0.001 0.001" /> -->
      </geometry>
    </collision>
    <inertial>
      <origin rpy="0.0 0.0 0.0" xyz="-0.037136587005447405 0.00033230528343419053 -9.498374522309838e-05"/>
      <mass value="0.475202773187987"/>
      <inertia ixx="0.000143" ixy="1e-06" ixz="1e-06" iyy="0.000157" iyz="1e-06" izz="0.000159"/>
    </inertial>
  </link>
  <joint name="openarm_right_joint6" type="revolute">
    <origin rpy="0 0 0" xyz="0.0375 0.0 0.1205"/>
    <parent link="openarm_right_link5"/>
    <child link="openarm_right_link6"/>
    <axis xyz="1 0 0"/>
    <limit effort="7" lower="-0.785398" upper="0.785398" velocity="20.943946"/>
  </joint>
  <link name="openarm_right_link7">
    <visual name="openarm_right_link7_visual">
      <origin rpy="0.0 0.0 0.0" xyz="0.0 -0.0 -0.5585"/>
      <geometry>
        <mesh filename="./meshes/arm/v10/visual/link7.dae" scale="0.001 0.001 0.001"/>
      </geometry>
    </visual>
    <collision name="openarm_right_link7_collision">
      <origin rpy="0.0 0.0 0.0" xyz="0.0 -0.0 -0.5585"/>
      <geometry>
        <mesh filename="./meshes/arm/v10/collision/link7_symp.stl" scale="0.001 0.001 0.001"/>
        <!-- <mesh filename="${mesh_prefix}/meshes/arm/${arm_type}/collision/${name}.stl" scale="0.001 0.001 0.001" /> -->
      </geometry>
    </collision>
    <inertial>
      <origin rpy="0.0 0.0 0.0" xyz="6.875510271106056e-05 0.01266175250761268 0.06951945409987448"/>
      <mass value="0.4659771327380578"/>
      <inertia ixx="0.000639" ixy="1e-06" ixz="1e-06" iyy="0.000497" iyz="8.9e-05" izz="0.000342"/>
    </inertial>
  </link>
  <joint name="openarm_right_joint7" type="revolute">
    <origin rpy="0 0 0" xyz="-0.0375 0.0 0.0"/>
    <parent link="openarm_right_link6"/>
    <child link="openarm_right_link7"/>
    <axis xyz="0 1 0"/>
    <limit effort="7" lower="-1.570796" upper="1.570796" velocity="20.943946"/>
  </joint>
  <!-- <link name="${prefix}link8"/>

    <joint name="${prefix}joint8" type="fixed">
      <xacro:openarm-kinematics name="joint8" config="${kinematics}" />
      <parent link="${prefix}link7" />
      <child link="${prefix}link8" />
    </joint> -->
  <link name="left_hand_mount" type="fixed">
    <visual>
      <origin rpy="0 0 3.1416" xyz="0 0 0"/>
      <geometry>
        <mesh filename="./meshes/ee/rh56f1/visual/rh56f1_mount.stl" scale="0.001 0.001 0.001"/>
      </geometry>
    </visual>
  </link>
  <link name="left_hand_base_link">
    <inertial>
      <origin rpy="0 0 0" xyz="0.000631583768841232 -4.98983354635385E-11 0.0185710296512339"/>
      <mass value="0.0793945339384899"/>
      <inertia ixx="2.73302961659096E-05" ixy="-1.14020192447604E-12" ixz="2.86317776549754E-08" iyy="2.62165201865506E-05" iyz="-9.86803596469321E-13" izz="3.56824415579562E-05"/>
    </inertial>
    <visual>
      <origin rpy="0 0 0" xyz="0 0 0"/>
      <geometry>
        <mesh filename="./inspire_hand_description/RH56F1/left/meshes/base_link.STL"/>
      </geometry>
      <material name="">
        <color rgba="1 1 1 1"/>
      </material>
    </visual>
    <collision>
      <origin rpy="0 0 0" xyz="0 0 0"/>
      <geometry>
        <mesh filename="./inspire_hand_description/RH56F1/left/meshes/base_link.STL"/>
      </geometry>
    </collision>
  </link>
  <link name="left_hand_thumb_1">
    <inertial>
      <origin rpy="0 0 0" xyz="-0.00015 0.00544 -0.0048200000000000005"/>
      <mass value="0.016800000000000002"/>
      <inertia ixx="7.3387e-07" ixy="1.436e-08" ixz="-1.11e-09" iyy="2.7925e-07" iyz="3.296e-08" izz="5.8189e-07"/>
    </inertial>
    <visual>
      <origin rpy="0 0 0" xyz="0 0 0"/>
      <geometry>
        <mesh filename="./inspire_hand_description/RH56F1/left/meshes/left_thumb_1.STL"/>
      </geometry>
      <material name="">
        <color rgba="1 1 1 1"/>
      </material>
    </visual>
    <collision>
      <origin rpy="0 0 0" xyz="0 0 0"/>
      <geometry>
        <mesh filename="./inspire_hand_description/RH56F1/left/meshes/left_thumb_1.STL"/>
      </geometry>
    </collision>
  </link>
  <joint name="left_hand_thumb_1_joint" type="revolute">
    <origin rpy="0 0 0" xyz="0.01836 -0.027241 0.070511"/>
    <parent link="left_hand_base_link"/>
    <child link="left_hand_thumb_1"/>
    <axis xyz="8.7274E-05 0 1"/>
    <limit effort="1" lower="0" upper="2.0943951023931953" velocity="2"/>
  </joint>
  <link name="left_hand_thumb_2">
    <inertial>
      <origin rpy="0 0 0" xyz="-0.0238 0.01042 0.00478"/>
      <mass value="0.06526"/>
      <inertia ixx="1.378224e-05" ixy="-5.95663e-06" ixz="-1.9799999999999998e-09" iyy="1.1840129999999999e-05" iyz="-7.070000000000001e-09" izz="2.249189e-05"/>
    </inertial>
    <visual>
      <origin rpy="0 0 0" xyz="0 0 0"/>
      <geometry>
        <mesh filename="./inspire_hand_description/RH56F1/left/meshes/left_thumb_2.STL"/>
      </geometry>
      <material name="">
        <color rgba="0.25 0.25 0.25 1"/>
      </material>
    </visual>
    <collision>
      <origin rpy="0 0 0" xyz="0 0 0"/>
      <geometry>
        <mesh filename="./inspire_hand_description/RH56F1/left/meshes/left_thumb_2.STL"/>
      </geometry>
    </collision>
  </link>
  <joint name="left_hand_thumb_2_joint" type="revolute">
    <origin rpy="1.5707 0 -1.5708" xyz="0.005034 -0.01349 -0.0049121"/>
    <parent link="left_hand_thumb_1"/>
    <child link="left_hand_thumb_2"/>
    <axis xyz="0 0 1"/>
    <limit effort="1" lower="0" upper="0.4745550236172582" velocity="2"/>
  </joint>
  <link name="left_hand_thumb_3">
    <inertial>
      <origin rpy="0 0 0" xyz="-0.01255 0.00331 0.00799"/>
      <mass value="0.01333"/>
      <inertia ixx="1.41987e-06" ixy="-1.4979e-07" ixz="-6.3e-10" iyy="1.18482e-06" iyz="-1.76e-09" izz="1.6920999999999999e-06"/>
    </inertial>
    <visual>
      <origin rpy="0 0 0" xyz="0 0 0"/>
      <geometry>
        <mesh filename="./inspire_hand_description/RH56F1/left/meshes/left_thumb_3.STL"/>
      </geometry>
      <material name="">
        <color rgba="0.25 0.25 0.25 1"/>
      </material>
    </visual>
    <collision>
      <origin rpy="0 0 0" xyz="0 0 0"/>
      <geometry>
        <mesh filename="./inspire_hand_description/RH56F1/left/meshes/left_thumb_3.STL"/>
      </geometry>
    </collision>
  </link>
  <joint name="left_hand_thumb_3_joint" type="revolute">
    <origin rpy="0 0 0" xyz="0.033907 0.034601 -0.0029656"/>
    <parent link="left_hand_thumb_2"/>
    <child link="left_hand_thumb_3"/>
    <axis xyz="0 0 1"/>
    <limit effort="1" lower="0" upper="3.14" velocity="2"/>
    <mimic joint="left_hand_thumb_2_joint" multiplier="1.2953" offset="0"/>
  </joint>
  <link name="left_hand_thumb_4">
    <inertial>
      <origin rpy="0 0 0" xyz="-0.010199999999999999 0.00886 0.0067"/>
      <mass value="0.011439999999999999"/>
      <inertia ixx="9.4221e-07" ixy="-1.6288e-07" ixz="-0.0" iyy="3.9966e-07" iyz="0.0" izz="9.478099999999999e-07"/>
    </inertial>
    <visual>
      <origin rpy="0 0 0" xyz="0 0 0"/>
      <geometry>
        <mesh filename="./inspire_hand_description/RH56F1/left/meshes/left_thumb_4.STL"/>
      </geometry>
      <material name="">
        <color rgba="0.25 0.25 0.25 1"/>
      </material>
    </visual>
    <collision>
      <origin rpy="0 0 0" xyz="0 0 0"/>
      <geometry>
        <mesh filename="./inspire_hand_description/RH56F1/left/meshes/left_thumb_4.STL"/>
      </geometry>
    </collision>
  </link>
  <joint name="left_hand_thumb_4_joint" type="revolute">
    <origin rpy="0 0 0" xyz="0.01441 0.014648 0.0013"/>
    <parent link="left_hand_thumb_3"/>
    <child link="left_hand_thumb_4"/>
    <axis xyz="0 0 1"/>
    <limit effort="1" lower="0" upper="3.14" velocity="2"/>
    <mimic joint="left_hand_thumb_3_joint" multiplier="0.8962" offset="0"/>
  </joint>
  <link name="left_hand_thumb_force_sensor">
    <inertial>
      <origin rpy="0 0 0" xyz="0.00489751957141649 0.0007076731556618 -0.00883776267773212"/>
      <mass value="0"/>
      <inertia ixx="0" ixy="0" ixz="0" iyy="0" iyz="0" izz="0"/>
    </inertial>
    <visual>
      <origin rpy="0 0 0" xyz="0 0 0"/>
      <geometry>
        <mesh filename="./inspire_hand_description/RH56F1/left/meshes/thumb_force_sensor.STL"/>
      </geometry>
      <material name="">
        <color rgba="0.25 0.25 0.25 1"/>
      </material>
    </visual>
    <collision>
      <origin rpy="0 0 0" xyz="0 0 0"/>
      <geometry>
        <mesh filename="./inspire_hand_description/RH56F1/left/meshes/thumb_force_sensor.STL"/>
      </geometry>
    </collision>
  </link>
  <joint name="left_hand_thumb_force_sensor_joint" type="fixed">
    <origin rpy="1.5194 0.0515 -2.3562" xyz="0.0082761 0.019128 0.0068"/>
    <parent link="left_hand_thumb_4"/>
    <child link="left_hand_thumb_force_sensor"/>
    <axis xyz="0 0 0"/>
  </joint>
  <link name="left_hand_thumb_tip">
    <inertial>
      <origin rpy="0 0 0" xyz="8.11478806861891E-05 -0.00949601991936605 -0.0139509187579862"/>
      <mass value="0"/>
      <inertia ixx="0" ixy="0" ixz="0" iyy="0" iyz="0" izz="0"/>
    </inertial>
    <visual>
      <origin rpy="0 0 0" xyz="0 0 0"/>
      <geometry>
        <mesh filename="./inspire_hand_description/RH56F1/left/meshes/thumb_tip.STL"/>
      </geometry>
      <material name="">
        <color rgba="0.25 0.25 0.25 1"/>
      </material>
    </visual>
    <collision>
      <origin rpy="0 0 0" xyz="0 0 0"/>
      <geometry>
        <mesh filename="./inspire_hand_description/RH56F1/left/meshes/thumb_tip.STL"/>
      </geometry>
    </collision>
  </link>
  <joint name="left_hand_thumb_tip_joint" type="fixed">
    <origin rpy="1.8172 -1.5641 -3.1286" xyz="0.016676 0.025314 0.0067577"/>
    <parent link="left_hand_thumb_4"/>
    <child link="left_hand_thumb_tip"/>
    <axis xyz="0 0 0"/>
  </joint>
  <link name="left_hand_index_1">
    <inertial>
      <origin rpy="0 0 0" xyz="0.00046 0.01509 0.0060999999999999995"/>
      <mass value="0.01111"/>
      <inertia ixx="2.04599e-06" ixy="3.703e-08" ixz="1.77e-09" iyy="5.4029e-07" iyz="-9.149e-08" izz="2.0895e-06"/>
    </inertial>
    <visual>
      <origin rpy="0 0 0" xyz="0 0 0"/>
      <geometry>
        <mesh filename="./inspire_hand_description/RH56F1/left/meshes/left_index_1.STL"/>
      </geometry>
      <material name="">
        <color rgba="0.25 0.25 0.25 1"/>
      </material>
    </visual>
    <collision>
      <origin rpy="0 0 0" xyz="0 0 0"/>
      <geometry>
        <mesh filename="./inspire_hand_description/RH56F1/left/meshes/left_index_1.STL"/>
      </geometry>
    </collision>
  </link>
  <joint name="left_hand_index_1_joint" type="revolute">
    <origin rpy="1.6319 0 0" xyz="0.00070753 -0.034377 0.13554"/>
    <parent link="left_hand_base_link"/>
    <child link="left_hand_index_1"/>
    <axis xyz="0 0 -1"/>
    <limit effort="1" lower="0" upper="1.5285593588966337" velocity="2"/>
  </joint>
  <link name="left_hand_index_2">
    <inertial>
      <origin rpy="0 0 0" xyz="-0.00436 0.01623 0.005019999999999999"/>
      <mass value="0.0103"/>
      <inertia ixx="1.5669000000000002e-06" ixy="2.2414e-07" ixz="1.3699999999999999e-08" iyy="2.9717e-07" iyz="-7.84e-08" izz="1.5746300000000001e-06"/>
    </inertial>
    <visual>
      <origin rpy="0 0 0" xyz="0 0 0"/>
      <geometry>
        <mesh filename="./inspire_hand_description/RH56F1/left/meshes/left_index_2.STL"/>
      </geometry>
      <material name="">
        <color rgba="0.25 0.25 0.25 1"/>
      </material>
    </visual>
    <collision>
      <origin rpy="0 0 0" xyz="0 0 0"/>
      <geometry>
        <mesh filename="./inspire_hand_description/RH56F1/left/meshes/left_index_2.STL"/>
      </geometry>
    </collision>
  </link>
  <joint name="left_hand_index_2_joint" type="revolute">
    <origin rpy="0 0 0" xyz="0.0031056 0.032854 -0.001"/>
    <parent link="left_hand_index_1"/>
    <child link="left_hand_index_2"/>
    <axis xyz="0 0 -1"/>
    <limit effort="1" lower="0" upper="3.14" velocity="2"/>
    <mimic joint="left_hand_index_1_joint" multiplier="1.1545" offset="0"/>
  </joint>
  <link name="left_hand_index_force_sensor">
    <inertial>
      <origin rpy="0 0 0" xyz="0.00120718275325524 -0.012261274947138 -0.00640384837472582"/>
      <mass value="0"/>
      <inertia ixx="0" ixy="0" ixz="0" iyy="0" iyz="0" izz="0"/>
    </inertial>
    <visual>
      <origin rpy="0 0 0" xyz="0 0 0"/>
      <geometry>
        <mesh filename="./inspire_hand_description/RH56F1/left/meshes/index_force_sensor.STL"/>
      </geometry>
      <material name="">
        <color rgba="0.25 0.25 0.25 1"/>
      </material>
    </visual>
    <collision>
      <origin rpy="0 0 0" xyz="0 0 0"/>
      <geometry>
        <mesh filename="./inspire_hand_description/RH56F1/left/meshes/index_force_sensor.STL"/>
      </geometry>
    </collision>
  </link>
  <joint name="left_hand_index_force_sensor_joint" type="fixed">
    <origin rpy="-2.1954 1.4829 -2.3749" xyz="0.005139 0.028671 -0.0059996"/>
    <parent link="left_hand_index_2"/>
    <child link="left_hand_index_force_sensor"/>
    <axis xyz="0 0 0"/>
  </joint>
  <link name="left_hand_index_tip">
    <inertial>
      <origin rpy="0 0 0" xyz="0.0014808314279941 -0.0177565390809834 -0.0152284217596933"/>
      <mass value="0"/>
      <inertia ixx="0" ixy="0" ixz="0" iyy="0" iyz="0" izz="0"/>
    </inertial>
    <visual>
      <origin rpy="0 0 0" xyz="0 0 0"/>
      <geometry>
        <mesh filename="./inspire_hand_description/RH56F1/left/meshes/index_tip.STL"/>
      </geometry>
      <material name="">
        <color rgba="0.25 0.25 0.25 1"/>
      </material>
    </visual>
    <collision>
      <origin rpy="0 0 0" xyz="0 0 0"/>
      <geometry>
        <mesh filename="./inspire_hand_description/RH56F1/left/meshes/index_tip.STL"/>
      </geometry>
    </collision>
  </link>
  <joint name="left_hand_index_tip_joint" type="fixed">
    <origin rpy="-2.1925 1.5073 -1.8461" xyz="0.0049188 0.039631 -0.006"/>
    <parent link="left_hand_index_2"/>
    <child link="left_hand_index_tip"/>
    <axis xyz="0 0 0"/>
  </joint>
  <link name="left_hand_middle_1">
    <inertial>
      <origin rpy="0 0 0" xyz="0.00046 0.01468 0.00701"/>
      <mass value="0.01111"/>
      <inertia ixx="2.04599e-06" ixy="3.707e-08" ixz="-4.9e-10" iyy="5.3491e-07" iyz="3.6e-09" izz="2.09487e-06"/>
    </inertial>
    <visual>
      <origin rpy="0 0 0" xyz="0 0 0"/>
      <geometry>
        <mesh filename="./inspire_hand_description/RH56F1/left/meshes/left_middle_1.STL"/>
      </geometry>
      <material name="">
        <color rgba="0.25 0.25 0.25 1"/>
      </material>
    </visual>
    <collision>
      <origin rpy="0 0 0" xyz="0 0 0"/>
      <geometry>
        <mesh filename="./inspire_hand_description/RH56F1/left/meshes/left_middle_1.STL"/>
      </geometry>
    </collision>
  </link>
  <joint name="left_hand_middle_1_joint" type="revolute">
    <origin rpy="1.5708 0 0" xyz="0.00070746 -0.015767 0.13648"/>
    <parent link="left_hand_base_link"/>
    <child link="left_hand_middle_1"/>
    <axis xyz="0 0 -1"/>
    <limit effort="1" lower="0" upper="1.5285593588966337" velocity="2"/>
  </joint>
  <link name="left_hand_middle_2">
    <inertial>
      <origin rpy="0 0 0" xyz="-0.004019999999999999 0.01731 0.006"/>
      <mass value="0.01122"/>
      <inertia ixx="1.92755e-06" ixy="2.9305e-07" ixz="-1.0000000000000001e-11" iyy="3.2973000000000003e-07" iyz="1.0000000000000001e-11" izz="1.95229e-06"/>
    </inertial>
    <visual>
      <origin rpy="0 0 0" xyz="0 0 0"/>
      <geometry>
        <mesh filename="./inspire_hand_description/RH56F1/left/meshes/left_middle_2.STL"/>
      </geometry>
      <material name="">
        <color rgba="0.25 0.25 0.25 1"/>
      </material>
    </visual>
    <collision>
      <origin rpy="0 0 0" xyz="0 0 0"/>
      <geometry>
        <mesh filename="./inspire_hand_description/RH56F1/left/meshes/left_middle_2.STL"/>
      </geometry>
    </collision>
  </link>
  <joint name="left_hand_middle_2_joint" type="revolute">
    <origin rpy="0 0 0" xyz="0.0031056 0.032854 -0.001"/>
    <parent link="left_hand_middle_1"/>
    <child link="left_hand_middle_2"/>
    <axis xyz="0 0 -1"/>
    <limit effort="1" lower="0" upper="3.14" velocity="2"/>
    <mimic joint="left_hand_middle_1_joint" multiplier="1.1545" offset="0"/>
  </joint>
  <link name="left_hand_middle_force_sensor">
    <inertial>
      <origin rpy="0 0 0" xyz="0.000471409970909109 -0.0138861005738287 -0.00634250554762082"/>
      <mass value="0"/>
      <inertia ixx="0" ixy="0" ixz="0" iyy="0" iyz="0" izz="0"/>
    </inertial>
    <visual>
      <origin rpy="0 0 0" xyz="0 0 0"/>
      <geometry>
        <mesh filename="./inspire_hand_description/RH56F1/left/meshes/middle_force_sensor.STL"/>
      </geometry>
      <material name="">
        <color rgba="0.25 0.25 0.25 1"/>
      </material>
    </visual>
    <collision>
      <origin rpy="0 0 0" xyz="0 0 0"/>
      <geometry>
        <mesh filename="./inspire_hand_description/RH56F1/left/meshes/middle_force_sensor.STL"/>
      </geometry>
    </collision>
  </link>
  <joint name="left_hand_middle_force_sensor_joint" type="fixed">
    <origin rpy="-2.9405 1.5184 3.1416" xyz="0.0059655 0.031551 -0.0060998"/>
    <parent link="left_hand_middle_2"/>
    <child link="left_hand_middle_force_sensor"/>
    <axis xyz="0 0 0"/>
  </joint>
  <link name="left_hand_middle_tip">
    <inertial>
      <origin rpy="0 0 0" xyz="-1.57112051041297E-05 -0.0191707815454482 -0.0160132461086732"/>
      <mass value="0"/>
      <inertia ixx="0" ixy="0" ixz="0" iyy="0" iyz="0" izz="0"/>
    </inertial>
    <visual>
      <origin rpy="0 0 0" xyz="0 0 0"/>
      <geometry>
        <mesh filename="./inspire_hand_description/RH56F1/left/meshes/middle_tip.STL"/>
      </geometry>
      <material name="">
        <color rgba="0.25 0.25 0.25 1"/>
      </material>
    </visual>
    <collision>
      <origin rpy="0 0 0" xyz="0 0 0"/>
      <geometry>
        <mesh filename="./inspire_hand_description/RH56F1/left/meshes/middle_tip.STL"/>
      </geometry>
    </collision>
  </link>
  <joint name="left_hand_middle_tip_joint" type="fixed">
    <origin rpy="-0.3273 1.5691 0" xyz="0.0059647 0.042512 -0.0060998"/>
    <parent link="left_hand_middle_2"/>
    <child link="left_hand_middle_tip"/>
    <axis xyz="0 0 0"/>
  </joint>
  <link name="left_hand_ring_1">
    <inertial>
      <origin rpy="0 0 0" xyz="0.00046 0.0143 0.00777"/>
      <mass value="0.01111"/>
      <inertia ixx="2.04599e-06" ixy="3.699e-08" ixz="-2.43e-09" iyy="5.395599999999999e-07" iyz="8.511e-08" izz="2.09023e-06"/>
    </inertial>
    <visual>
      <origin rpy="0 0 0" xyz="0 0 0"/>
      <geometry>
        <mesh filename="./inspire_hand_description/RH56F1/left/meshes/left_ring_1.STL"/>
      </geometry>
      <material name="">
        <color rgba="0.25 0.25 0.25 1"/>
      </material>
    </visual>
    <collision>
      <origin rpy="0 0 0" xyz="0 0 0"/>
      <geometry>
        <mesh filename="./inspire_hand_description/RH56F1/left/meshes/left_ring_1.STL"/>
      </geometry>
    </collision>
  </link>
  <joint name="left_hand_ring_1_joint" type="revolute">
    <origin rpy="1.5184 0 0" xyz="0.00070746 0.0030876 0.13643"/>
    <parent link="left_hand_base_link"/>
    <child link="left_hand_ring_1"/>
    <axis xyz="0 0 -1"/>
    <limit effort="1" lower="0" upper="1.5285593588966337" velocity="2"/>
  </joint>
  <link name="left_hand_ring_2">
    <inertial>
      <origin rpy="0 0 0" xyz="-0.00436 0.015560000000000001 0.0068200000000000005"/>
      <mass value="0.0103"/>
      <inertia ixx="1.5669000000000002e-06" ixy="2.2425e-07" ixz="-1.1759999999999999e-08" iyy="2.959e-07" iyz="6.729e-08" izz="1.5758900000000002e-06"/>
    </inertial>
    <visual>
      <origin rpy="0 0 0" xyz="0 0 0"/>
      <geometry>
        <mesh filename="./inspire_hand_description/RH56F1/left/meshes/left_ring_2.STL"/>
      </geometry>
      <material name="">
        <color rgba="0.25 0.25 0.25 1"/>
      </material>
    </visual>
    <collision>
      <origin rpy="0 0 0" xyz="0 0 0"/>
      <geometry>
        <mesh filename="./inspire_hand_description/RH56F1/left/meshes/left_ring_2.STL"/>
      </geometry>
    </collision>
  </link>
  <joint name="left_hand_ring_2_joint" type="revolute">
    <origin rpy="0 0 0" xyz="0.0031056 0.032854 -0.001"/>
    <parent link="left_hand_ring_1"/>
    <child link="left_hand_ring_2"/>
    <axis xyz="0 0 -1"/>
    <limit effort="1" lower="0" upper="3.14" velocity="2"/>
    <mimic joint="left_hand_ring_1_joint" multiplier="1.1545" offset="0"/>
  </joint>
  <link name="left_hand_ring_force_sensor">
    <inertial>
      <origin rpy="0 0 0" xyz="-0.000209715894633783 -0.0123187686132097 -0.00640384736210899"/>
      <mass value="0"/>
      <inertia ixx="0" ixy="0" ixz="0" iyy="0" iyz="0" izz="0"/>
    </inertial>
    <visual>
      <origin rpy="0 0 0" xyz="0 0 0"/>
      <geometry>
        <mesh filename="./inspire_hand_description/RH56F1/left/meshes/ring_force_sensor.STL"/>
      </geometry>
      <material name="">
        <color rgba="0.25 0.25 0.25 1"/>
      </material>
    </visual>
    <collision>
      <origin rpy="0 0 0" xyz="0 0 0"/>
      <geometry>
        <mesh filename="./inspire_hand_description/RH56F1/left/meshes/ring_force_sensor.STL"/>
      </geometry>
    </collision>
  </link>
  <joint name="left_hand_ring_force_sensor_joint" type="fixed">
    <origin rpy="2.4366 1.5033 2.2541" xyz="0.005139 0.028671 -0.0059996"/>
    <parent link="left_hand_ring_2"/>
    <child link="left_hand_ring_force_sensor"/>
    <axis xyz="0 0 0"/>
  </joint>
  <link name="left_hand_ring_tip">
    <inertial>
      <origin rpy="0 0 0" xyz="-0.00100385930577584 -0.0177521786857137 -0.0152723548834053"/>
      <mass value="0"/>
      <inertia ixx="0" ixy="0" ixz="0" iyy="0" iyz="0" izz="0"/>
    </inertial>
    <visual>
      <origin rpy="0 0 0" xyz="0 0 0"/>
      <geometry>
        <mesh filename="./inspire_hand_description/RH56F1/left/meshes/ring_tip.STL"/>
      </geometry>
      <material name="">
        <color rgba="0.25 0.25 0.25 1"/>
      </material>
    </visual>
    <collision>
      <origin rpy="0 0 0" xyz="0 0 0"/>
      <geometry>
        <mesh filename="./inspire_hand_description/RH56F1/left/meshes/ring_tip.STL"/>
      </geometry>
    </collision>
  </link>
  <joint name="left_hand_ring_tip_joint" type="fixed">
    <origin rpy="1.5417 1.5157 1.889" xyz="0.0049188 0.039631 -0.006"/>
    <parent link="left_hand_ring_2"/>
    <child link="left_hand_ring_tip"/>
    <axis xyz="0 0 0"/>
  </joint>
  <link name="left_hand_little_1">
    <inertial>
      <origin rpy="0 0 0" xyz="0.00046 0.013869999999999999 0.0085"/>
      <mass value="0.01111"/>
      <inertia ixx="2.04599e-06" ixy="3.6810000000000003e-08" ixz="-4.360000000000001e-09" iyy="5.527e-07" iyz="1.6568e-07" izz="2.07708e-06"/>
    </inertial>
    <visual>
      <origin rpy="0 0 0" xyz="0 0 0"/>
      <geometry>
        <mesh filename="./inspire_hand_description/RH56F1/left/meshes/left_little_1.STL"/>
      </geometry>
      <material name="">
        <color rgba="0.25 0.25 0.25 1"/>
      </material>
    </visual>
    <collision>
      <origin rpy="0 0 0" xyz="0 0 0"/>
      <geometry>
        <mesh filename="./inspire_hand_description/RH56F1/left/meshes/left_little_1.STL"/>
      </geometry>
    </collision>
  </link>
  <joint name="left_hand_little_1_joint" type="revolute">
    <origin rpy="1.4661 0 0" xyz="0.00070753 0.021094 0.13531"/>
    <parent link="left_hand_base_link"/>
    <child link="left_hand_little_1"/>
    <axis xyz="0 0 -1"/>
    <limit effort="1" lower="0" upper="1.5285593588966337" velocity="2"/>
  </joint>
  <link name="left_hand_little_2">
    <inertial>
      <origin rpy="0 0 0" xyz="-0.004070000000000001 0.01192 0.00728"/>
      <mass value="0.00839"/>
      <inertia ixx="9.3539e-07" ixy="1.6843e-07" ixz="-1.7670000000000002e-08" iyy="2.4681e-07" iyz="7.359e-08" izz="9.379400000000001e-07"/>
    </inertial>
    <visual>
      <origin rpy="0 0 0" xyz="0 0 0"/>
      <geometry>
        <mesh filename="./inspire_hand_description/RH56F1/left/meshes/left_little_2.STL"/>
      </geometry>
      <material name="">
        <color rgba="0.25 0.25 0.25 1"/>
      </material>
    </visual>
    <collision>
      <origin rpy="0 0 0" xyz="0 0 0"/>
      <geometry>
        <mesh filename="./inspire_hand_description/RH56F1/left/meshes/left_little_2.STL"/>
      </geometry>
    </collision>
  </link>
  <joint name="left_hand_little_2_joint" type="revolute">
    <origin rpy="0 0 0" xyz="0.0031057 0.032854 -0.001"/>
    <parent link="left_hand_little_1"/>
    <child link="left_hand_little_2"/>
    <axis xyz="0 0 -1"/>
    <limit effort="1" lower="0" upper="3.14" velocity="2"/>
    <mimic joint="left_hand_little_1_joint" multiplier="1.1545" offset="0"/>
  </joint>
  <link name="left_hand_little_force_sensor">
    <inertial>
      <origin rpy="0 0 0" xyz="-0.000486995031034054 -0.00853489982845629 -0.00651155949691547"/>
      <mass value="0"/>
      <inertia ixx="0" ixy="0" ixz="0" iyy="0" iyz="0" izz="0"/>
    </inertial>
    <visual>
      <origin rpy="0 0 0" xyz="0 0 0"/>
      <geometry>
        <mesh filename="./inspire_hand_description/RH56F1/left/meshes/little_force_sensor.STL"/>
      </geometry>
      <material name="">
        <color rgba="0.25 0.25 0.25 1"/>
      </material>
    </visual>
    <collision>
      <origin rpy="0 0 0" xyz="0 0 0"/>
      <geometry>
        <mesh filename="./inspire_hand_description/RH56F1/left/meshes/little_force_sensor.STL"/>
      </geometry>
    </collision>
  </link>
  <joint name="left_hand_little_force_sensor_joint" type="fixed">
    <origin rpy="2.0609 1.4616 1.858" xyz="0.0051314 0.021582 -0.0063543"/>
    <parent link="left_hand_little_2"/>
    <child link="left_hand_little_force_sensor"/>
    <axis xyz="0 0 0"/>
  </joint>
  <link name="left_hand_little_tip">
    <inertial>
      <origin rpy="0 0 0" xyz="-0.00160676343735405 -0.0143780070321105 -0.0134619377604817"/>
      <mass value="0"/>
      <inertia ixx="0" ixy="0" ixz="0" iyy="0" iyz="0" izz="0"/>
    </inertial>
    <visual>
      <origin rpy="0 0 0" xyz="0 0 0"/>
      <geometry>
        <mesh filename="./inspire_hand_description/RH56F1/left/meshes/little_tip.STL"/>
      </geometry>
      <material name="">
        <color rgba="0.25 0.25 0.25 1"/>
      </material>
    </visual>
    <collision>
      <origin rpy="0 0 0" xyz="0 0 0"/>
      <geometry>
        <mesh filename="./inspire_hand_description/RH56F1/left/meshes/little_tip.STL"/>
      </geometry>
    </collision>
  </link>
  <joint name="left_hand_little_tip_joint" type="fixed">
    <origin rpy="1.554 1.4608 1.8824" xyz="0.0051203 0.032544 -0.0063511"/>
    <parent link="left_hand_little_2"/>
    <child link="left_hand_little_tip"/>
    <axis xyz="0 0 0"/>
  </joint>
  <link name="left_hand_plam_1">
    <inertial>
      <origin rpy="0 0 0" xyz="-0.00132 0.00039 0.07415000000000001"/>
      <mass value="0.41238"/>
      <inertia ixx="0.00078835939" ixy="-8.875e-07" ixz="3.202881e-05" iyy="0.00066648352" iyz="1.4681199999999999e-06" izz="0.00026678122"/>
    </inertial>
    <visual>
      <origin rpy="0 0 0" xyz="0 0 0"/>
      <geometry>
        <mesh filename="./inspire_hand_description/RH56F1/left/meshes/plam_1.STL"/>
      </geometry>
      <material name="">
        <color rgba="1 1 1 1"/>
      </material>
    </visual>
    <collision>
      <origin rpy="0 0 0" xyz="0 0 0"/>
      <geometry>
        <mesh filename="./inspire_hand_description/RH56F1/left/meshes/plam_1.STL"/>
      </geometry>
    </collision>
  </link>
  <joint name="left_hand_plam_1_joint" type="fixed">
    <origin rpy="0 0 0" xyz="0 0 0.0305"/>
    <parent link="left_hand_base_link"/>
    <child link="left_hand_plam_1"/>
    <axis xyz="0 0 0"/>
  </joint>
  <link name="left_hand_plam_2">
    <inertial>
      <origin rpy="0 0 0" xyz="0.00738877558367422 0.00286851435787733 0.0491990009538881"/>
      <mass value="0.01"/>
      <inertia ixx="7.42627311403438E-05" ixy="-1.51062288185372E-06" ixz="-1.38221866903039E-06" iyy="4.54002453711238E-05" iyz="3.52845387182101E-06" izz="3.50303789099898E-05"/>
    </inertial>
    <visual>
      <origin rpy="0 0 0" xyz="0 0 0"/>
      <geometry>
        <mesh filename="./inspire_hand_description/RH56F1/left/meshes/plam_2.STL"/>
      </geometry>
      <material name="">
        <color rgba="0.25 0.25 0.25 1"/>
      </material>
    </visual>
    <collision>
      <origin rpy="0 0 0" xyz="0 0 0"/>
      <geometry>
        <mesh filename="./inspire_hand_description/RH56F1/left/meshes/plam_2.STL"/>
      </geometry>
    </collision>
  </link>
  <joint name="left_hand_plam_2_joint" type="fixed">
    <origin rpy="0 0 0" xyz="0 0 0"/>
    <parent link="left_hand_plam_1"/>
    <child link="left_hand_plam_2"/>
    <axis xyz="0 0 0"/>
  </joint>
  <link name="left_hand_plam_3">
    <inertial>
      <origin rpy="0 0 0" xyz="-0.0145080707705958 -0.00297062755371721 0.0599886430688916"/>
      <mass value="0.01"/>
      <inertia ixx="7.44290151295326E-05" ixy="2.11550341708188E-06" ixz="3.5267344320077E-07" iyy="4.06594932990061E-05" iyz="-3.15566621908941E-06" izz="4.24832389559144E-05"/>
    </inertial>
    <visual>
      <origin rpy="0 0 0" xyz="0 0 0"/>
      <geometry>
        <mesh filename="./inspire_hand_description/RH56F1/left/meshes/plam_3.STL"/>
      </geometry>
      <material name="">
        <color rgba="1 1 1 1"/>
      </material>
    </visual>
    <collision>
      <origin rpy="0 0 0" xyz="0 0 0"/>
      <geometry>
        <mesh filename="./inspire_hand_description/RH56F1/left/meshes/plam_3.STL"/>
      </geometry>
    </collision>
  </link>
  <joint name="left_hand_plam_3_joint" type="fixed">
    <origin rpy="0 0 0" xyz="0 0 0"/>
    <parent link="left_hand_plam_2"/>
    <child link="left_hand_plam_3"/>
    <axis xyz="0 0 0"/>
  </joint>
  <link name="left_hand_plam_force_sensor">
    <inertial>
      <origin rpy="0 0 0" xyz="0.00135083432691963 -0.00241176672948407 -0.00177409386471654"/>
      <mass value="0.00449423213489162"/>
      <inertia ixx="2.77343430370559E-07" ixy="9.29194202733673E-12" ixz="-1.13995686775868E-12" iyy="1.25941926345234E-06" iyz="5.96425032363731E-09" izz="1.53055306696602E-06"/>
    </inertial>
    <visual>
      <origin rpy="0 0 0" xyz="0 0 0"/>
      <geometry>
        <mesh filename="./inspire_hand_description/RH56F1/left/meshes/plam_force_sensor.STL"/>
      </geometry>
      <material name="">
        <color rgba="0.25 0.25 0.25 1"/>
      </material>
    </visual>
    <collision>
      <origin rpy="0 0 0" xyz="0 0 0"/>
      <geometry>
        <mesh filename="./inspire_hand_description/RH56F1/left/meshes/plam_force_sensor.STL"/>
      </geometry>
    </collision>
  </link>
  <joint name="left_hand_plam_force_sensor_joint" type="fixed">
    <origin rpy="1.5708 0 1.5708" xyz="0.01594 -0.0013505 0.073746"/>
    <parent link="left_hand_plam_2"/>
    <child link="left_hand_plam_force_sensor"/>
    <axis xyz="0 0 0"/>
  </joint>
  <joint name="left_arm_to_mount" type="fixed">
    <parent link="openarm_left_link7"/>
    <child link="left_hand_mount"/>
    <origin rpy="0 0 0" xyz="0 0 0.0495"/>
  </joint>
  <joint name="left_mount_to_rh56f1" type="fixed">
    <parent link="left_hand_mount"/>
    <child link="left_hand_base_link"/>
    <origin rpy="0 0 1.5708" xyz="0 0 0.006"/>
  </joint>
  <link name="right_hand_mount" type="fixed">
    <visual>
      <origin rpy="0 0 0" xyz="0 0 0"/>
      <geometry>
        <mesh filename="./meshes/ee/rh56f1/visual/rh56f1_mount.stl" scale="0.001 0.001 0.001"/>
      </geometry>
    </visual>
  </link>
  <link name="right_hand_base_link">
    <inertial>
      <origin rpy="0 0 0" xyz="0.000631584180168987 1.55468476565051E-09 0.0185710308410627"/>
      <mass value="0.0793945003608915"/>
      <inertia ixx="2.73302869871105E-05" ixy="4.73396056660905E-13" ixz="2.86328005285174E-08" iyy="2.62165141408126E-05" iyz="1.90463743334758E-12" izz="3.5682432554866E-05"/>
    </inertial>
    <visual>
      <origin rpy="0 0 0" xyz="0 0 0"/>
      <geometry>
        <mesh filename="./inspire_hand_description/RH56F1/right/meshes/base_link.STL"/>
      </geometry>
      <material name="">
        <color rgba="1 1 1 1"/>
      </material>
    </visual>
    <collision>
      <origin rpy="0 0 0" xyz="0 0 0"/>
      <geometry>
        <mesh filename="./inspire_hand_description/RH56F1/right/meshes/base_link.STL"/>
      </geometry>
    </collision>
  </link>
  <link name="right_hand_plam_1">
    <inertial>
      <origin rpy="0 0 0" xyz="-0.00132 0.00039 0.07415000000000001"/>
      <mass value="0.41238"/>
      <inertia ixx="0.00078835939" ixy="8.875e-07" ixz="3.202881e-05" iyy="0.00066648352" iyz="-1.4681199999999999e-06" izz="0.00026678122"/>
    </inertial>
    <visual>
      <origin rpy="0 0 0" xyz="0 0 0"/>
      <geometry>
        <mesh filename="./inspire_hand_description/RH56F1/right/meshes/plam_1.STL"/>
      </geometry>
      <material name="">
        <color rgba="0.866666666666667 0.866666666666667 0.890196078431372 1"/>
      </material>
    </visual>
    <collision>
      <origin rpy="0 0 0" xyz="0 0 0"/>
      <geometry>
        <mesh filename="./inspire_hand_description/RH56F1/right/meshes/plam_1.STL"/>
      </geometry>
    </collision>
  </link>
  <joint name="right_hand_plam_1_joint" type="fixed">
    <origin rpy="0 0 0" xyz="0 0 0.0305"/>
    <parent link="right_hand_base_link"/>
    <child link="right_hand_plam_1"/>
    <axis xyz="0 0 0"/>
  </joint>
  <link name="right_hand_plam_2">
    <inertial>
      <origin rpy="0 0 0" xyz="0.00780742986700294 -0.00181684242732992 0.0484726926194218"/>
      <mass value="0.01"/>
      <inertia ixx="7.53775883572448E-05" ixy="1.67198206435067E-06" ixz="-1.35138361804759E-06" iyy="4.62768852730386E-05" iyz="-3.66656859035162E-06" izz="3.55364070799627E-05"/>
    </inertial>
    <visual>
      <origin rpy="0 0 0" xyz="0 0 0"/>
      <geometry>
        <mesh filename="./inspire_hand_description/RH56F1/right/meshes/plam_2.STL"/>
      </geometry>
      <material name="">
        <color rgba="0.25 0.25 0.25 1"/>
      </material>
    </visual>
    <collision>
      <origin rpy="0 0 0" xyz="0 0 0"/>
      <geometry>
        <mesh filename="./inspire_hand_description/RH56F1/right/meshes/plam_2.STL"/>
      </geometry>
    </collision>
  </link>
  <joint name="right_hand_plam_2_joint" type="fixed">
    <origin rpy="0 0 0" xyz="0 0 0"/>
    <parent link="right_hand_plam_1"/>
    <child link="right_hand_plam_2"/>
    <axis xyz="0 0 0"/>
  </joint>
  <link name="right_hand_plam_3">
    <inertial>
      <origin rpy="0 0 0" xyz="-0.0145087315400233 0.00297298156011864 0.0599801851672911"/>
      <mass value="0.01"/>
      <inertia ixx="7.44229190374554E-05" ixy="-2.11457285174435E-06" ixz="3.53419391577662E-07" iyy="4.06574859268604E-05" iyz="3.15838633047347E-06" izz="4.24785219389853E-05"/>
    </inertial>
    <visual>
      <origin rpy="0 0 0" xyz="0 0 0"/>
      <geometry>
        <mesh filename="./inspire_hand_description/RH56F1/right/meshes/plam_3.STL"/>
      </geometry>
      <material name="">
        <color rgba="1 1 1 1"/>
      </material>
    </visual>
    <collision>
      <origin rpy="0 0 0" xyz="0 0 0"/>
      <geometry>
        <mesh filename="./inspire_hand_description/RH56F1/right/meshes/plam_3.STL"/>
      </geometry>
    </collision>
  </link>
  <joint name="right_hand_plam_3_jont" type="fixed">
    <origin rpy="0 0 0" xyz="0 0 0"/>
    <parent link="right_hand_plam_2"/>
    <child link="right_hand_plam_3"/>
    <axis xyz="0 0 0"/>
  </joint>
  <link name="right_hand_plam_force_sensor">
    <inertial>
      <origin rpy="0 0 0" xyz="0.00135015380328561 -0.00241176259562209 -0.00177409297911233"/>
      <mass value="0.00449423927061171"/>
      <inertia ixx="2.77343347350042E-07" ixy="-5.59517451189968E-13" ixz="2.86825536833881E-13" iyy="1.25942537762186E-06" iyz="5.96429255234865E-09" izz="1.53055908452317E-06"/>
    </inertial>
    <visual>
      <origin rpy="0 0 0" xyz="0 0 0"/>
      <geometry>
        <mesh filename="./inspire_hand_description/RH56F1/right/meshes/plam_force_sensor.STL"/>
      </geometry>
      <material name="">
        <color rgba="0.298039215686275 0.298039215686275 0.298039215686275 1"/>
      </material>
    </visual>
    <collision>
      <origin rpy="0 0 0" xyz="0 0 0"/>
      <geometry>
        <mesh filename="./inspire_hand_description/RH56F1/right/meshes/plam_force_sensor.STL"/>
      </geometry>
    </collision>
  </link>
  <joint name="right_hand_plam_force_sensor_joint" type="fixed">
    <origin rpy="1.5707963267949 0 1.5707963267949" xyz="0.0159401947506102 -0.00135045394126701 0.0737460952299602"/>
    <parent link="right_hand_plam_2"/>
    <child link="right_hand_plam_force_sensor"/>
    <axis xyz="0 0 0"/>
  </joint>
  <link name="right_hand_thumb_1">
    <inertial>
      <origin rpy="0 0 0" xyz="-0.00015 0.00544 -0.0048200000000000005"/>
      <mass value="0.016800000000000002"/>
      <inertia ixx="7.3387e-07" ixy="-1.436e-08" ixz="-1.11e-09" iyy="2.7925e-07" iyz="-3.296e-08" izz="5.8189e-07"/>
    </inertial>
    <visual>
      <origin rpy="0 0 0" xyz="0 0 0"/>
      <geometry>
        <mesh filename="./inspire_hand_description/RH56F1/right/meshes/right_thumb_1.STL"/>
      </geometry>
      <material name="">
        <color rgba="1 1 1 1"/>
      </material>
    </visual>
    <collision>
      <origin rpy="0 0 0" xyz="0 0 0"/>
      <geometry>
        <mesh filename="./inspire_hand_description/RH56F1/right/meshes/right_thumb_1.STL"/>
      </geometry>
    </collision>
  </link>
  <joint name="right_hand_thumb_1_joint" type="revolute">
    <origin rpy="0 0 0" xyz="0.01836 0.027241 0.070511"/>
    <parent link="right_hand_base_link"/>
    <child link="right_hand_thumb_1"/>
    <axis xyz="8.7274E-05 0 -1"/>
    <limit effort="1" lower="0" upper="2.0943951023931953" velocity="2"/>
  </joint>
  <link name="right_hand_thumb_2">
    <inertial>
      <origin rpy="0 0 0" xyz="-0.0238 0.01042 0.00478"/>
      <mass value="0.06526"/>
      <inertia ixx="1.378224e-05" ixy="5.95663e-06" ixz="-1.9799999999999998e-09" iyy="1.1840129999999999e-05" iyz="7.070000000000001e-09" izz="2.249189e-05"/>
    </inertial>
    <visual>
      <origin rpy="0 0 0" xyz="0 0 0"/>
      <geometry>
        <mesh filename="./inspire_hand_description/RH56F1/right/meshes/right_thumb_2.STL"/>
      </geometry>
      <material name="">
        <color rgba="0.25 0.25 0.25 1"/>
      </material>
    </visual>
    <collision>
      <origin rpy="0 0 0" xyz="0 0 0"/>
      <geometry>
        <mesh filename="./inspire_hand_description/RH56F1/right/meshes/right_thumb_2.STL"/>
      </geometry>
    </collision>
  </link>
  <joint name="right_hand_thumb_2_joint" type="revolute">
    <origin rpy="1.5707 0 -1.5708" xyz="0.0047995 0.013396 -0.0052536"/>
    <parent link="right_hand_thumb_1"/>
    <child link="right_hand_thumb_2"/>
    <axis xyz="0 0 -1"/>
    <limit effort="1" lower="0" upper="0.4745550236172582" velocity="2"/>
  </joint>
  <link name="right_hand_thumb_3">
    <inertial>
      <origin rpy="0 0 0" xyz="-0.01255 0.00331 0.00799"/>
      <mass value="0.01333"/>
      <inertia ixx="1.41987e-06" ixy="1.4979e-07" ixz="-6.3e-10" iyy="1.18482e-06" iyz="1.76e-09" izz="1.6920999999999999e-06"/>
    </inertial>
    <visual>
      <origin rpy="0 0 0" xyz="0 0 0"/>
      <geometry>
        <mesh filename="./inspire_hand_description/RH56F1/right/meshes/right_thumb_3.STL"/>
      </geometry>
      <material name="">
        <color rgba="0.25 0.25 0.25 1"/>
      </material>
    </visual>
    <collision>
      <origin rpy="0 0 0" xyz="0 0 0"/>
      <geometry>
        <mesh filename="./inspire_hand_description/RH56F1/right/meshes/right_thumb_3.STL"/>
      </geometry>
    </collision>
  </link>
  <joint name="right_hand_thumb_3_joint" type="revolute">
    <origin rpy="0 0 0" xyz="-0.029155 0.03869 -0.0032"/>
    <parent link="right_hand_thumb_2"/>
    <child link="right_hand_thumb_3"/>
    <axis xyz="0 0 -1"/>
    <limit effort="1" lower="0" upper="3.14" velocity="2"/>
    <mimic joint="right_hand_thumb_2_joint" multiplier="1.2953" offset="0"/>
  </joint>
  <link name="right_hand_thumb_4">
    <inertial>
      <origin rpy="0 0 0" xyz="-0.010199999999999999 0.00886 0.0067"/>
      <mass value="0.011439999999999999"/>
      <inertia ixx="9.4221e-07" ixy="1.6288e-07" ixz="-0.0" iyy="3.9966e-07" iyz="-0.0" izz="9.478099999999999e-07"/>
    </inertial>
    <visual>
      <origin rpy="0 0 0" xyz="0 0 0"/>
      <geometry>
        <mesh filename="./inspire_hand_description/RH56F1/right/meshes/right_thumb_4.STL"/>
      </geometry>
      <material name="">
        <color rgba="0.25 0.25 0.25 1"/>
      </material>
    </visual>
    <collision>
      <origin rpy="0 0 0" xyz="0 0 0"/>
      <geometry>
        <mesh filename="./inspire_hand_description/RH56F1/right/meshes/right_thumb_4.STL"/>
      </geometry>
    </collision>
  </link>
  <joint name="right_hand_thumb_4_joint" type="revolute">
    <origin rpy="0 0 0" xyz="-0.01441 0.014648 0.0013"/>
    <parent link="right_hand_thumb_3"/>
    <child link="right_hand_thumb_4"/>
    <axis xyz="0 0 -1"/>
    <limit effort="1" lower="0" upper="3.14" velocity="2"/>
    <mimic joint="right_hand_thumb_3_joint" multiplier="0.8962" offset="0"/>
  </joint>
  <link name="right_hand_thumb_force_sensor">
    <inertial>
      <origin rpy="0 0 0" xyz="0.0048965432924319 0.000707788830417878 -0.00883745365301308"/>
      <mass value="0"/>
      <inertia ixx="0" ixy="0" ixz="0" iyy="0" iyz="0" izz="0"/>
    </inertial>
    <visual>
      <origin rpy="0 0 0" xyz="0 0 0"/>
      <geometry>
        <mesh filename="./inspire_hand_description/RH56F1/right/meshes/thumb_force_sensor.STL"/>
      </geometry>
      <material name="">
        <color rgba="0.25 0.25 0.25 1"/>
      </material>
    </visual>
    <collision>
      <origin rpy="0 0 0" xyz="0 0 0"/>
      <geometry>
        <mesh filename="./inspire_hand_description/RH56F1/right/meshes/thumb_force_sensor.STL"/>
      </geometry>
    </collision>
  </link>
  <joint name="right_hand_thumb_force_sensor_joint" type="fixed">
    <origin rpy="-1.6222 -0.051489 -0.78543" xyz="-0.0082761 0.019128 0.0068"/>
    <parent link="right_hand_thumb_4"/>
    <child link="right_hand_thumb_force_sensor"/>
    <axis xyz="0 0 0"/>
  </joint>
  <link name="right_hand_thumb_tip">
    <inertial>
      <origin rpy="0 0 0" xyz="3.77562735170631E-05 -0.0101703967740828 -0.0136494381069971"/>
      <mass value="0"/>
      <inertia ixx="0" ixy="0" ixz="0" iyy="0" iyz="0" izz="0"/>
    </inertial>
    <visual>
      <origin rpy="0 0 0" xyz="0 0 0"/>
      <geometry>
        <mesh filename="./inspire_hand_description/RH56F1/right/meshes/thumb_tip.STL"/>
      </geometry>
      <material name="">
        <color rgba="0.25 0.25 0.25 1"/>
      </material>
    </visual>
    <collision>
      <origin rpy="0 0 0" xyz="0 0 0"/>
      <geometry>
        <mesh filename="./inspire_hand_description/RH56F1/right/meshes/thumb_tip.STL"/>
      </geometry>
    </collision>
  </link>
  <joint name="right_hand_thumb_tip_joint" type="fixed">
    <origin rpy="-1.2971 1.5647 0.01425" xyz="-0.017405 0.025196 0.0068001"/>
    <parent link="right_hand_thumb_4"/>
    <child link="right_hand_thumb_tip"/>
    <axis xyz="0 0 0"/>
  </joint>
  <link name="right_hand_index_1">
    <inertial>
      <origin rpy="0 0 0" xyz="0.00046 0.01509 0.0060999999999999995"/>
      <mass value="0.01111"/>
      <inertia ixx="2.04599e-06" ixy="-3.703e-08" ixz="1.77e-09" iyy="5.4029e-07" iyz="9.149e-08" izz="2.0895e-06"/>
    </inertial>
    <visual>
      <origin rpy="0 0 0" xyz="0 0 0"/>
      <geometry>
        <mesh filename="./inspire_hand_description/RH56F1/right/meshes/right_index_1.STL"/>
      </geometry>
      <material name="">
        <color rgba="0.25 0.25 0.25 1"/>
      </material>
    </visual>
    <collision>
      <origin rpy="0 0 0" xyz="0 0 0"/>
      <geometry>
        <mesh filename="./inspire_hand_description/RH56F1/right/meshes/right_index_1.STL"/>
      </geometry>
    </collision>
  </link>
  <joint name="right_hand_index_1_joint" type="revolute">
    <origin rpy="1.5097 0 0" xyz="0.00070751 0.034376 0.13554"/>
    <parent link="right_hand_base_link"/>
    <child link="right_hand_index_1"/>
    <axis xyz="0 0 -1"/>
    <limit effort="1" lower="0" upper="1.5285593588966337" velocity="2"/>
  </joint>
  <link name="right_hand_index_2">
    <inertial>
      <origin rpy="0 0 0" xyz="-0.00436 0.01623 0.005019999999999999"/>
      <mass value="0.0103"/>
      <inertia ixx="1.5669000000000002e-06" ixy="-2.2414e-07" ixz="1.3699999999999999e-08" iyy="2.9717e-07" iyz="7.84e-08" izz="1.5746300000000001e-06"/>
    </inertial>
    <visual>
      <origin rpy="0 0 0" xyz="0 0 0"/>
      <geometry>
        <mesh filename="./inspire_hand_description/RH56F1/right/meshes/right_index_2.STL"/>
      </geometry>
      <material name="">
        <color rgba="0.25 0.25 0.25 1"/>
      </material>
    </visual>
    <collision>
      <origin rpy="0 0 0" xyz="0 0 0"/>
      <geometry>
        <mesh filename="./inspire_hand_description/RH56F1/right/meshes/right_index_2.STL"/>
      </geometry>
    </collision>
  </link>
  <joint name="right_hand_index_2_joint" type="revolute">
    <origin rpy="0 0 0" xyz="0.0031056 0.032854 0.001"/>
    <parent link="right_hand_index_1"/>
    <child link="right_hand_index_2"/>
    <axis xyz="0 0 -1"/>
    <limit effort="1" lower="0" upper="3.14" velocity="2"/>
    <mimic joint="right_hand_index_1_joint" multiplier="1.1545" offset="0"/>
  </joint>
  <link name="right_hand_index_force_sensor">
    <inertial>
      <origin rpy="0 0 0" xyz="-0.000411923019764227 -0.0123118470405642 -0.00640361541021662"/>
      <mass value="0"/>
      <inertia ixx="0" ixy="0" ixz="0" iyy="0" iyz="0" izz="0"/>
    </inertial>
    <visual>
      <origin rpy="0 0 0" xyz="0 0 0"/>
      <geometry>
        <mesh filename="./inspire_hand_description/RH56F1/right/meshes/index_force_sensor.STL"/>
      </geometry>
      <material name="">
        <color rgba="0.25 0.25 0.25 1"/>
      </material>
    </visual>
    <collision>
      <origin rpy="0 0 0" xyz="0 0 0"/>
      <geometry>
        <mesh filename="./inspire_hand_description/RH56F1/right/meshes/index_force_sensor.STL"/>
      </geometry>
    </collision>
  </link>
  <joint name="right_hand_index_force_sensor_joint" type="fixed">
    <origin rpy="2.2782 1.4918 2.0953" xyz="0.005139 0.028671 0.0059996"/>
    <parent link="right_hand_index_2"/>
    <child link="right_hand_index_force_sensor"/>
    <axis xyz="0 0 0"/>
  </joint>
  <link name="right_hand_index_tip">
    <inertial>
      <origin rpy="0 0 0" xyz="-0.00116882659469011 -0.0177404684378123 -0.0152714634926817"/>
      <mass value="0"/>
      <inertia ixx="0" ixy="0" ixz="0" iyy="0" iyz="0" izz="0"/>
    </inertial>
    <visual>
      <origin rpy="0 0 0" xyz="0 0 0"/>
      <geometry>
        <mesh filename="./inspire_hand_description/RH56F1/right/meshes/index_tip.STL"/>
      </geometry>
      <material name="">
        <color rgba="0.25 0.25 0.25 1"/>
      </material>
    </visual>
    <collision>
      <origin rpy="0 0 0" xyz="0 0 0"/>
      <geometry>
        <mesh filename="./inspire_hand_description/RH56F1/right/meshes/index_tip.STL"/>
      </geometry>
    </collision>
  </link>
  <joint name="right_hand_index_tip_joint" type="fixed">
    <origin rpy="1.5446 1.5064 1.892" xyz="0.0049188 0.039631 0.006"/>
    <parent link="right_hand_index_2"/>
    <child link="right_hand_index_tip"/>
    <axis xyz="0 0 0"/>
  </joint>
  <link name="right_hand_middle_1">
    <inertial>
      <origin rpy="0 0 0" xyz="0.00046 0.01468 0.00701"/>
      <mass value="0.01111"/>
      <inertia ixx="2.04599e-06" ixy="-3.707e-08" ixz="-4.9e-10" iyy="5.3491e-07" iyz="-3.6e-09" izz="2.09487e-06"/>
    </inertial>
    <visual>
      <origin rpy="0 0 0" xyz="0 0 0"/>
      <geometry>
        <mesh filename="./inspire_hand_description/RH56F1/right/meshes/right_middle_1.STL"/>
      </geometry>
      <material name="">
        <color rgba="0.25 0.25 0.25 1"/>
      </material>
    </visual>
    <collision>
      <origin rpy="0 0 0" xyz="0 0 0"/>
      <geometry>
        <mesh filename="./inspire_hand_description/RH56F1/right/meshes/right_middle_1.STL"/>
      </geometry>
    </collision>
  </link>
  <joint name="right_hand_middle_1_joint" type="revolute">
    <origin rpy="1.5708 0 0" xyz="0.00070746 0.015767 0.13648"/>
    <parent link="right_hand_base_link"/>
    <child link="right_hand_middle_1"/>
    <axis xyz="0 0 -1"/>
    <limit effort="1" lower="0" upper="1.5285593588966337" velocity="2"/>
  </joint>
  <link name="right_hand_middle_2">
    <inertial>
      <origin rpy="0 0 0" xyz="-0.004019999999999999 0.01731 0.006"/>
      <mass value="0.01122"/>
      <inertia ixx="1.92755e-06" ixy="-2.9305e-07" ixz="-1.0000000000000001e-11" iyy="3.2973000000000003e-07" iyz="-1.0000000000000001e-11" izz="1.95229e-06"/>
    </inertial>
    <visual>
      <origin rpy="0 0 0" xyz="0 0 0"/>
      <geometry>
        <mesh filename="./inspire_hand_description/RH56F1/right/meshes/right_middle_2.STL"/>
      </geometry>
      <material name="">
        <color rgba="0.25 0.25 0.25 1"/>
      </material>
    </visual>
    <collision>
      <origin rpy="0 0 0" xyz="0 0 0"/>
      <geometry>
        <mesh filename="./inspire_hand_description/RH56F1/right/meshes/right_middle_2.STL"/>
      </geometry>
    </collision>
  </link>
  <joint name="right_hand_middle_2_joint" type="revolute">
    <origin rpy="0 0 0" xyz="0.0031056 0.032854 0.001"/>
    <parent link="right_hand_middle_1"/>
    <child link="right_hand_middle_2"/>
    <axis xyz="0 0 -1"/>
    <limit effort="1" lower="0" upper="3.14" velocity="2"/>
    <mimic joint="right_hand_middle_1_joint" multiplier="1.1545" offset="0"/>
  </joint>
  <link name="right_hand_middle_force_sensor">
    <inertial>
      <origin rpy="0 0 0" xyz="0.000471532938695406 -0.0138846665754712 -0.0063422335367961"/>
      <mass value="0"/>
      <inertia ixx="0" ixy="0" ixz="0" iyy="0" iyz="0" izz="0"/>
    </inertial>
    <visual>
      <origin rpy="0 0 0" xyz="0 0 0"/>
      <geometry>
        <mesh filename="./inspire_hand_description/RH56F1/right/meshes/middle_force_sensor.STL"/>
      </geometry>
      <material name="">
        <color rgba="0.25 0.25 0.25 1"/>
      </material>
    </visual>
    <collision>
      <origin rpy="0 0 0" xyz="0 0 0"/>
      <geometry>
        <mesh filename="./inspire_hand_description/RH56F1/right/meshes/middle_force_sensor.STL"/>
      </geometry>
    </collision>
  </link>
  <joint name="right_hand_middle_force_sensor_joint" type="fixed">
    <origin rpy="-2.9405 1.5184 3.1416" xyz="0.0059655 0.031551 0.0060998"/>
    <parent link="right_hand_middle_2"/>
    <child link="right_hand_middle_force_sensor"/>
    <axis xyz="0 0 0"/>
  </joint>
  <link name="right_hand_middle_tip">
    <inertial>
      <origin rpy="0 0 0" xyz="-1.56032137985686E-05 -0.0191696833676399 -0.0160122884402975"/>
      <mass value="0"/>
      <inertia ixx="0" ixy="0" ixz="0" iyy="0" iyz="0" izz="0"/>
    </inertial>
    <visual>
      <origin rpy="0 0 0" xyz="0 0 0"/>
      <geometry>
        <mesh filename="./inspire_hand_description/RH56F1/right/meshes/middle_tip.STL"/>
      </geometry>
      <material name="">
        <color rgba="0.25 0.25 0.25 1"/>
      </material>
    </visual>
    <collision>
      <origin rpy="0 0 0" xyz="0 0 0"/>
      <geometry>
        <mesh filename="./inspire_hand_description/RH56F1/right/meshes/middle_tip.STL"/>
      </geometry>
    </collision>
  </link>
  <joint name="right_hand_middle_tip_joint" type="fixed">
    <origin rpy="-0.3273 1.5691 0" xyz="0.0059647 0.042512 0.0060998"/>
    <parent link="right_hand_middle_2"/>
    <child link="right_hand_middle_tip"/>
    <axis xyz="0 0 0"/>
  </joint>
  <link name="right_hand_ring_1">
    <inertial>
      <origin rpy="0 0 0" xyz="0.00046 0.0143 0.00777"/>
      <mass value="0.01111"/>
      <inertia ixx="2.04599e-06" ixy="-3.699e-08" ixz="-2.43e-09" iyy="5.395599999999999e-07" iyz="-8.511e-08" izz="2.09023e-06"/>
    </inertial>
    <visual>
      <origin rpy="0 0 0" xyz="0 0 0"/>
      <geometry>
        <mesh filename="./inspire_hand_description/RH56F1/right/meshes/right_ring_1.STL"/>
      </geometry>
      <material name="">
        <color rgba="0.25 0.25 0.25 1"/>
      </material>
    </visual>
    <collision>
      <origin rpy="0 0 0" xyz="0 0 0"/>
      <geometry>
        <mesh filename="./inspire_hand_description/RH56F1/right/meshes/right_ring_1.STL"/>
      </geometry>
    </collision>
  </link>
  <joint name="right_hand_ring_1_joint" type="revolute">
    <origin rpy="1.6232 0 0" xyz="0.00070746 -0.0030876 0.13643"/>
    <parent link="right_hand_base_link"/>
    <child link="right_hand_ring_1"/>
    <axis xyz="0 0 -1"/>
    <limit effort="1" lower="0" upper="1.5285593588966337" velocity="2"/>
  </joint>
  <link name="right_hand_ring_2">
    <inertial>
      <origin rpy="0 0 0" xyz="-0.00436 0.015560000000000001 0.0068200000000000005"/>
      <mass value="0.0103"/>
      <inertia ixx="1.5669000000000002e-06" ixy="-2.2425e-07" ixz="-1.1759999999999999e-08" iyy="2.959e-07" iyz="-6.729e-08" izz="1.5758900000000002e-06"/>
    </inertial>
    <visual>
      <origin rpy="0 0 0" xyz="0 0 0"/>
      <geometry>
        <mesh filename="./inspire_hand_description/RH56F1/right/meshes/right_ring_2.STL"/>
      </geometry>
      <material name="">
        <color rgba="0.25 0.25 0.25 1"/>
      </material>
    </visual>
    <collision>
      <origin rpy="0 0 0" xyz="0 0 0"/>
      <geometry>
        <mesh filename="./inspire_hand_description/RH56F1/right/meshes/right_ring_2.STL"/>
      </geometry>
    </collision>
  </link>
  <joint name="right_hand_ring_2_joint" type="revolute">
    <origin rpy="0 0 0" xyz="0.0031056 0.032854 0.001"/>
    <parent link="right_hand_ring_1"/>
    <child link="right_hand_ring_2"/>
    <axis xyz="0 0 -1"/>
    <limit effort="1" lower="0" upper="3.14" velocity="2"/>
    <mimic joint="right_hand_ring_1_joint" multiplier="1.1545" offset="0"/>
  </joint>
  <link name="right_hand_ring_force_sensor">
    <inertial>
      <origin rpy="0 0 0" xyz="0.00109767398054146 -0.0122697321740606 -0.00640361768517552"/>
      <mass value="0"/>
      <inertia ixx="0" ixy="0" ixz="0" iyy="0" iyz="0" izz="0"/>
    </inertial>
    <visual>
      <origin rpy="0 0 0" xyz="0 0 0"/>
      <geometry>
        <mesh filename="./inspire_hand_description/RH56F1/right/meshes/ring_force_sensor.STL"/>
      </geometry>
      <material name="">
        <color rgba="0.25 0.25 0.25 1"/>
      </material>
    </visual>
    <collision>
      <origin rpy="0 0 0" xyz="0 0 0"/>
      <geometry>
        <mesh filename="./inspire_hand_description/RH56F1/right/meshes/ring_force_sensor.STL"/>
      </geometry>
    </collision>
  </link>
  <joint name="right_hand_ring_force_sensor_joint" type="fixed">
    <origin rpy="-2.2589 1.4899 -2.4386" xyz="0.005139 0.028671 0.0059996"/>
    <parent link="right_hand_ring_2"/>
    <child link="right_hand_ring_force_sensor"/>
    <axis xyz="0 0 0"/>
  </joint>
  <link name="right_hand_ring_tip">
    <inertial>
      <origin rpy="0 0 0" xyz="0.000974578618407327 -0.0177521976538281 -0.015271465020787"/>
      <mass value="0"/>
      <inertia ixx="0" ixy="0" ixz="0" iyy="0" iyz="0" izz="0"/>
    </inertial>
    <visual>
      <origin rpy="0 0 0" xyz="0 0 0"/>
      <geometry>
        <mesh filename="./inspire_hand_description/RH56F1/right/meshes/ring_tip.STL"/>
      </geometry>
      <material name="">
        <color rgba="0.25 0.25 0.25 1"/>
      </material>
    </visual>
    <collision>
      <origin rpy="0 0 0" xyz="0 0 0"/>
      <geometry>
        <mesh filename="./inspire_hand_description/RH56F1/right/meshes/ring_tip.STL"/>
      </geometry>
    </collision>
  </link>
  <joint name="right_hand_ring_tip_joint" type="fixed">
    <origin rpy="-1.5409 1.5145 -1.1936" xyz="0.0049188 0.039631 0.006"/>
    <parent link="right_hand_ring_2"/>
    <child link="right_hand_ring_tip"/>
    <axis xyz="0 0 0"/>
  </joint>
  <link name="right_hand_little_1">
    <inertial>
      <origin rpy="0 0 0" xyz="0.00046 0.013869999999999999 0.0085"/>
      <mass value="0.01111"/>
      <inertia ixx="2.04599e-06" ixy="-3.6810000000000003e-08" ixz="-4.360000000000001e-09" iyy="5.527e-07" iyz="-1.6568e-07" izz="2.07708e-06"/>
    </inertial>
    <visual>
      <origin rpy="0 0 0" xyz="0 0 0"/>
      <geometry>
        <mesh filename="./inspire_hand_description/RH56F1/right/meshes/right_little_1.STL"/>
      </geometry>
      <material name="">
        <color rgba="0.25 0.25 0.25 1"/>
      </material>
    </visual>
    <collision>
      <origin rpy="0 0 0" xyz="0 0 0"/>
      <geometry>
        <mesh filename="./inspire_hand_description/RH56F1/right/meshes/right_little_1.STL"/>
      </geometry>
    </collision>
  </link>
  <joint name="right_hand_little_1_joint" type="revolute">
    <origin rpy="1.6755 0 0" xyz="0.00070753 -0.021451 0.13527"/>
    <parent link="right_hand_base_link"/>
    <child link="right_hand_little_1"/>
    <axis xyz="0 0 -1"/>
    <limit effort="1" lower="0" upper="1.5285593588966337" velocity="2"/>
  </joint>
  <link name="right_hand_little_2">
    <inertial>
      <origin rpy="0 0 0" xyz="-0.004070000000000001 0.01192 0.00728"/>
      <mass value="0.00839"/>
      <inertia ixx="9.3539e-07" ixy="-1.6843e-07" ixz="-1.7670000000000002e-08" iyy="2.4681e-07" iyz="-7.359e-08" izz="9.379400000000001e-07"/>
    </inertial>
    <visual>
      <origin rpy="0 0 0" xyz="0 0 0"/>
      <geometry>
        <mesh filename="./inspire_hand_description/RH56F1/right/meshes/right_little_2.STL"/>
      </geometry>
      <material name="">
        <color rgba="0.25 0.25 0.25 1"/>
      </material>
    </visual>
    <collision>
      <origin rpy="0 0 0" xyz="0 0 0"/>
      <geometry>
        <mesh filename="./inspire_hand_description/RH56F1/right/meshes/right_little_2.STL"/>
      </geometry>
    </collision>
  </link>
  <joint name="right_hand_little_2_joint" type="revolute">
    <origin rpy="0 0 0" xyz="0.0031057 0.032854 0.001"/>
    <parent link="right_hand_little_1"/>
    <child link="right_hand_little_2"/>
    <axis xyz="0 0 -1"/>
    <limit effort="1" lower="0" upper="3.14" velocity="2"/>
    <mimic joint="right_hand_little_1_joint" multiplier="1.1545" offset="0"/>
  </joint>
  <link name="right_hand_little_force_sensor">
    <inertial>
      <origin rpy="0 0 0" xyz="0.00132747018137316 -0.00844356465788672 -0.00651118992676019"/>
      <mass value="0"/>
      <inertia ixx="0" ixy="0" ixz="0" iyy="0" iyz="0" izz="0"/>
    </inertial>
    <visual>
      <origin rpy="0 0 0" xyz="0 0 0"/>
      <geometry>
        <mesh filename="./inspire_hand_description/RH56F1/right/meshes/little_force_sensor.STL"/>
      </geometry>
      <material name="">
        <color rgba="0.25 0.25 0.25 1"/>
      </material>
    </visual>
    <collision>
      <origin rpy="0 0 0" xyz="0 0 0"/>
      <geometry>
        <mesh filename="./inspire_hand_description/RH56F1/right/meshes/little_force_sensor.STL"/>
      </geometry>
    </collision>
  </link>
  <joint name="right_hand_little_force_sensor_joint" type="fixed">
    <origin rpy="-1.9859 1.443 -2.1833" xyz="0.0051314 0.021582 0.0059959"/>
    <parent link="right_hand_little_2"/>
    <child link="right_hand_little_force_sensor"/>
    <axis xyz="0 0 0"/>
  </joint>
  <link name="right_hand_little_tip">
    <inertial>
      <origin rpy="0 0 0" xyz="0.00157850769633822 -0.0143797245335056 -0.0134611237924734"/>
      <mass value="0"/>
      <inertia ixx="0" ixy="0" ixz="0" iyy="0" iyz="0" izz="0"/>
    </inertial>
    <visual>
      <origin rpy="0 0 0" xyz="0 0 0"/>
      <geometry>
        <mesh filename="./inspire_hand_description/RH56F1/right/meshes/little_tip.STL"/>
      </geometry>
      <material name="">
        <color rgba="0.25 0.25 0.25 1"/>
      </material>
    </visual>
    <collision>
      <origin rpy="0 0 0" xyz="0 0 0"/>
      <geometry>
        <mesh filename="./inspire_hand_description/RH56F1/right/meshes/little_tip.STL"/>
      </geometry>
    </collision>
  </link>
  <joint name="right_hand_little_tip_joint" type="fixed">
    <origin rpy="-1.5577 1.4597 -1.2296" xyz="0.0051203 0.032544 0.0059927"/>
    <parent link="right_hand_little_2"/>
    <child link="right_hand_little_tip"/>
    <axis xyz="0 0 0"/>
  </joint>
  <joint name="right_arm_to_mount" type="fixed">
    <parent link="openarm_right_link7"/>
    <child link="right_hand_mount"/>
    <origin rpy="0 0 0" xyz="0 0 0.0495"/>
  </joint>
  <joint name="right_mount_to_rh56f1" type="fixed">
    <parent link="right_hand_mount"/>
    <child link="right_hand_base_link"/>
    <origin rpy="0 0 -1.5708" xyz="0 0 0.006"/>
  </joint>
</robot>
