<?xml version="1.0" encoding="utf-8"?>
<!-- =================================================================================== -->
<!-- |    This document was autogenerated by xacro from xarm6_robot.urdf.xacro         | -->
<!-- |    EDITING THIS FILE BY HAND IS NOT RECOMMENDED                                 | -->
<!-- =================================================================================== -->
<robot name="xarm6">

    <!--
      Material colors
    -->

    <!-- Basic colors -->
  <material name="Black">
    <color rgba="0.0 0.0 0.0 1.0"/>
  </material>
  <material name="Red">
    <color rgba="0.8 0.0 0.0 1.0"/>
  </material>
  <material name="White">
    <color rgba="1.0 1.0 1.0 1.0"/>
  </material>
  <material name="Silver">
    <color rgba="0.753 0.753 0.753 1.0"/>
  </material>

    <!--
    Base
  -->

  <!-- Base link -->
  <link name="world"/>
  <joint name="world_joint" type="fixed">
    <parent link="world"/>
    <child link="allegro_root0"/>
    <origin rpy="0 0 0" xyz="0 0 0"/>
  </joint>


  <link name="allegro_root0">
    <inertial>
      <origin rpy="0 0 0" xyz="0 0 0"/>
      <mass value="4.00000"/>
      <inertia ixx="1e-4" ixy="0" ixz="0" iyy="1e-4" iyz="0" izz="1e-4"/>
    </inertial>
  </link>
    <link name="allegro_root1">
    <inertial>
      <mass value="0.05"/>
      <inertia ixx="1e-4" ixy="0.0" ixz="0.0" iyy="1e-4" iyz="0.0" izz="1e-4"/>
    </inertial>
  </link>
  <link name="allegro_root2">
    <inertial>
      <mass value="0.05"/>
      <inertia ixx="1e-4" ixy="0.0" ixz="0.0" iyy="1e-4" iyz="0.0" izz="1e-4"/>
    </inertial>
  </link>
    <link name="allegro_root3">
    <inertial>
      <mass value="0.05"/>
      <inertia ixx="1e-4" ixy="0.0" ixz="0.0" iyy="1e-4" iyz="0.0" izz="1e-4"/>
    </inertial>
  </link>
  <link name="allegro_root4">
    <inertial>
      <mass value="0.05"/>
      <inertia ixx="1e-4" ixy="0.0" ixz="0.0" iyy="1e-4" iyz="0.0" izz="1e-4"/>
    </inertial>
  </link>
  <link name="allegro_root5">
    <inertial>
      <mass value="0.05"/>
      <inertia ixx="1e-4" ixy="0.0" ixz="0.0" iyy="1e-4" iyz="0.0" izz="1e-4"/>
    </inertial>
  </link>
  
  <joint name="x_joint" type="prismatic">
    <parent link="allegro_root0"/>
    <child link="allegro_root1"/>
    <axis xyz="1 0 0"/>
    <limit effort="100" lower="-50.0" upper="50.0" velocity="20"/>
  </joint>
  <joint name="y_joint" type="prismatic">
    <parent link="allegro_root1"/>
    <child link="allegro_root2"/>
    <axis xyz="0 1 0"/>
    <limit effort="100" lower="-50.0" upper="50.0" velocity="20"/>
  </joint>
  <joint name="z_joint" type="prismatic">
    <parent link="allegro_root2"/>
    <child link="allegro_root3"/>
    <axis xyz="0 0 1"/>
    <limit effort="100" lower="-50.0" upper="50.0" velocity="20"/>
  </joint>

  <joint name="x_rotation_joint" type="revolute">
    <parent link="allegro_root3"/>
    <child link="allegro_root4"/>
    <axis xyz="1 0 0"/>
    <limit effort="100" lower="-6.28" upper="6.28" velocity="20"/>
  </joint>
  <joint name="y_rotation_joint" type="revolute">
    <parent link="allegro_root4"/>
    <child link="allegro_root5"/>
    <axis xyz="0 1 0"/>
    <limit effort="100" lower="-6.28" upper="6.28" velocity="20"/>
  </joint>
  <joint name="z_rotation_joint" type="revolute">
    <parent link="allegro_root5"/>
    <child link="palm_link"/>
    <axis xyz="0 0 1"/>
    <!-- <origin rpy="-0.00000 -0.00000 0" xyz="0 0 0"/> -->
    <limit effort="100" lower="-6.28" upper="6.28" velocity="20"/>
  </joint>

  <link name="palm_link">
    <inertial>
      <mass value="0.4167"/>
      <origin rpy="0 0 0" xyz="0 0 0"/>
      <inertia ixx="1e-4" ixy="0" ixz="0" iyy="1e-4" iyz="0" izz="1e-4"/>
    </inertial>
    <visual>
      <geometry>
        <mesh filename="meshes/allegro/palm_link.obj"/>
      </geometry>
      <origin rpy="0 0 0" xyz="0 0 0 "/>
      <material name="Grey">
        <color rgba="0.2 0.2 0.2 1"/>
      </material>
    </visual>
    <collision>
      <origin rpy="0.0 0 0" xyz="0 0 0"/>
      <geometry>
        <mesh filename="meshes/allegro/palm_link.obj"/>
      </geometry>
    </collision>
  </link>

  <link name="contact_sensor1">
    <inertial>
      <mass value="0.0001"/>
      <origin rpy="0 0 0" xyz="0 0 0"/>
      <inertia ixx="1e-4" ixy="0" ixz="0" iyy="1e-4" iyz="0" izz="1e-4"/>
    </inertial>
    <visual>
      <geometry>
        <mesh filename="meshes/contact/palm.obj"/>
      </geometry>
      <origin rpy="0 0 0" xyz="0.0125 0.025 -0.065"/>
      <material name="Red">
        <color rgba="0.8 0.0 0.0 1.0"/>
      </material>
    </visual>
  </link>

  <joint name="contact_sensor1_attach" type="fixed">
    <parent link="palm_link"/>
    <child link="contact_sensor1"/>
    <origin rpy="0 0 0" xyz="0 0 0.0423"/>
  </joint>

    <link name="contact_sensor2">
    <inertial>
      <mass value="0.0001"/>
      <origin rpy="0 0 0" xyz="0 0 0"/>
      <inertia ixx="1e-4" ixy="0" ixz="0" iyy="1e-4" iyz="0" izz="1e-4"/>
    </inertial>
    <visual>
      <geometry>
        <mesh filename="meshes/contact/palm.obj"/>
      </geometry>
      <origin rpy="0 0 0" xyz="0.0125 -0.019 -0.065"/>
      <material name="Red">
        <color rgba="0.8 0.0 0.0 1.0"/>
      </material>
    </visual>
  </link>

  <joint name="contact_sensor2_attach" type="fixed">
    <parent link="palm_link"/>
    <child link="contact_sensor2"/>
    <origin rpy="0 0 0" xyz="0 0 0.0423"/>
  </joint>

    <link name="contact_sensor3">
    <inertial>
      <mass value="0.0001"/>
      <origin rpy="0 0 0" xyz="0 0 0"/>
      <inertia ixx="1e-4" ixy="0" ixz="0" iyy="1e-4" iyz="0" izz="1e-4"/>
    </inertial>
    <visual>
      <geometry>
        <mesh filename="meshes/contact/palm.obj"/>
      </geometry>
      <origin rpy="0 0 0" xyz="0.0125 -0.019 -0.105"/>
      <material name="Red">
        <color rgba="0.8 0.0 0.0 1.0"/>
      </material>
    </visual>
  </link>

  <joint name="contact_sensor3_attach" type="fixed">
    <parent link="palm_link"/>
    <child link="contact_sensor3"/>
    <origin rpy="0 0 0" xyz="0 0 0.0423"/>
  </joint>

  <!-- ============================================================================= -->
  <!-- FINGERS -->
  <!-- RIGHT HAND due to which finger is number 0 -->
  <!-- for LEFT HAND switch the sign of the **offset_origin_y** and **finger_angle_r** parameters-->
  <link name="thumb_base">
    <visual>
      <geometry>
        <mesh filename="meshes/allegro/thumb_base.STL"/>
      </geometry>
      <material name="black">
        <color rgba=".2 .2 .2 1"/>
      </material>
    </visual>
    <collision>
      <geometry>
        <mesh filename="meshes/allegro/thumb_base.STL"/>
      </geometry>
    </collision>
    <inertial>
      <mass value="0.0798"/>
      <inertia ixx="5.1458e-5" ixy="0" ixz="0" iyy="5.1458e-5" iyz="0" izz="6.125e-5"/>
    </inertial>
  </link>
  <joint name="thumb_base" type="revolute">
    <axis xyz="-1 0 0"/>
    <limit effort="15" lower="0.36" upper="1.496" velocity="7"/>
    <parent link="palm_link"/>
    <child link="thumb_base"/>
    <origin rpy="0 -1.65806278845 -1.5707963259" xyz="-0.0182 0.019333 -0.045987"/>
    <dynamics damping="0.0001" friction="0.035"/>
  </joint>
  <link name="thumb_proximal">
    <visual>
      <geometry>
        <mesh filename="meshes/allegro/thumb_proximal.STL"/>  
      </geometry>
      <material name="black">
        <color rgba=".2 .2 .2 1"/>
      </material>
    </visual>
    <collision>
      <geometry>
        <mesh filename="meshes/allegro/thumb_proximal.STL"/>  
      </geometry>
    </collision>
    <inertial>
      <mass value="0.0114"/>
      <origin rpy="0 0 0" xyz="0 0 0"/>
      <inertia ixx="4.24250866667e-06" ixy="1.032087e-06" ixz="1.603525e-06" iyy="4.52362633333e-06" iyz="1.44808125e-06" izz="4.24250866667e-06"/>
    </inertial>
  </link>
  <joint name="thumb_proximal" type="revolute">
    <axis xyz="0 0 1"/>
    <limit effort="15" lower="-0.204" upper="1.263" velocity="7"/>
    <parent link="thumb_base"/>
    <child link="thumb_proximal"/>
    <origin xyz="-0.027 0.005 0.0399"/>
      <dynamics damping="0.0001" friction="0.035"/>
  </joint>
  <!-- [LINK 14] -->
  <link name="thumb_medial">
    <visual>
      <geometry>
        <mesh filename="meshes/allegro/thumb_medial.STL"/>
      </geometry>
      <material name="black">
        <color rgba=".2 .2 .2 1"/>
      </material>
    </visual>
    <collision>
      <geometry>
        <mesh filename="meshes/allegro/thumb_medial.STL"/>
      </geometry>
    </collision>
    <inertial>
      <mass value="0.0402"/>
      <origin rpy="0 0 0" xyz="0 0 0"/>
      <inertia ixx="4.30439933333e-05" ixy="9.57068e-06" ixz="5.1205e-06" iyy="1.44451933333e-05" iyz="1.342825e-05" izz="4.30439933333e-05"/>
    </inertial>
  </link>
  <joint name="thumb_medial" type="revolute">
    <axis xyz="0 1 0"/>
    <limit effort="15" lower="-0.289" upper="1.744" velocity="7"/>
    <parent link="thumb_proximal"/>
    <child link="thumb_medial"/>
    <origin xyz="0 0 0.0177"/>
      <dynamics damping="0.0001" friction="0.035"/>
  </joint>
  <!-- [LINK 15] -->
  <link name="thumb_distal">
    <visual>
      <geometry>
        <mesh filename="meshes/allegro/thumb_distal.STL"/>
      </geometry>
      <material name="black">
        <color rgba=".2 .2 .2 1"/>
      </material>
    </visual>
    <collision>
      <geometry>
        <mesh filename="meshes/allegro/thumb_distal.STL"/>
      </geometry>
    </collision>
    <inertial>
      <mass value="0.0408"/>
      <origin rpy="0 0 0" xyz="0 0 0"/>
      <inertia ixx="3.29223173333e-05" ixy="8.042076e-06" ixz="5.2283e-06" iyy="1.47493026667e-5" iyz="1.1283525e-5" izz="3.29223173333e-05"/>
    </inertial>
  </link>
  <joint name="thumb_distal" type="revolute">
    <axis xyz="0 1 0"/>
    <limit effort="15" lower="-0.26" upper="1.819" velocity="7"/>
    <parent link="thumb_medial"/>
    <child link="thumb_distal"/>
    <origin xyz="0 0 0.0514"/>
      <dynamics damping="0.0001" friction="0.035"/>
  </joint>
  <!-- [FINGER TIP] -->
  <link name="thumb_tip">
    <visual>
      <geometry>
        <mesh filename="meshes/allegro/thumb_tip.STL"/>
      </geometry>
      <material name="white">
        <color rgba=".9 .9 .9 1"/>
      </material>
    </visual>
    <collision>
      <geometry>
        <sphere radius="0.0145"/>
      </geometry>
    </collision>
    <inertial>
      <mass value="0.0166"/>
      <origin rpy="0 0 0" xyz="0 0 0"/>
      <inertia ixx="9.68e-07" ixy="0" ixz="0" iyy="9.68e-07" iyz="0" izz="9.68e-07"/>
    </inertial>
  </link>
  <joint name="thumb_tip" type="fixed">
    <parent link="thumb_distal"/>
    <child link="thumb_tip"/>
    <origin rpy="0 0 0" xyz="0 0 0.0423"/>
  </joint>
  <link name="index_base">
    <visual>
      <geometry>
        <mesh filename="meshes/allegro/primary_base.STL"/>
      </geometry>
      <material name="black"/>
    </visual>
    <collision>
      <geometry>
        <mesh filename="meshes/allegro/primary_base.STL"/>
      </geometry>
    </collision>
    <inertial>
      <mass value="0.0114"/>
      <origin xyz="0 0 0"/>
      <inertia ixx="5.1458e-05" iyy="5.1458e-05" izz="6.125e-05" ixy="0" ixz="0" iyz="0"/>	
    </inertial>
  </link>
  <joint name="index_base" type="revolute">
    <axis xyz="0 0 1"/>
    <limit effort="15" lower="-0.57" upper="0.57" velocity="7"/>
    <parent link="palm_link"/>
    <child link="index_base"/>
    <origin rpy="-0.08726646255 0 0" xyz="0 0.0435 -0.001542"/> 
      <dynamics damping="0.0001" friction="0.035"/>
  </joint>
  <!-- [LINK 1, 5, 9] -->
  <link name="index_proximal">
    <visual>
      <geometry>
        <mesh filename="meshes/allegro/primary_proximal.STL"/>
      </geometry>
      <material name="black"/>
    </visual>
    <collision>
      <geometry>
        <mesh filename="meshes/allegro/primary_proximal.STL"/>
      </geometry>
      <origin rpy="0 0 0" xyz="0 0 0.027"/>
    </collision>
    <inertial>
      <mass value="0.0712"/>
      <origin xyz="0.027 0 0"/>
      <inertia ixx="6.39979e-06" iyy="8.88687e-05" izz="9.13751e-05" ixy="-3.26531e-06" ixz="1.23963e-05" iyz="2.07384e-05"/>	
    </inertial>
  </link>
  <joint name="index_proximal" type="revolute">
    <limit effort="15" lower="-0.296" upper="1.71" velocity="7"/>
    <axis xyz="0 1 0"/>
    <parent link="index_base"/>
    <child link="index_proximal"/>
    <origin xyz="0 0 0.0164"/>
      <dynamics damping="0.0001" friction="0.035"/>
  </joint>
  <!-- [LINK 2, 6, 10]-->
  <link name="index_medial">
    <visual>
      <geometry>
        <mesh filename="meshes/allegro/primary_medial.STL"/>
      </geometry>
      <material name="black"/>
    </visual>
    <collision>
      <geometry>
        <mesh filename="meshes/allegro/primary_medial.STL"/>
      </geometry>
    </collision>
    <inertial>
      <mass value="0.0376"/>
      <origin xyz="0.039 0 0"/>
      <inertia ixx="7.04217e-05" iyy="3.95744e-05" izz="6.61125e-05" ixy="-9.64342e-05" ixz="5.8796e-05" iyz="-3.62996e-05"/>	
    </inertial>
  </link>
  <joint name="index_medial" type="revolute">
    <axis xyz="0 1 0"/>
    <limit effort="15" lower="-0.274" upper="1.809" velocity="7"/>
    <parent link="index_proximal"/>
    <child link="index_medial"/>
    <origin xyz="0 0 0.054"/>
      <dynamics damping="0.0001" friction="0.035"/>
  </joint>
  <link name="index_distal">
    <visual>
      <geometry>
        <mesh filename="meshes/allegro/primary_distal.STL"/>
      </geometry>
      <material name="black"/>
    </visual>
    <collision>
      <geometry>
        <mesh filename="meshes/allegro/primary_distal.STL"/>
      </geometry>
    </collision>
    <inertial>
      <mass value="0.0094"/>
      <origin xyz="0.039 0 0"/>
      <inertia ixx="7.04217e-05" iyy="3.95744e-05" izz="6.61125e-05" ixy="-9.64342e-05" ixz="5.8796e-05" iyz="-3.62996e-05"/>	
    </inertial>
  </link>
  <joint name="index_distal" type="revolute">
    <axis xyz="0 1 0"/>
    <limit effort="15" lower="-0.327" upper="1.718" velocity="7"/>
    <parent link="index_medial"/>
    <child link="index_distal"/>
    <origin xyz="0 0 0.0384"/>
      <dynamics damping="0.0001" friction="0.035"/>
  </joint>
  <!-- [FINGER TIP] -->
  <link name="index_tip">
    <visual>
      <geometry>
        <mesh filename="meshes/allegro/primary_tip.STL"/>
      </geometry>
      <material name="white">
        <color rgba=".9 .9 .9 1"/>
      </material>
    </visual>
    <collision>
      <geometry>
        <sphere radius="0.015"/>  
      </geometry>
    </collision>
    <inertial>
      <mass value="0.0166"/>
      <origin rpy="0 0 0" xyz="0 0 0"/>
      <inertia ixx="9.68e-07" ixy="0" ixz="0" iyy="9.68e-07" iyz="0" izz="9.68e-07"/>
    </inertial>
  </link>  <!-- need to be fixed later-->
  <joint name="index_tip" type="fixed">
    <parent link="index_distal"/>
    <child link="index_tip"/>
    <origin rpy="0 0 0" xyz="0 0 0.0267"/>
  </joint>
  <!-- [LINK 0, 4, 8] -->
  <link name="middle_base">
    <visual>
      <geometry>
        <mesh filename="meshes/allegro/primary_base.STL"/>
      </geometry>
      <material name="black"/>
    </visual>
    <collision>
      <geometry>
        <mesh filename="meshes/allegro/primary_base.STL"/>
      </geometry>
    </collision>
    <inertial>
      <mass value="0.0114"/>
      <origin xyz="0 0 0"/>
      <inertia ixx="5.1458e-05" iyy="5.1458e-05" izz="6.125e-05" ixy="0" ixz="0" iyz="0"/>	
    </inertial>
  </link>
  <joint name="middle_base" type="revolute">
    <axis xyz="0 0 1"/>
    <limit effort="15" lower="-0.57" upper="0.57" velocity="7"/>
    <parent link="palm_link"/>
    <child link="middle_base"/>
    <dynamics damping="0.0414019" friction="0.0523963"/>
  </joint>
  <!-- [LINK 1, 5, 9] -->
  <link name="middle_proximal">
    <visual>
      <geometry>
        <mesh filename="meshes/allegro/primary_proximal.STL"/>
      </geometry>
      <material name="black"/>
    </visual>
    <collision>
      <geometry>
        <mesh filename="meshes/allegro/primary_proximal.STL"/>
      </geometry>
    </collision>
    <inertial>
      <mass value="0.0712"/>
      <origin xyz="0.027 0 0"/>
      <inertia ixx="6.39979e-06" iyy="8.88687e-05" izz="9.13751e-05" ixy="-3.26531e-06" ixz="1.23963e-05" iyz="2.07384e-05"/>	
    </inertial>
  </link>
  <joint name="middle_proximal" type="revolute">
    <limit effort="15" lower="-0.296" upper="1.71" velocity="7"/>
    <axis xyz="0 1 0"/>
    <parent link="middle_base"/>
    <child link="middle_proximal"/>
    <origin xyz="0 0 0.0164"/>
      <dynamics damping="0.0001" friction="0.035"/>
  </joint>
  <!-- [LINK 2, 6, 10]-->
  <link name="middle_medial">
    <visual>
      <geometry>
        <mesh filename="meshes/allegro/primary_medial.STL"/>
      </geometry>
      <material name="black"/>
    </visual>
    <collision>
      <geometry>
        <mesh filename="meshes/allegro/primary_medial.STL"/>
      </geometry>
    </collision>
    <inertial>
      <mass value="0.0376"/>
      <origin xyz="0.039 0 0"/>
      <inertia ixx="7.04217e-05" iyy="3.95744e-05" izz="6.61125e-05" ixy="-9.64342e-05" ixz="5.8796e-05" iyz="-3.62996e-05"/>	
    </inertial>
  </link>
  <joint name="middle_medial" type="revolute">
    <axis xyz="0 1 0"/>
    <limit effort="15" lower="-0.274" upper="1.809" velocity="7"/>
    <parent link="middle_proximal"/>
    <child link="middle_medial"/>
    <origin xyz="0 0 0.054"/>
      <dynamics damping="0.0001" friction="0.035"/>
  </joint>
  <!-- [LINK 3, 7, 11] -->
  <link name="middle_distal">
    <visual>
      <geometry>
        <mesh filename="meshes/allegro/primary_distal.STL"/>
      </geometry>
      <material name="black"/>
    </visual>
    <collision>
      <geometry>
        <mesh filename="meshes/allegro/primary_distal.STL"/>
      </geometry>
    </collision>
    <inertial>
      <mass value="0.0094"/>
      <origin rpy="0 0 0" xyz="0 0 0"/>
      <inertia ixx="4.701248e-06" ixy="1.255968e-06" ixz="1.2936e-06" iyy="3.649312e-06" iyz="1.7622e-06" izz="4.701248e-06"/>
    </inertial>
  </link>
  <joint name="middle_distal" type="revolute">
    <axis xyz="0 1 0"/>
    <limit effort="15" lower="-0.327" upper="1.718" velocity="7"/>
    <parent link="middle_medial"/>
    <child link="middle_distal"/>
    <origin xyz="0 0 0.0384"/>
      <dynamics damping="0.0001" friction="0.035"/>
  </joint>
  <link name="middle_tip">
    <visual>
      <geometry>
        <mesh filename="meshes/allegro/primary_tip.STL"/>
      </geometry>
      <material name="white">
        <color rgba=".9 .9 .9 1"/>
      </material>
    </visual>
    <collision>
      <geometry>
        <sphere radius="0.015"/>  
      </geometry>
    </collision>
    <inertial>
      <mass value="0.0166"/>
      <origin rpy="0 0 0" xyz="0 0 0"/>
      <inertia ixx="9.68e-07" ixy="0" ixz="0" iyy="9.68e-07" iyz="0" izz="9.68e-07"/>
    </inertial>
  </link>
  <joint name="middle_tip" type="fixed">
    <parent link="middle_distal"/>
    <child link="middle_tip"/>
    <origin rpy="0 0 0" xyz="0 0 0.0267"/>
  </joint>
  <!-- [LINK 0, 4, 8] -->
  <link name="ring_base">
    <visual>
      <geometry>
        <mesh filename="meshes/allegro/primary_base.STL"/>
      </geometry>
      <material name="black"/>
    </visual>
    <collision>
      <geometry>
        <mesh filename="meshes/allegro/primary_base.STL"/>
      </geometry>
    </collision>
    <inertial>
      <mass value="0.0114"/>
      <origin xyz="0 0 0"/>
      <inertia ixx="5.1458e-05" iyy="5.1458e-05" izz="6.125e-05" ixy="0" ixz="0" iyz="0"/>	
    </inertial>
  </link>
  <joint name="ring_base" type="revolute">
    <axis xyz="0 0 1"/>
    <limit effort="15" lower="-0.57" upper="0.57" velocity="7"/>
    <parent link="palm_link"/>
    <child link="ring_base"/>
    <origin rpy="0.08726646255 0 0" xyz="0 -0.0435 -0.001542"/>
      <dynamics damping="0.0001" friction="0.035"/>
  </joint>
  <!-- [LINK 1, 5, 9] -->
  <link name="ring_proximal">
    <visual>
      <geometry>
        <mesh filename="meshes/allegro/primary_proximal.STL"/>
      </geometry>
      <material name="black"/>
    </visual>
    <collision>
      <geometry>
        <mesh filename="meshes/allegro/primary_proximal.STL"/>
      </geometry>
    </collision>
    <inertial>
      <mass value="0.0712"/>
      <origin xyz="0.027 0 0"/>
      <inertia ixx="6.39979e-06" iyy="8.88687e-05" izz="9.13751e-05" ixy="-3.26531e-06" ixz="1.23963e-05" iyz="2.07384e-05"/>	
    </inertial>
  </link>
  <joint name="ring_proximal" type="revolute">
    <limit effort="15" lower="-0.296" upper="1.71" velocity="7"/>
    <axis xyz="0 1 0"/>
    <parent link="ring_base"/>
    <child link="ring_proximal"/>
    <origin xyz="0 0 0.0164"/>
      <dynamics damping="0.0001" friction="0.035"/>
  </joint>
  <!-- [LINK 2, 6, 10]-->
  <link name="ring_medial">
    <visual>
      <geometry>
        <mesh filename="meshes/allegro/primary_medial.STL"/>
      </geometry>
      <material name="black"/>
    </visual>
    <collision>
      <geometry>
        <mesh filename="meshes/allegro/primary_medial.STL"/>
      </geometry>
    </collision>
    <inertial>
      <mass value="0.0376"/>
      <origin xyz="0.039 0 0"/>
      <inertia ixx="7.04217e-05" iyy="3.95744e-05" izz="6.61125e-05" ixy="-9.64342e-05" ixz="5.8796e-05" iyz="-3.62996e-05"/>	
    </inertial>
  </link>
  <joint name="ring_medial" type="revolute">
    <axis xyz="0 1 0"/>
    <limit effort="15" lower="-0.274" upper="1.809" velocity="7"/>
    <parent link="ring_proximal"/>
    <child link="ring_medial"/>
    <origin xyz="0 0 0.054"/>
      <dynamics damping="0.0001" friction="0.035"/>
  </joint>
  <!-- [LINK 3, 7, 11] -->
  <link name="ring_distal">
    <visual>
      <geometry>
        <mesh filename="meshes/allegro/primary_distal.STL"/>
      </geometry>
      <material name="black"/>
    </visual>
    <collision>
      <geometry>
        <mesh filename="meshes/allegro/primary_distal.STL"/>
      </geometry>
    </collision>
    <inertial>
      <mass value="0.0094"/>
      <origin rpy="0 0 0" xyz="0 0 0"/>
      <inertia ixx="4.701248e-06" ixy="1.255968e-06" ixz="1.2936e-06" iyy="3.649312e-06" iyz="1.7622e-06" izz="4.701248e-06"/>
    </inertial>
  </link>
  <joint name="ring_distal" type="revolute">
    <axis xyz="0 1 0"/>
    <limit effort="15" lower="-0.327" upper="1.718" velocity="7"/>
    <parent link="ring_medial"/>
    <child link="ring_distal"/>
    <origin xyz="0 0 0.0384"/>
      <dynamics damping="0.0001" friction="0.035"/>
  </joint>
  <!-- [FINGER TIP] -->
  <link name="ring_tip">
    <visual>
      <geometry>
        <mesh filename="meshes/allegro/primary_tip.STL"/>
      </geometry>
      <material name="white">
        <color rgba=".9 .9 .9 1"/>
      </material>
    </visual>
    <collision>
      <geometry>
        <sphere radius="0.015"/> 
      </geometry>
    </collision>
    <inertial>
      <mass value="0.0166"/>
      <origin rpy="0 0 0" xyz="0 0 0"/>
      <inertia ixx="9.68e-07" ixy="0" ixz="0" iyy="9.68e-07" iyz="0" izz="9.68e-07"/>
    </inertial>
  </link>
  <joint name="ring_tip" type="fixed">
    <parent link="ring_distal"/>
    <child link="ring_tip"/>
    <origin rpy="0 0 0" xyz="0 0 0.0267"/>
  </joint>
  <!-- THUMB -->
  <!-- [LINK 12] -->
</robot>
