<?xml version="1.0" ?>
<!-- =================================================================================== -->
<!-- |    This document was autogenerated by xacro from allegro_hand_right_A.urdf.xacro | -->
<!-- |    EDITING THIS FILE BY HAND IS NOT RECOMMENDED                                 | -->
<!-- =================================================================================== -->
<robot name="allegro_hand">
  <!-- ======================== BASE PARAMS ========================= -->
  <!-- ======================== FINGER PARAMS ======================== -->
  <!-- full height from joint to tip. when used,
    the radius of the finger tip sphere will be subtracted
    and one fixed link will be added for the tip. -->
  <!-- ========================= THUMB PARAMS ========================= -->
  <!-- ========================= LIMITS ========================= -->
  <!-- ============================================================================= -->
  <!-- PALM -->
  <link name="world"/>
  <joint name="global" type="fixed">
    <parent link="world"/>
    <child link="palm_link"/>
    <!--<origin xyz="0 0 0.095" rpy="0 0 0"/>-->
    <origin rpy="0 0 0" xyz="0 0 0.0"/>
  </joint>
  <link name="palm_link">
    <visual>
      <geometry>
        <mesh filename="meshes/palm.stl" scale="0.001 0.001 0.001"/>
      </geometry>
      <origin rpy="0 3.14 1.57" xyz="0.02 -0.00 -0.1"/>
      <material name="black">
        <color rgba="0.2 0.2 0.2 1"/>
      </material>
    </visual>
    <collision>
      <geometry>
        <mesh filename="meshes/palm.stl" scale="0.001 0.001 0.001"/>
      </geometry>
      <origin rpy="0 3.14 1.57" xyz="0.02 -0.00 -0.1"/>
    </collision>
    <inertial>
      <origin rpy="0 0 0" xyz="0 0 0.0475"/>
      <mass value="0.4154"/>
      <inertia ixx="1e-4" ixy="0.0" ixz="0.0" iyy="1e-4" iyz="0.0" izz="1e-4"/>
    </inertial>
  </link>
  <!-- ============================================================================= -->
  <!-- FINGERS -->
  <!-- RIGHT HAND due to which finger is number 0 -->
  <!-- for LEFT HAND switch the sign of the **offset_origin_y** and **finger_angle_r** parameters-->
  <!-- [LINK 0, 4, 8] -->
  <link name="link_0_0">
    <visual>
      <geometry>
        <mesh filename="meshes/l1.stl" scale="0.001 0.001 0.001"/>
      </geometry>
      <origin rpy="0 0 -1.57" xyz="-0.025 -0.019 0.165"/>
      <material name="black">
        <color rgba="0.2 0.2 0.2 1"/>
      </material>
    </visual>
    <collision>
      <geometry>
        <mesh filename="meshes/l1.stl" scale="0.001 0.001 0.001"/>
      </geometry>
      <origin rpy="0 0 -1.57" xyz="-0.025 -0.019 0.165"/>
    </collision>
    <inertial>
      <mass value="0.0176"/>
      <origin rpy="0 0 0" xyz="0 0 0"/>
      <inertia ixx="1.2854008e-05" ixy="2.04e-08" ixz="1.89e-06" iyy="1.225e-05" iyz="1.51e-07" izz="2.999e-06"/>
    </inertial>
  </link>
  <joint name="joint_0_0" type="revolute">
    <axis xyz="0 0 1"/>
    <limit effort="15" lower="-0.47" upper="0.47" velocity="7"/>
    <parent link="palm_link"/>
    <child link="link_0_0"/>
    <origin rpy="-0.08726646255 0 0" xyz="0.00 0.0405 -0.00945"/>
    <dynamics damping="3" friction="10"/>
  </joint>
  <!-- [LINK 1, 5, 9] -->
  <link name="link_1_0">
    <visual>
      <geometry>
        <mesh filename="meshes/l2.stl" scale="0.001 0.001 0.001"/>
      </geometry>
      <origin rpy="0 0 -1.57" xyz="-0.025 -0.019 0.145"/>
      <material name="black"/>
    </visual>
    <collision>
      <geometry>
        <mesh filename="meshes/l2.stl" scale="0.001 0.001 0.001"/>
      </geometry>
      <origin rpy="0 0 -1.57" xyz="-0.025 -0.019 0.145"/>
    </collision>
    <inertial>
      <mass value="0.066"/>
      <origin rpy="0 0 0" xyz="0 0 0"/>
      <inertia ixx="6.2497616e-06" ixy="0.0000e-06" ixz="-1.892683e-06" iyy="3.1284129e-05" iyz="0.0000e-06" izz="2.9004797e-05"/>
    </inertial>
  </link>
  <joint name="joint_1_0" type="revolute">
    <limit effort="15" lower="-0.196" upper="1.8" velocity="7"/>
    <axis xyz="0 1 0"/>
    <parent link="link_0_0"/>
    <child link="link_1_0"/>
    <origin xyz="0.00 0 0.021"/>
    <dynamics damping="3" friction="5"/>
  </joint>
  <!-- [LINK 2, 6, 10]-->
  <link name="link_2_0">
    <visual>
      <geometry>
        <mesh filename="meshes/l3.stl" scale="0.001 0.001 0.001"/>
      </geometry>
      <origin rpy="0 0 -1.57" xyz="-0.025 -0.019 0.0945"/>
      <material name="black"/>
    </visual>
    <collision>
      <geometry>
        <mesh filename="meshes/l3.stl" scale="0.001 0.001 0.001"/>
      </geometry>
      <origin rpy="0 0 -1.57" xyz="-0.025 -0.019 0.0945"/>
    </collision>
    <inertial>
      <mass value="0.0366"/>
      <origin rpy="0 0 0" xyz="0 0 0"/>
      <inertia ixx="3.8070280e-06" ixy="5.7154287e-03" ixz="-9.9708657e-07" iyy="1.4547214e-05" iyz="2.632663e-04" izz="1.2905337e-05"/>
    </inertial>
  </link>
  <joint name="joint_2_0" type="revolute">
    <axis xyz="0 1 0"/>
    <limit effort="15" lower="-0.174" upper="1.709" velocity="7"/>
    <parent link="link_1_0"/>
    <child link="link_2_0"/>
    <origin xyz="0 0 0.051"/>
    <dynamics damping="8" friction="10"/>
  </joint>
  <!-- [LINK 3, 7, 11] -->
  <link name="link_3_0">
    <visual>
      <geometry>
        <mesh filename="meshes/l4.stl" scale="0.001 0.001 0.001"/>
      </geometry>
      <origin rpy="0 0 -1.57" xyz="-0.025 -0.019 0.0561"/>
      <material name="black"/>
    </visual>
    <collision>
      <geometry>
        <mesh filename="meshes/l4.stl" scale="0.001 0.001 0.001"/>
      </geometry>
      <origin rpy="0 0 -1.57" xyz="-0.025 -0.019 0.0561"/>
    </collision>
    <inertial>
      <mass value="0.00569"/>
      <origin rpy="0 0 0" xyz="0 0 0"/>
      <inertia ixx="1.176928e-06" ixy="5.0891669e-03" ixz="0.000000e-06" iyy="2.40127e-06" iyz="-5.3128971e-11" izz="1.674842e-06"/>
    </inertial>
  </link>
  <joint name="joint_3_0" type="revolute">
    <axis xyz="0 1 0"/>
    <limit effort="15" lower="-0.227" upper="1.618" velocity="7"/>
    <parent link="link_2_0"/>
    <child link="link_3_0"/>
    <origin rpy="0 -0.15 0" xyz="0 0 0.0384"/>
    <dynamics damping="10" friction="12"/>
  </joint>
  <!-- [FINGER TIP] -->
  <link name="link_3_0_tip">
    <visual>
      <geometry>
        <mesh filename="meshes/finger_tip.stl" scale="0.001 0.001 0.0012"/>
      </geometry>
      <origin rpy="0 0 -1.57" xyz="-0.05482 -0.01393 -0.00995"/>
      <material name="white">
        <color rgba=".9 .9 .9 1"/>
      </material>
    </visual>
    <collision>
      <geometry>
        <mesh filename="meshes/finger_tip.stl" scale="0.001 0.001 0.0012"/>
      </geometry>
      <origin rpy="0 0 -1.57" xyz="-0.05482 -0.01393 -0.00995"/>
    </collision>
    <inertial>
      <mass value="0.00"/>
      <origin rpy="0 0 0" xyz="0 0 0"/>
      <inertia ixx="9.68e-07" ixy="0" ixz="0" iyy="9.68e-07" iyz="0" izz="9.68e-07"/>
    </inertial>
  </link>
  <joint name="joint_3_0_tip" type="fixed">
    <parent link="link_3_0"/>
    <child link="link_3_0_tip"/>
    <origin rpy="0 0 0" xyz="0 0 0.0267"/>
  </joint>
  <!-- [LINK 0, 4, 8] -->
  <link name="link_4_0">
    <visual>
      <geometry>
        <mesh filename="meshes/l1.stl" scale="0.001 0.001 0.0012"/>
      </geometry>
      <origin rpy="0 0 -1.57" xyz="-0.025 -0.019 0.165"/>
      <material name="black"/>
    </visual>
    <collision>
      <geometry>
        <mesh filename="meshes/l1.stl" scale="0.001 0.001 0.0012"/>
      </geometry>
      <origin rpy="0 0 -1.57" xyz="-0.025 -0.019 0.165"/>
    </collision>
    <inertial>
      <mass value="0.0176"/>
      <origin rpy="0 0 0" xyz="0 0 0"/>
      <inertia ixx="1.2854008e-05" ixy="2.04e-08" ixz="1.89e-06" iyy="1.225e-05" iyz="1.51e-07" izz="2.999e-06"/>
    </inertial>
  </link>
  <joint name="joint_4_0" type="revolute">
    <axis xyz="0 0 1"/>
    <limit effort="15" lower="-0.47" upper="0.47" velocity="7"/>
    <parent link="palm_link"/>
    <child link="link_4_0"/>
    <origin rpy="0.0 0 0" xyz="0 0.00 -0.0079"/>
    <dynamics damping="3" friction="10"/>
  </joint>
  <!-- [LINK 1, 5, 9] -->
  <link name="link_5_0">
    <visual>
      <geometry>
        <mesh filename="meshes/l2.stl" scale="0.001 0.001 0.001"/>
      </geometry>
      <origin rpy="0 0 -1.57" xyz="-0.025 -0.019 0.145"/>
      <material name="black"/>
    </visual>
    <collision>
      <geometry>
        <mesh filename="meshes/l2.stl" scale="0.001 0.001 0.001"/>
      </geometry>
      <origin rpy="0 0 -1.57" xyz="-0.025 -0.019 0.145"/>
    </collision>
    <inertial>
      <mass value="0.066"/>
      <origin rpy="0 0 0" xyz="0 0 0"/>
      <inertia ixx="6.2497616e-06" ixy="0.0000e-06" ixz="-1.892683e-06" iyy="3.1284129e-05" iyz="0.0000e-06" izz="2.9004797e-05"/>
    </inertial>
  </link>
  <joint name="joint_5_0" type="revolute">
    <limit effort="15" lower="-0.196" upper="1.8" velocity="7"/>
    <axis xyz="0 1 0"/>
    <parent link="link_4_0"/>
    <child link="link_5_0"/>
    <origin xyz="0 0 0.021"/>
    <dynamics damping="3" friction="5"/>
  </joint>
  <!-- [LINK 2, 6, 10]-->
  <link name="link_6_0">
    <visual>
      <geometry>
        <mesh filename="meshes/l3.stl" scale="0.001 0.001 0.001"/>
      </geometry>
      <origin rpy="0 0 -1.57" xyz="-0.025 -0.019 0.0945"/>
      <material name="black"/>
    </visual>
    <collision>
      <geometry>
        <mesh filename="meshes/l3.stl" scale="0.001 0.001 0.001"/>
      </geometry>
      <origin rpy="0 0 -1.57" xyz="-0.025 -0.019 0.0945"/>
    </collision>
    <inertial>
      <mass value="0.0366"/>
      <origin rpy="0 0 0" xyz="0 0 0"/>
      <inertia ixx="3.8070280e-06" ixy="5.7154287e-03" ixz="-9.9708657e-07" iyy="1.4547214e-05" iyz="2.632663e-04" izz="1.2905337e-05"/>
    </inertial>
  </link>
  <joint name="joint_6_0" type="revolute">
    <axis xyz="0 1 0"/>
    <limit effort="15" lower="-0.174" upper="1.709" velocity="7"/>
    <parent link="link_5_0"/>
    <child link="link_6_0"/>
    <origin xyz="0 0 0.051"/>
    <dynamics damping="8" friction="10"/>
  </joint>
  <!-- [LINK 3, 7, 11] -->
  <link name="link_7_0">
    <visual>
      <geometry>
        <mesh filename="meshes/l4.stl" scale="0.001 0.001 0.001"/>
      </geometry>
      <origin rpy="0 0 -1.57" xyz="-0.025 -0.019 0.0561"/>
      <material name="black"/>
    </visual>
    <collision>
      <geometry>
        <mesh filename="meshes/l4.stl" scale="0.001 0.001 0.001"/>
      </geometry>
      <origin rpy="0 0 -1.57" xyz="-0.025 -0.019 0.0561"/>
    </collision>
    <inertial>
      <mass value="0.00569"/>
      <origin rpy="0 0 0" xyz="0 0 0"/>
      <inertia ixx="1.176928e-06" ixy="5.0891669e-03" ixz="0.000000e-06" iyy="2.40127e-06" iyz="-5.3128971e-11" izz="1.674842e-06"/>
    </inertial>
  </link>
  <joint name="joint_7_0" type="revolute">
    <axis xyz="0 1 0"/>
    <limit effort="15" lower="-0.227" upper="1.618" velocity="7"/>
    <parent link="link_6_0"/>
    <child link="link_7_0"/>
    <origin rpy="0 -0.15 0" xyz="0 0 0.0384"/>
    <dynamics damping="10" friction="12"/>
  </joint>
  <!-- [FINGER TIP] -->
  <link name="link_7_0_tip">
    <visual>
      <geometry>
        <mesh filename="meshes/finger_tip.stl" scale="0.001 0.001 0.0012"/>
      </geometry>
      <origin rpy="0 0 -1.57" xyz="-0.05482 -0.01393 -0.00995"/>
      <material name="white">
        <color rgba=".9 .9 .9 1"/>
      </material>
    </visual>
    <collision>
      <geometry>
        <mesh filename="meshes/finger_tip.stl" scale="0.001 0.001 0.0012"/>
      </geometry>
      <origin rpy="0 0 -1.57" xyz="-0.05482 -0.01393 -0.00995"/>
    </collision>
    <inertial>
      <mass value="0.00"/>
      <origin rpy="0 0 0" xyz="0 0 0"/>
      <inertia ixx="9.68e-07" ixy="0" ixz="0" iyy="9.68e-07" iyz="0" izz="9.68e-07"/>
    </inertial>
  </link>
  <joint name="joint_7_0_tip" type="fixed">
    <parent link="link_7_0"/>
    <child link="link_7_0_tip"/>
    <origin rpy="0 0 0" xyz="0 0 0.0267"/>
  </joint>
  <!-- [LINK 0, 4, 8] -->
  <link name="link_8_0">
    <visual>
      <geometry>
        <mesh filename="meshes/l1.stl" scale="0.001 0.001 0.0012"/>
      </geometry>
      <origin rpy="0 0 -1.57" xyz="-0.025 -0.019 0.165"/>
      <material name="black">
        <color rgba="0.2 0.2 0.2 1"/>
      </material>
    </visual>
    <collision>
      <geometry>
        <mesh filename="meshes/l1.stl" scale="0.001 0.001 0.0012"/>
      </geometry>
      <origin rpy="0 0 -1.57" xyz="-0.025 -0.019 0.165"/>
    </collision>
    <inertial>
      <mass value="0.0176"/>
      <origin rpy="0 0 0" xyz="0 0 0"/>
      <inertia ixx="1.2854008e-05" ixy="2.04e-08" ixz="1.89e-06" iyy="1.225e-05" iyz="1.51e-07" izz="2.999e-06"/>
    </inertial>
  </link>
  <joint name="joint_8_0" type="revolute">
    <axis xyz="0 0 1"/>
    <limit effort="15" lower="-0.47" upper="0.47" velocity="7"/>
    <parent link="palm_link"/>
    <child link="link_8_0"/>
    <origin rpy="0.08726646255 0 0" xyz="0.0025 -0.0405 -0.00945"/>
    <dynamics damping="3" friction="10"/>
  </joint>
  <!-- [LINK 1, 5, 9] -->
  <link name="link_9_0">
    <visual>
      <geometry>
        <mesh filename="meshes/l2.stl" scale="0.001 0.001 0.001"/>
      </geometry>
      <origin rpy="0 0 -1.57" xyz="-0.025 -0.019 0.145"/>
      <material name="black"/>
    </visual>
    <collision>
      <geometry>
        <mesh filename="meshes/l2.stl" scale="0.001 0.001 0.001"/>
      </geometry>
      <origin rpy="0 0 -1.57" xyz="-0.025 -0.019 0.145"/>
    </collision>
    <inertial>
      <mass value="0.066"/>
      <origin rpy="0 0 0" xyz="0 0 0"/>
      <inertia ixx="6.2497616e-06" ixy="0.0000e-06" ixz="-1.892683e-06" iyy="3.1284129e-05" iyz="0.0000e-06" izz="2.9004797e-05"/>
    </inertial>
  </link>
  <joint name="joint_9_0" type="revolute">
    <limit effort="15" lower="-0.196" upper="1.8" velocity="7"/>
    <axis xyz="0 1 0"/>
    <parent link="link_8_0"/>
    <child link="link_9_0"/>
    <origin xyz="0 0 0.021"/>
    <dynamics damping="3" friction="5"/>
  </joint>
  <!-- [LINK 2, 6, 10]-->
  <link name="link_10_0">
    <visual>
      <geometry>
        <mesh filename="meshes/l3.stl" scale="0.001 0.001 0.001"/>
      </geometry>
      <origin rpy="0 0 -1.57" xyz="-0.025 -0.019 0.0945"/>
      <material name="black"/>
    </visual>
    <collision>
      <geometry>
        <mesh filename="meshes/l3.stl" scale="0.001 0.001 0.001"/>
      </geometry>
      <origin rpy="0 0 -1.57" xyz="-0.025 -0.019 0.0945"/>
    </collision>
    <inertial>
      <mass value="0.0366"/>
      <origin rpy="0 0 0" xyz="0 0 0"/>
      <inertia ixx="3.8070280e-06" ixy="5.7154287e-03" ixz="-9.9708657e-07" iyy="1.4547214e-05" iyz="2.632663e-04" izz="1.2905337e-05"/>
    </inertial>
  </link>
  <joint name="joint_10_0" type="revolute">
    <axis xyz="0 1 0"/>
    <limit effort="15" lower="-0.174" upper="1.709" velocity="7"/>
    <parent link="link_9_0"/>
    <child link="link_10_0"/>
    <origin xyz="0 0 0.051"/>
    <dynamics damping="8" friction="10"/>
  </joint>
  <!-- [LINK 3, 7, 11] -->
  <link name="link_11_0">
    <visual>
      <geometry>
        <mesh filename="meshes/l4.stl" scale="0.001 0.001 0.001"/>
      </geometry>
      <origin rpy="0 0 -1.57" xyz="-0.025 -0.019 0.0561"/>
      <material name="black"/>
    </visual>
    <collision>
      <geometry>
        <mesh filename="meshes/l4.stl" scale="0.001 0.001 0.001"/>
      </geometry>
      <origin rpy="0 0 -1.57" xyz="-0.025 -0.019 0.0561"/>
    </collision>
    <inertial>
      <mass value="0.00569"/>
      <origin rpy="0 0 0" xyz="0 0 0"/>
      <inertia ixx="1.176928e-06" ixy="5.0891669e-03" ixz="0.000000e-06" iyy="2.40127e-06" iyz="-5.3128971e-11" izz="1.674842e-06"/>
    </inertial>
  </link>
  <joint name="joint_11_0" type="revolute">
    <axis xyz="0 1 0"/>
    <limit effort="15" lower="-0.227" upper="1.618" velocity="7"/>
    <parent link="link_10_0"/>
    <child link="link_11_0"/>
    <origin rpy="0 -0.15 0" xyz="0 0 0.0384"/>
    <dynamics damping="10" friction="12"/>
  </joint>
  <!-- [FINGER TIP] -->
  <link name="link_11_0_tip">
    <visual>
      <geometry>
        <mesh filename="meshes/finger_tip.stl" scale="0.001 0.001 0.0012"/>
      </geometry>
      <origin rpy="0 0 -1.57" xyz="-0.05482 -0.01393 -0.00995"/>
      <material name="white">
        <color rgba=".9 .9 .9 1"/>
      </material>
    </visual>
    <collision>
      <geometry>
        <mesh filename="meshes/finger_tip.stl" scale="0.001 0.001 0.0012"/>
      </geometry>
      <origin rpy="0 0 -1.57" xyz="-0.05482 -0.01393 -0.00995"/>
    </collision>
    <inertial>
      <mass value="0.00"/>
      <origin rpy="0 0 0" xyz="0 0 0"/>
      <inertia ixx="9.68e-07" ixy="0" ixz="0" iyy="9.68e-07" iyz="0" izz="9.68e-07"/>
    </inertial>
  </link>
  <joint name="joint_11_0_tip" type="fixed">
    <parent link="link_11_0"/>
    <child link="link_11_0_tip"/>
    <origin rpy="0 0 0" xyz="0 0 0.0267"/>
  </joint>
  <!-- THUMB -->
  <!-- [LINK 12] -->
  <link name="link_12_0">
    <visual>
      <geometry>
        <mesh filename="meshes/t1_set.stl" scale="0.001 0.001 0.001"/>
      </geometry>
      <origin rpy="3.926991 3.14 3.14" xyz="0.021 -0.1145 0.0725"/>
      <material name="black">
        <color rgba=".2 .2 .2 1"/>
      </material>
    </visual>
    <collision>
      <geometry>
        <mesh filename="meshes/t1_set.stl" scale="0.001 0.001 0.001"/>
      </geometry>
      <origin rpy="3.926991 3.14 3.14" xyz="0.021 -0.1145 0.0725"/>
    </collision>
    <inertial>
      <mass value="0.0446"/>
      <origin rpy="0 0 0" xyz="0 0 0"/>
      <inertia ixx="5.44e-5" ixy="4.0e-07" ixz="-1.12e-07" iyy="9.19e-06" iyz="1.07e-05" izz="4.8e-05"/>
    </inertial>
  </link>
  <joint name="joint_12_0" type="revolute">
    <axis xyz="-1 0 0"/>
    <limit effort="15" lower="0.00" upper="1.78" velocity="7"/>
    <parent link="palm_link"/>
    <child link="link_12_0"/>
    <origin rpy="0 -1.65806278845 -1.5707963259" xyz="0.002 0.027 -0.06342"/>
    <dynamics damping="3" friction="10"/>
  </joint>
  <!-- [LINK 13] -->
  <link name="link_13_0">
    <visual>
      <geometry>
        <mesh filename="meshes/t2_set.stl" scale="0.001 0.001 0.001"/>
      </geometry>
      <origin rpy="3.14 3.14 1.57" xyz="-0.138 -0.0605 0.2143"/>
      <material name="black">
        <color rgba=".2 .2 .2 1"/>
      </material>
    </visual>
    <collision>
      <geometry>
        <mesh filename="meshes/t2_set.stl" scale="0.001 0.001 0.001"/>
      </geometry>
      <origin rpy="3.14 3.14 1.57" xyz="-0.138 -0.0605 0.2143"/>
    </collision>
    <inertial>
      <mass value="0.0173"/>
      <origin rpy="0 0 0" xyz="0 0 0"/>
      <inertia ixx="1.52e-05" ixy="-2.09e-08" ixz="-9.8e-09" iyy="1.3323e-05" iyz="-2.04e-06" izz="2.85e-06"/>
    </inertial>
  </link>
  <joint name="joint_13_0" type="revolute">
    <axis xyz="0 0 1"/>
    <limit effort="15" lower="-0.26" upper="1.78" velocity="7"/>
    <parent link="link_12_0"/>
    <child link="link_13_0"/>
    <origin xyz="-0.001 0.00 0.06874"/>
    <dynamics damping="3" friction="5"/>
  </joint>
  <!-- [LINK 14] -->
  <link name="link_14_0">
    <visual>
      <geometry>
        <mesh filename="meshes/t3_set.stl" scale="0.001 0.001 0.001"/>
      </geometry>
      <origin rpy="3.14 3.14 1.57" xyz="-0.1265 -0.061 0.166"/>
      <material name="black">
      </material>
    </visual>
    <collision>
      <geometry>
        <mesh filename="meshes/t3_set.stl" scale="0.001 0.001 0.001"/>
      </geometry>
      <origin rpy="3.14 3.14 1.57" xyz="-0.1265 -0.061 0.166"/>
    </collision>
    <inertial>
      <mass value="0.03607"/>
      <origin rpy="0 0 0" xyz="0 0 0"/>
      <inertia ixx="3.7e-06" ixy="2.43e-07" ixz="6.48e-07" iyy="1.54e-05" iyz="-3.11e-08" izz="1.388e-05"/>
    </inertial>
  </link>
  <joint name="joint_14_0" type="revolute">
    <axis xyz="0 1 0"/>
    <!--<limit effort="15" lower="-0.54" upper="1.53" velocity="7"/>-->
    <limit effort="15" lower="0.00" upper="1.9" velocity="7"/>
    <parent link="link_13_0"/>
    <child link="link_14_0"/>
    <origin rpy="0 -0.15 0" xyz="0 0 0.00"/>
    <dynamics damping="3" friction="10"/>
  </joint>
  <!-- [LINK 15] -->
  <link name="link_15_0">
    <visual>
      <geometry>
        <mesh filename="meshes/t4_set.stl" scale="0.001 0.001 0.001"/>
      </geometry>
      <origin rpy="3.14 3.14 1.57" xyz="-0.149 -0.061 0.096"/>
      <material name="black">
      </material>
    </visual>
    <collision>
      <geometry>
        <mesh filename="meshes/t4_set.stl" scale="0.001 0.001 0.001"/>
      </geometry>
      <origin rpy="3.14 3.14 1.57" xyz="-0.149 -0.061 0.096"/>
    </collision>
    <inertial>
      <mass value="0.0338"/>
      <origin rpy="0 0 0" xyz="0 0 0"/>
      <inertia ixx="2.94e-06" ixy="1.244e-07" ixz="3.52e-07" iyy="1.13e-05" iyz="-3.11e-08" izz="1.06e-05"/>
    </inertial>
  </link>
  <joint name="joint_15_0" type="revolute">
    <axis xyz="0 1 0"/>
    <limit effort="15" lower="-0.09" upper="1.80" velocity="7"/>
    <parent link="link_14_0"/>
    <child link="link_15_0"/>
    <origin xyz="0 0 0.038"/>
    <dynamics damping="3" friction="12"/>
  </joint>
  <!-- [FINGER TIP] -->
  <link name="link_15_0_tip">
    <visual>
      <geometry>
        <mesh filename="meshes/finger_tip_silicon.stl" scale="0.001 0.001 0.0012"/>
      </geometry>
      <origin rpy="0 0 3.14" xyz="-0.014 0.0545 -0.0172"/>
      <material name="white">
        <color rgba=".9 .9 .9 1"/>
      </material>
    </visual>
    <collision>
      <geometry>
        <mesh filename="meshes/finger_tip_silicon.stl" scale="0.001 0.001 0.001"/>
      </geometry>
      <origin rpy="0 0 3.14" xyz="-0.014 0.0545 -0.0172"/>
    </collision>
    <inertial>
      <mass value="0.00"/>
      <origin rpy="0 0 0" xyz="0 0 0"/>
      <inertia ixx="9.68e-07" ixy="0" ixz="0" iyy="9.68e-07" iyz="0" izz="9.68e-07"/>
    </inertial>
  </link>
  <joint name="joint_15_0_tip" type="fixed">
    <parent link="link_15_0"/>
    <child link="link_15_0_tip"/>
    <origin rpy="0 0 0" xyz="0 0 0.05"/>
  </joint>
  <!-- ============================================================================= -->
  <!-- THUMB MACRO -->
  <!-- END THUMB MACRO -->
  <!-- THREE FINGER MACRO -->
  <!-- [[END]] THREE FINGER MACRO -->
  <ros2_control name="FakeSystem" type="system">
    <hardware>
      <!-- By default, set up controllers for simulation. This won't work on real hardware -->
      <plugin>mock_components/GenericSystem</plugin>
    </hardware>
    <joint name="joint_0_0">
      <command_interface name="position"/>
      <state_interface name="position">
        <param name="initial_value">0</param>
      </state_interface>
      <state_interface name="velocity"/>
    </joint>
    <joint name="joint_1_0">
      <command_interface name="position"/>
      <state_interface name="position">
        <param name="initial_value">0</param>
      </state_interface>
      <state_interface name="velocity"/>
    </joint>
    <joint name="joint_2_0">
      <command_interface name="position"/>
      <state_interface name="position">
        <param name="initial_value">0</param>
      </state_interface>
      <state_interface name="velocity"/>
    </joint>
    <joint name="joint_3_0">
      <command_interface name="position"/>
      <state_interface name="position">
        <param name="initial_value">0</param>
      </state_interface>
      <state_interface name="velocity"/>
    </joint>
    <joint name="joint_12_0">
      <command_interface name="position"/>
      <state_interface name="position">
        <param name="initial_value">0</param>
      </state_interface>
      <state_interface name="velocity"/>
    </joint>
    <joint name="joint_13_0">
      <command_interface name="position"/>
      <state_interface name="position">
        <param name="initial_value">1.57</param>
      </state_interface>
      <state_interface name="velocity"/>
    </joint>
    <joint name="joint_14_0">
      <command_interface name="position"/>
      <state_interface name="position">
        <param name="initial_value">0</param>
      </state_interface>
      <state_interface name="velocity"/>
    </joint>
    <joint name="joint_15_0">
      <command_interface name="position"/>
      <state_interface name="position">
        <param name="initial_value">0</param>
      </state_interface>
      <state_interface name="velocity"/>
    </joint>
    <joint name="joint_4_0">
      <command_interface name="position"/>
      <state_interface name="position">
        <param name="initial_value">0</param>
      </state_interface>
      <state_interface name="velocity"/>
    </joint>
    <joint name="joint_5_0">
      <command_interface name="position"/>
      <state_interface name="position">
        <param name="initial_value">0</param>
      </state_interface>
      <state_interface name="velocity"/>
    </joint>
    <joint name="joint_6_0">
      <command_interface name="position"/>
      <state_interface name="position">
        <param name="initial_value">0</param>
      </state_interface>
      <state_interface name="velocity"/>
    </joint>
    <joint name="joint_7_0">
      <command_interface name="position"/>
      <state_interface name="position">
        <param name="initial_value">0</param>
      </state_interface>
      <state_interface name="velocity"/>
    </joint>
    <joint name="joint_8_0">
      <command_interface name="position"/>
      <state_interface name="position">
        <param name="initial_value">0</param>
      </state_interface>
      <state_interface name="velocity"/>
    </joint>
    <joint name="joint_9_0">
      <command_interface name="position"/>
      <state_interface name="position">
        <param name="initial_value">0</param>
      </state_interface>
      <state_interface name="velocity"/>
    </joint>
    <joint name="joint_10_0">
      <command_interface name="position"/>
      <state_interface name="position">
        <param name="initial_value">0</param>
      </state_interface>
      <state_interface name="velocity"/>
    </joint>
    <joint name="joint_11_0">
      <command_interface name="position"/>
      <state_interface name="position">
        <param name="initial_value">0</param>
      </state_interface>
      <state_interface name="velocity"/>
    </joint>
  </ros2_control>
</robot>
