<?xml version="1.0" encoding="utf-8"?>
<!-- This URDF was automatically created by SolidWorks to URDF Exporter! Originally created by Stephen Brawner (brawner@gmail.com) 
     Commit Version: 1.6.0-4-g7f85cfe  Build Version: 1.6.7995.38578
     For more information, please see http://wiki.ros.org/sw_urdf_exporter -->
<robot
  name="urdf_left_12_20" xmlns:xacro="http://ros.org/wiki/xacro">
  
    <link name="world"/>

    <joint name="L_hand_base_joint" type="fixed">
      <origin
      xyz="0.5 0.5 0.001"
      rpy="3.14  0 -1.57" />
      <parent link="world"/>
      <child link="base_link"/>
    </joint>
  
  <link
    name="base_link">
    <inertial>
      <origin
        xyz="-5.81855257230368E-05 0.0036855956860619 -0.0826153899028331"
        rpy="0 0 0" />
      <mass
        value="0.260034351097693" />
      <inertia
        ixx="0.000223659755666589"
        ixy="-1.13436481934473E-06"
        ixz="5.34309354519849E-07"
        iyy="0.000266799681483547"
        iyz="1.40944118648867E-05"
        izz="0.000132857769181899" />
    </inertial>
    <visual>
      <origin
        xyz="0 0 0"
        rpy="0 0 0" />
      <geometry>
        <mesh
          filename="inspire/meshes_left/base_link.STL" />
      </geometry>
      <material
        name="">
        <color
          rgba="0.792156862745098 0.819607843137255 0.933333333333333 1" />
      </material>
    </visual>
    <collision>
      <origin
        xyz="0 0 0"
        rpy="0 0 0" />
      <geometry>
        <mesh
          filename="inspire/meshes_left/base_link.STL" />
      </geometry>
    </collision>
  </link>
  <link
    name="left_thumb_1">
    <inertial>
      <origin
        xyz="0.00178423404495211 -0.000649404577309123 -0.0031358931043441"
        rpy="0 0 0" />
      <mass
        value="0.00115518743162309" />
      <inertia
        ixx="5.98912200501135E-08"
        ixy="-8.04315731947437E-09"
        ixz="-3.29346919841095E-09"
        iyy="4.07201234589857E-08"
        iyz="1.19872544716431E-09"
        izz="6.18161684388651E-08" />
    </inertial>
    <visual>
      <origin
        xyz="0 0 0"
        rpy="0 0 0" />
      <geometry>
        <mesh
          filename="inspire/meshes_left/left_thumb_1.STL" />
      </geometry>
      <material
        name="">
        <color
          rgba="0.792156862745098 0.819607843137255 0.933333333333333 1" />
      </material>
    </visual>
    <collision>
      <origin
        xyz="0 0 0"
        rpy="0 0 0" />
      <geometry>
        <mesh
          filename="inspire/meshes_left/left_thumb_1.STL" />
      </geometry>
    </collision>
  </link>
  <joint
    name="left_thumb_1_joint"
    type="revolute">
    <origin
      xyz="0.0269 -0.02101 -0.07075"
      rpy="0 0 0" />
    <parent
      link="base_link" />
    <child
      link="left_thumb_1" />
    <axis
      xyz="0 0 -1" />
    <limit
      lower="0"
      upper="1.15"
      effort="10"
      velocity="1" />
  </joint>
  <link
    name="left_thumb_2">
    <inertial>
      <origin
        xyz="0.0141077165126408 0.013272947664556 0.00905027694248729"
        rpy="0 0 0" />
      <mass
        value="0.016" />
      <inertia
        ixx="1.06585698719649E-06"
        ixy="-7.62263321516971E-08"
        ixz="2.95033226564006E-11"
        iyy="1.06558155578278E-06"
        iyz="1.55271585897891E-11"
        izz="1.39709651951733E-06" />
    </inertial>
    <visual>
      <origin
        xyz="0 0 0"
        rpy="0 0 0" />
      <geometry>
        <mesh
          filename="inspire/meshes_left/left_thumb_2.STL" />
      </geometry>
      <material
        name="">
        <color
          rgba="0.792156862745098 0.819607843137255 0.933333333333333 1" />
      </material>
    </visual>
    <collision>
      <origin
        xyz="0 0 0"
        rpy="0 0 0" />
      <geometry>
        <mesh
          filename="inspire/meshes_left/left_thumb_2.STL" />
      </geometry>
    </collision>
  </link>
  <joint
    name="left_thumb_2_joint"
    type="revolute">
    <origin
      xyz="0.0063016 -0.011924 -0.00125"
      rpy="-1.5708 0 -0.34907" />
    <parent
      link="left_thumb_1" />
    <child
      link="left_thumb_2" />
    <axis
      xyz="0 0 1" />
    <limit
      lower="0"
      upper="0.55"
      effort="10"
      velocity="1" />
  </joint>
  <link
    name="left_thumb_3">
    <inertial>
      <origin
        xyz="0.0175210608796189 -0.000458783419545392 0.00589186777098984"
        rpy="0 0 0" />
      <mass
        value="0.012" />
      <inertia
        ixx="4.67948369620491E-07"
        ixy="-4.4974688607358E-08"
        ixz="1.01425359574474E-11"
        iyy="3.98794196148187E-07"
        iyz="2.07037920898898E-10"
        izz="4.24723917424999E-07" />
    </inertial>
    <visual>
      <origin
        xyz="0 0 0"
        rpy="0 0 0" />
      <geometry>
        <mesh
          filename="inspire/meshes_left/left_thumb_3.STL" />
      </geometry>
      <material
        name="">
        <color
          rgba="0.792156862745098 0.819607843137255 0.933333333333333 1" />
      </material>
    </visual>
    <collision>
      <origin
        xyz="0 0 0"
        rpy="0 0 0" />
      <geometry>
        <mesh
          filename="inspire/meshes_left/left_thumb_3.STL" />
      </geometry>
    </collision>
  </link>
  <joint
    name="left_thumb_3_joint"
    type="revolute">
    <origin
      xyz="0.026828 0.02583 0.00315"
      rpy="0 0 0" />
    <parent
      link="left_thumb_2" />
    <child
      link="left_thumb_3" />
    <axis
      xyz="0 0 1" />
    <limit
      lower="0"
      upper="3.14"
      effort="10"
      velocity="1" />
    <mimic
        joint="left_thumb_2_joint"
        multiplier="0.60"
        offset="0" />
  </joint>
  <link
    name="left_thumb_4">
    <inertial>
      <origin
        xyz="0.0159972574626049 0.0063105797700872 0.0073433144647696"
        rpy="0 0 0" />
      <mass
        value="0.01" />
      <inertia
        ixx="6.4362640059723E-07"
        ixy="-2.57376746969386E-07"
        ixz="-8.63129696542143E-10"
        iyy="7.63678708562786E-07"
        iyz="-7.21288836303217E-10"
        izz="9.2570163408105E-07" />
    </inertial>
    <visual>
      <origin
        xyz="0 0 0"
        rpy="0 0 0" />
      <geometry>
        <mesh
          filename="inspire/meshes_left/left_thumb_4.STL" />
      </geometry>
      <material
        name="">
        <color
          rgba="0.792156862745098 0.819607843137255 0.933333333333333 1" />
      </material>
    </visual>
    <collision>
      <origin
        xyz="0 0 0"
        rpy="0 0 0" />
      <geometry>
        <mesh
          filename="inspire/meshes_left/left_thumb_4.STL" />
      </geometry>
    </collision>
  </link>
  <joint
    name="left_thumb_4_joint"
    type="revolute">
    <origin
      xyz="0.027027 0.0069965 -0.00145"
      rpy="0 0 0" />
    <parent
      link="left_thumb_3" />
    <child
      link="left_thumb_4" />
    <axis
      xyz="0 0 1" />
    <limit
      lower="0"
      upper="3.14"
      effort="10"
      velocity="1" />
    <mimic
        joint="left_thumb_2_joint"
        multiplier="0.8"
        offset="0" />
  </joint>
  <link
    name="left_index_1">
    <inertial>
      <origin
        xyz="-0.00183599258071257 0.0123544163382434 -0.00665152565125451"
        rpy="0 0 0" />
      <mass
        value="0.0071995003148682" />
      <inertia
        ixx="1.28363093823079E-06"
        ixy="4.22091506924093E-08"
        ixz="-1.1741465013013E-12"
        iyy="5.79447850871435E-07"
        iyz="-8.63816965731366E-11"
        izz="1.32914845722975E-06" />
    </inertial>
    <visual>
      <origin
        xyz="0 0 0"
        rpy="0 0 0" />
      <geometry>
        <mesh
          filename="inspire/meshes_left/left_index_1.STL" />
      </geometry>
      <material
        name="">
        <color
          rgba="0.792156862745098 0.819607843137255 0.933333333333333 1" />
      </material>
    </visual>
    <collision>
      <origin
        xyz="0 0 0"
        rpy="0 0 0" />
      <geometry>
        <mesh
          filename="inspire/meshes_left/left_index_1.STL" />
      </geometry>
    </collision>
  </link>
  <joint
    name="left_index_1_joint"
    type="revolute">
    <origin
      xyz="0.025387 -0.00056467 -0.15686"
      rpy="-1.6057 0 1.5708" />
    <parent
      link="base_link" />
    <child
      link="left_index_1" />
    <axis
      xyz="0 0 1" />
    <limit
      lower="0"
      upper="1.6"
      effort="10"
      velocity="1" />
  </joint>
  <link
    name="left_index_2">
    <inertial>
      <origin
        xyz="0.000405420051948283 0.0257003783460073 -0.00610830787560272"
        rpy="0 0 0" />
      <mass
        value="0.00968688267109518" />
      <inertia
        ixx="2.25563043691857E-06"
        ixy="4.11282885240034E-07"
        ixz="3.87338024122588E-10"
        iyy="3.91279806505403E-07"
        iyz="-2.76559043550419E-09"
        izz="2.30247359295784E-06" />
    </inertial>
    <visual>
      <origin
        xyz="0 0 0"
        rpy="0 0 0" />
      <geometry>
        <mesh
          filename="inspire/meshes_left/left_index_2.STL" />
      </geometry>
      <material
        name="">
        <color
          rgba="0.792156862745098 0.819607843137255 0.933333333333333 1" />
      </material>
    </visual>
    <collision>
      <origin
        xyz="0 0 0"
        rpy="0 0 0" />
      <geometry>
        <mesh
          filename="inspire/meshes_left/left_index_2.STL" />
      </geometry>
    </collision>
  </link>
  <joint
    name="left_index_2_joint"
    type="revolute">
    <origin
      xyz="-0.0016312 0.032734 -0.00055"
      rpy="0 0 0" />
    <parent
      link="left_index_1" />
    <child
      link="left_index_2" />
    <axis
      xyz="0 0 1" />
    <limit
      lower="0"
      upper="3.14"
      effort="10"
      velocity="1" />
    <mimic
        joint="left_index_1_joint"
        multiplier="1.05"
        offset="0" />
  </joint>
  <link
    name="left_middle_1">
    <inertial>
      <origin
        xyz="-0.00229271394242232 0.0122778605414752 -0.00665151068667683"
        rpy="0 0 0" />
      <mass
        value="0.00719950322487974" />
      <inertia
        ixx="1.27951858905779E-06"
        ixy="6.81813021711596E-08"
        ixz="1.58551121583499E-12"
        iyy="5.83543537428452E-07"
        iyz="-8.56179612608701E-11"
        izz="1.32913234511164E-06" />
    </inertial>
    <visual>
      <origin
        xyz="0 0 0"
        rpy="0 0 0" />
      <geometry>
        <mesh
          filename="inspire/meshes_left/left_middle_1.STL" />
      </geometry>
      <material
        name="">
        <color
          rgba="0.792156862745098 0.819607843137255 0.933333333333333 1" />
      </material>
    </visual>
    <collision>
      <origin
        xyz="0 0 0"
        rpy="0 0 0" />
      <geometry>
        <mesh
          filename="inspire/meshes_left/left_middle_1.STL" />
      </geometry>
    </collision>
  </link>
  <joint
    name="left_middle_1_joint"
    type="revolute">
    <origin
      xyz="0.0037996 -0.00056467 -0.157"
      rpy="-1.5708 0 1.5708" />
    <parent
      link="base_link" />
    <child
      link="left_middle_1" />
    <axis
      xyz="0 0 1" />
    <limit
      lower="0"
      upper="1.6"
      effort="1"
      velocity="1" />
  </joint>
  <link
    name="left_middle_2">
    <inertial>
      <origin
        xyz="7.51983994427274E-05 0.027448753770842 -0.00610022997575017"
        rpy="0 0 0" />
      <mass
        value="0.0104611931926301" />
      <inertia
        ixx="2.75831931773332E-06"
        ixy="4.66412841401028E-07"
        ixz="7.35766561775226E-12"
        iyy="4.22466538741155E-07"
        iyz="-1.79608426686769E-11"
        izz="2.80722617348706E-06" />
    </inertial>
    <visual>
      <origin
        xyz="0 0 0"
        rpy="0 0 0" />
      <geometry>
        <mesh
          filename="inspire/meshes_left/left_middle_2.STL" />
      </geometry>
      <material
        name="">
        <color
          rgba="0.792156862745098 0.819607843137255 0.933333333333333 1" />
      </material>
    </visual>
    <collision>
      <origin
        xyz="0 0 0"
        rpy="0 0 0" />
      <geometry>
        <mesh
          filename="inspire/meshes_left/left_middle_2.STL" />
      </geometry>
    </collision>
  </link>
  <joint
    name="left_middle_2_joint"
    type="revolute">
    <origin
      xyz="-0.0028436 0.032651 -0.00055"
      rpy="0 0 0" />
    <parent
      link="left_middle_1" />
    <child
      link="left_middle_2" />
    <axis
      xyz="0 0 1" />
    <limit
      lower="0"
      upper="3.14"
      effort="10"
      velocity="1" />
    <mimic
        joint="left_middle_1_joint"
        multiplier="1.05"
        offset="0" />
  </joint>
  <link
    name="left_ring_1">
    <inertial>
      <origin
        xyz="-0.00240530428455066 0.0122563079467745 -0.00665150968297497"
        rpy="0 0 0" />
      <mass
        value="0.00719949770218712" />
      <inertia
        ixx="1.27820682409824E-06"
        ixy="7.45572429780093E-08"
        ixz="2.25718181808859E-12"
        iyy="5.84853511073517E-07"
        iyz="-8.56222330411309E-11"
        izz="1.32913088941838E-06" />
    </inertial>
    <visual>
      <origin
        xyz="0 0 0"
        rpy="0 0 0" />
      <geometry>
        <mesh
          filename="inspire/meshes_left/left_ring_1.STL" />
      </geometry>
      <material
        name="">
        <color
          rgba="0.792156862745098 0.819607843137255 0.933333333333333 1" />
      </material>
    </visual>
    <collision>
      <origin
        xyz="0 0 0"
        rpy="0 0 0" />
      <geometry>
        <mesh
          filename="inspire/meshes_left/left_ring_1.STL" />
      </geometry>
    </collision>
  </link>
  <joint
    name="left_ring_1_joint"
    type="revolute">
    <origin
      xyz="-0.017813 -0.00056467 -0.15614"
      rpy="-1.5184 0 1.5708" />
    <parent
      link="base_link" />
    <child
      link="left_ring_1" />
    <axis
      xyz="0 0 1" />
    <limit
      lower="0"
      upper="1.6"
      effort="10"
      velocity="1" />
  </joint>
  <link
    name="left_ring_2">
    <inertial>
      <origin
        xyz="0.000667145407605998 0.0256949163202511 -0.00610829894053159"
        rpy="0 0 0" />
      <mass
        value="0.00968685177133057" />
      <inertia
        ixx="2.26381138740299E-06"
        ixy="3.92210300202205E-07"
        ixz="3.58404653503583E-10"
        iyy="3.83095000534084E-07"
        iyz="-2.77027363965469E-09"
        izz="2.30247104599333E-06" />
    </inertial>
    <visual>
      <origin
        xyz="0 0 0"
        rpy="0 0 0" />
      <geometry>
        <mesh
          filename="inspire/meshes_left/left_ring_2.STL" />
      </geometry>
      <material
        name="">
        <color
          rgba="0.792156862745098 0.819607843137255 0.933333333333333 1" />
      </material>
    </visual>
    <collision>
      <origin
        xyz="0 0 0"
        rpy="0 0 0" />
      <geometry>
        <mesh
          filename="inspire/meshes_left/left_ring_2.STL" />
      </geometry>
    </collision>
  </link>
  <joint
    name="left_ring_2_joint"
    type="revolute">
    <origin
      xyz="-0.0031431 0.032624 -0.00055"
      rpy="0 0 0" />
    <parent
      link="left_ring_1" />
    <child
      link="left_ring_2" />
    <axis
      xyz="0 0 1" />
    <limit
      lower="0"
      upper="3.14"
      effort="10"
      velocity="1" />
    <mimic
        joint="left_ring_1_joint"
        multiplier="1.05"
        offset="0" />
  </joint>
  <link
    name="left_little_1">
    <inertial>
      <origin
        xyz="-0.00316889023513399 0.0120814769898197 -0.00665148964848"
        rpy="0 0 0" />
      <mass
        value="0.0071994553320001" />
      <inertia
        ixx="1.26614239360362E-06"
        ixy="1.17349328114653E-07"
        ixz="6.69925886240907E-12"
        iyy="5.96905140854994E-07"
        iyz="-8.54914063893311E-11"
        izz="1.32912203576944E-06" />
    </inertial>
    <visual>
      <origin
        xyz="0 0 0"
        rpy="0 0 0" />
      <geometry>
        <mesh
          filename="inspire/meshes_left/left_little_1.STL" />
      </geometry>
      <material
        name="">
        <color
          rgba="0.792156862745098 0.819607843137255 0.933333333333333 1" />
      </material>
    </visual>
    <collision>
      <origin
        xyz="0 0 0"
        rpy="0 0 0" />
      <geometry>
        <mesh
          filename="inspire/meshes_left/left_little_1.STL" />
      </geometry>
    </collision>
  </link>
  <joint
    name="left_little_1_joint"
    type="revolute">
    <origin
      xyz="-0.039144 -0.00056467 -0.15226"
      rpy="-1.4661 0 1.5708" />
    <parent
      link="base_link" />
    <child
      link="left_little_1" />
    <axis
      xyz="0 0 1" />
    <limit
      lower="0"
      upper="1.6"
      effort="10"
      velocity="1" />
  </joint>
  <link
    name="left_little_2">
    <inertial>
      <origin
        xyz="0.00469503836926433 0.020441957551037 -0.0061004930536056"
        rpy="0 0 0" />
      <mass
        value="0.00759267726265222" />
      <inertia
        ixx="1.27661762368947E-06"
        ixy="7.27034842413144E-08"
        ixz="1.62724400979504E-12"
        iyy="2.31536498425727E-07"
        iyz="-9.71604458446237E-12"
        izz="1.23907231734916E-06" />
    </inertial>
    <visual>
      <origin
        xyz="0 0 0"
        rpy="0 0 0" />
      <geometry>
        <mesh
          filename="inspire/meshes_left/left_little_2.STL" />
      </geometry>
      <material
        name="">
        <color
          rgba="0.792156862745098 0.819607843137255 0.933333333333333 1" />
      </material>
    </visual>
    <collision>
      <origin
        xyz="0 0 0"
        rpy="0 0 0" />
      <geometry>
        <mesh
          filename="inspire/meshes_left/left_little_2.STL" />
      </geometry>
    </collision>
  </link>
  <joint
    name="left_little_2_joint"
    type="revolute">
    <origin
      xyz="-0.005182 0.032363 -0.00055"
      rpy="0 0 0" />
    <parent
      link="left_little_1" />
    <child
      link="left_little_2" />
    <axis
      xyz="0 0 1" />
    <limit
      lower="0"
      upper="3.14"
      effort="10"
      velocity="1" />
    <mimic
        joint="left_little_1_joint"
        multiplier="1.18"
        offset="0" />  
  </joint>
</robot>
