<?xml version="1.0" encoding="utf-8"?>
<robot name="xarm_allegro_v5">
  <material name="Black">
    
    <color rgba="0.0 0.0 0.0 1.0"/>
    
  </material>
  
  <material name="Red">
    
    <color rgba="0.8 0.0 0.0 1.0"/>
    
  </material>
  
  <material name="White">
    
    <color rgba="1.0 1.0 1.0 1.0"/>
    
  </material>
  
  <material name="Silver">
    
    <color rgba="0.753 0.753 0.753 1.0"/>
    
  </material>
  
  <link name="world"/>
  
  <joint name="world_joint" type="fixed">
    
    <parent link="world"/>
    
    <child link="link_base"/>
    
    <origin rpy="0 0 0" xyz="0 0 0"/>
    
  </joint>
  
  <link name="link_base">
    
    <visual>
      
      <geometry>
        
        <mesh filename="xarm/meshes/base.obj"/>
        
      </geometry>
      
      <origin rpy="0 0 0" xyz="0 0 0"/>
      
      <material name="White"/>
      
    </visual>
    
    <collision>
      
      <geometry>
        
        <mesh filename="xarm/meshes/base.obj"/>
        
      </geometry>
      
      <origin rpy="0 0 0" xyz="0 0 0"/>
      
    </collision>
    
    <inertial>
      
      <origin rpy="0 0 0" xyz="0.0 0.0 0.09103"/>
      
      <mass value="2.7"/>
      
      <inertia ixx="0.00494875" ixy="-3.5E-06" ixz="1.25E-05" iyy="0.00494174" iyz="1.67E-06" izz="0.002219"/>
      
    </inertial>
    
  </link>
  
  <link name="link1">
    
    <visual>
      
      <geometry>
        
        <mesh filename="xarm/meshes/link1.obj"/>
        
      </geometry>
      
      <origin rpy="0 0 0" xyz="0 0 0"/>
      
      <material name="White"/>
      
    </visual>
    
    <collision>
      
      <geometry>
        
        <mesh filename="xarm/meshes/link1.obj"/>
        
      </geometry>
      
      <origin rpy="0 0 0" xyz="0 0 0"/>
      
    </collision>
    
    <inertial>
      
      <origin rpy="0 0 0" xyz="-0.002 0.02692 -0.01332"/>
      
      <mass value="2.16"/>
      
      <inertia ixx="0.00539427" ixy="1.095E-05" ixz="1.635E-06" iyy="0.0048979" iyz="0.000793" izz="0.00311573"/>
      
    </inertial>
    
  </link>
  
  <joint name="joint1" type="revolute">
    
    <parent link="link_base"/>
    
    <child link="link1"/>
    
    <origin rpy="-0.000981912831775844 -0.0020678131841123104 1.0152065215152106e-06" xyz="-0.0007769996882416308 0.0007711717044003308 0.26595622301101685"/>

    <axis xyz="0 0 1"/>

    <limit effort="50.0" lower="-6.283185307179586" upper="6.283185307179586" velocity="3.14"/>

    <dynamics damping="1.0" friction="1.0"/>

  </joint>
  
  <link name="link2">
    
    <visual>
      
      <geometry>
        
        <mesh filename="xarm/meshes/link2.obj"/>
        
      </geometry>
      
      <origin rpy="0 0 0" xyz="0 0 0"/>
      
      <material name="White"/>
      
    </visual>
    
    <collision>
      
      <geometry>
        
        <mesh filename="xarm/meshes/link2.obj"/>
        
      </geometry>
      
      <origin rpy="0 0 0" xyz="0 0 0"/>
      
    </collision>
    
    <inertial>
      
      <origin rpy="0 0 0" xyz="0.03531 -0.21398 0.03386"/>
      
      <mass value="1.71"/>
      
      <inertia ixx="0.0248674" ixy="-0.00430651" ixz="-0.00067797" iyy="0.00485548" iyz="0.00457245" izz="0.02387827"/>
      
    </inertial>
    
  </link>
  
  <joint name="joint2" type="revolute">
    
    <parent link="link1"/>
    
    <child link="link2"/>
    
    <origin rpy="-1.5712535381317139 0.002067566616460681 0.0009407909237779677" xyz="-4.07262341468595e-05 -3.840348838934915e-08 -7.701249360447804e-12"/>

    <axis xyz="0 0 1"/>

    <limit effort="50.0" lower="-2.059" upper="2.0944" velocity="3.14"/>
    
    <dynamics damping="1.0" friction="1.0"/>
    
  </joint>
  
  <link name="link3">
    
    <visual>
      
      <geometry>
        
        <mesh filename="xarm/meshes/link3.obj"/>
        
      </geometry>
      
      <origin rpy="0 0 0" xyz="0 0 0"/>
      
      <material name="White"/>
      
    </visual>
    
    <collision>
      
      <geometry>
        
        <mesh filename="xarm/meshes/link3.obj"/>
        
      </geometry>
      
      <origin rpy="0 0 0" xyz="0 0 0"/>
      
    </collision>
    
    <inertial>
      
      <origin rpy="0 0 0" xyz="0.06781 0.10749 0.01457"/>
      
      <mass value="1.384"/>
      
      <inertia ixx="0.0053694" ixy="0.0014185" ixz="-0.00092094" iyy="0.0032423" iyz="-0.00169178" izz="0.00501731"/>
      
    </inertial>
    
  </link>
  
  <joint name="joint3" type="revolute">
    
    <parent link="link2"/>
    
    <child link="link3"/>
    
    <origin rpy="0.001618124428205192 -0.0010822704061865807 -2.415801873212331e-06" xyz="0.053162120282649994 -0.2844921350479126 0.0004026298993267119"/>

    <axis xyz="0 0 1"/>

    <limit effort="32.0" lower="-3.927" upper="0.19198" velocity="3.14"/>
    
    <dynamics damping="1.0" friction="1.0"/>
    
  </joint>
  
  <link name="link4">
    
    <visual>
      
      <geometry>
        
        <mesh filename="xarm/meshes/link4.obj"/>
        
      </geometry>
      
      <origin rpy="0 0 0" xyz="0 0 0"/>
      
      <material name="White"/>
      
    </visual>
    
    <collision>
      
      <geometry>
        
        <mesh filename="xarm/meshes/link4.obj"/>
        
      </geometry>
      
      <origin rpy="0 0 0" xyz="0 0 0"/>
      
    </collision>
    
    <inertial>
      
      <origin rpy="0 0 0" xyz="-0.00021 0.02578 -0.02538"/>
      
      <mass value="1.115"/>
      
      <inertia ixx="0.00439263" ixy="5.028E-05" ixz="1.374E-05" iyy="0.0040077" iyz="0.00045338" izz="0.00110321"/>
      
    </inertial>
    
  </link>
  
  <joint name="joint4" type="revolute">
    
    <parent link="link3"/>
    
    <child link="link4"/>
    
    <origin rpy="-1.57097327709198 0.0020220461301505566 -1.7895548864999e-07" xyz="0.0777892991900444 0.34164339303970337 -6.047571878298186e-05"/>

    <axis xyz="0 0 1"/>

    <limit effort="32.0" lower="-6.283185307179586" upper="6.283185307179586" velocity="3.14"/>
    
    <dynamics damping="1.0" friction="1.0"/>
    
  </joint>
  
  <link name="link5">
    
    <visual>
      
      <geometry>
        
        <mesh filename="xarm/meshes/link5.obj"/>
        
      </geometry>
      
      <origin rpy="0 0 0" xyz="0 0 0"/>
      
      <material name="White"/>
      
    </visual>
    
    <collision>
      
      <geometry>
        
        <mesh filename="xarm/meshes/link5.obj"/>
        
      </geometry>
      
      <origin rpy="0 0 0" xyz="0 0 0"/>
      
    </collision>
    
    <inertial>
      
      <origin rpy="0 0 0" xyz="0.05428 0.01781 0.00543"/>
      
      <mass value="1.275"/>
      
      <inertia ixx="0.001202758" ixy="0.000492428" ixz="-0.00039147" iyy="0.0022876" iyz="-1.235E-04" izz="0.0026866"/>
      
    </inertial>
    
  </link>
  
  <joint name="joint5" type="revolute">
    
    <parent link="link4"/>
    
    <child link="link5"/>
    
    <origin rpy="1.5707963705062866 -0.0 0.0" xyz="-0.00013099999341648072 0.0021800000686198473 -2.6697300799058424e-19"/>

    <axis xyz="0 0 1"/>

    <limit effort="32.0" lower="-1.69297" upper="3.141592653589793" velocity="3.14"/>
    
    <dynamics damping="1.0" friction="1.0"/>
    
  </joint>
  
  <link name="link6">
    
    <visual>
      
      <geometry>
        
        <mesh filename="xarm/meshes/link6.obj"/>
        
      </geometry>
      
      <origin rpy="0 0 0" xyz="0 0 0"/>
      
      <material name="Silver"/>
      
    </visual>
    
    <collision>
      
      <geometry>
        
        <mesh filename="xarm/meshes/link6.obj"/>
        
      </geometry>
      
      <origin rpy="0 0 0" xyz="0 0 0"/>
      
    </collision>
    
    <inertial>
      
      <origin rpy="0 0 0" xyz="0 0.00064 -0.00952"/>
      
      <mass value="0.1096"/>
      
      <inertia ixx="4.5293E-05" ixy="0" ixz="0" iyy="4.8111E-05" iyz="0" izz="7.9715E-05"/>
      
    </inertial>
    
  </link>
  
  <joint name="joint6" type="revolute">
    
    <parent link="link5"/>
    
    <child link="link6"/>
    
    <origin rpy="-1.570866346359253 0.00012199999764561653 -0.00012799999967683107" xyz="0.07616599649190903 0.09558600187301636 0.00021499999274965376"/>

    <axis xyz="0 0 1"/>

    <limit effort="20.0" lower="-6.283185307179586" upper="6.283185307179586" velocity="3.14"/>
    
    <dynamics damping="1.0" friction="1.0"/>
    
  </joint>

  <link name="wrist"/>
  <joint name="arm_to_hand" type="fixed">
    <parent link="link6"/>
    <child link="wrist"/>
    <origin rpy="3.14159 3.14159 1.57079" xyz="0.00000 -0.00700 0.146000"/>
  </joint>
  <joint name="wrist_to_palm" type="fixed">
    <parent link="wrist"/>
    <child link="palm_link"/>
    <origin rpy="0 0 0" xyz="0 0 0"/>
  </joint>
  <link name="palm_link">
    <visual>
      <geometry>
        <mesh filename="allegro_v5/meshes/palm.stl" scale="0.001 0.001 0.001"/>
      </geometry>
      <origin rpy="0 3.14 1.57" xyz="0.02 -0.00 -0.1"/>
      <material name="black">
        <color rgba="0.2 0.2 0.2 1"/>
      </material>
    </visual>
    <collision>
      <geometry>
        <mesh filename="allegro_v5/meshes/palm.stl" scale="0.001 0.001 0.001"/>
      </geometry>
      <origin rpy="0 3.14 1.57" xyz="0.02 -0.00 -0.1"/>
    </collision>
    <inertial>
      <origin rpy="0 0 0" xyz="0 0 0.0475"/>
      <mass value="0.4154"/>
      <inertia ixx="1e-4" ixy="0.0" ixz="0.0" iyy="1e-4" iyz="0.0" izz="1e-4"/>
    </inertial>
  </link>
  <!-- ============================================================================= -->
  <!-- FINGERS -->
  <!-- RIGHT HAND due to which finger is number 0 -->
  <!-- for LEFT HAND switch the sign of the **offset_origin_y** and **finger_angle_r** parameters-->
  <!-- [LINK 0, 4, 8] -->
  <link name="link_0_0">
    <visual>
      <geometry>
        <mesh filename="allegro_v5/meshes/l1.stl" scale="0.001 0.001 0.001"/>
      </geometry>
      <origin rpy="0 0 -1.57" xyz="-0.025 -0.019 0.165"/>
      <material name="black">
        <color rgba="0.2 0.2 0.2 1"/>
      </material>
    </visual>
    <collision>
      <geometry>
        <mesh filename="allegro_v5/meshes/l1.stl" scale="0.001 0.001 0.001"/>
      </geometry>
      <origin rpy="0 0 -1.57" xyz="-0.025 -0.019 0.165"/>
    </collision>
    <inertial>
      <mass value="0.0176"/>
      <origin rpy="0 0 0" xyz="0 0 0"/>
      <inertia ixx="1.2854008e-05" ixy="2.04e-08" ixz="1.89e-06" iyy="1.225e-05" iyz="1.51e-07" izz="2.999e-06"/>
    </inertial>
  </link>
  <joint name="joint_0_0" type="revolute">
    <axis xyz="0 0 1"/>
    <limit effort="15" lower="-0.47" upper="0.47" velocity="7"/>
    <parent link="palm_link"/>
    <child link="link_0_0"/>
    <origin rpy="-0.08726646255 0 0" xyz="0.00 0.0405 -0.00945"/>
    <dynamics damping="3" friction="10"/>
  </joint>
  <!-- [LINK 1, 5, 9] -->
  <link name="link_1_0">
    <visual>
      <geometry>
        <mesh filename="allegro_v5/meshes/l2.stl" scale="0.001 0.001 0.001"/>
      </geometry>
      <origin rpy="0 0 -1.57" xyz="-0.025 -0.019 0.145"/>
      <material name="black"/>
    </visual>
    <collision>
      <geometry>
        <mesh filename="allegro_v5/meshes/l2.stl" scale="0.001 0.001 0.001"/>
      </geometry>
      <origin rpy="0 0 -1.57" xyz="-0.025 -0.019 0.145"/>
    </collision>
    <inertial>
      <mass value="0.066"/>
      <origin rpy="0 0 0" xyz="0 0 0"/>
      <inertia ixx="6.2497616e-06" ixy="0.0000e-06" ixz="-1.892683e-06" iyy="3.1284129e-05" iyz="0.0000e-06" izz="2.9004797e-05"/>
    </inertial>
  </link>
  <joint name="joint_1_0" type="revolute">
    <limit effort="15" lower="-0.196" upper="1.8" velocity="7"/>
    <axis xyz="0 1 0"/>
    <parent link="link_0_0"/>
    <child link="link_1_0"/>
    <origin xyz="0.00 0 0.021"/>
    <dynamics damping="3" friction="5"/>
  </joint>
  <!-- [LINK 2, 6, 10]-->
  <link name="link_2_0">
    <visual>
      <geometry>
        <mesh filename="allegro_v5/meshes/l3.stl" scale="0.001 0.001 0.001"/>
      </geometry>
      <origin rpy="0 0 -1.57" xyz="-0.025 -0.019 0.0945"/>
      <material name="black"/>
    </visual>
    <collision>
      <geometry>
        <mesh filename="allegro_v5/meshes/l3.stl" scale="0.001 0.001 0.001"/>
      </geometry>
      <origin rpy="0 0 -1.57" xyz="-0.025 -0.019 0.0945"/>
    </collision>
    <inertial>
      <mass value="0.0366"/>
      <origin rpy="0 0 0" xyz="0 0 0"/>
      <inertia ixx="3.8070280e-06" ixy="5.7154287e-03" ixz="-9.9708657e-07" iyy="1.4547214e-05" iyz="2.632663e-04" izz="1.2905337e-05"/>
    </inertial>
  </link>
  <joint name="joint_2_0" type="revolute">
    <axis xyz="0 1 0"/>
    <limit effort="15" lower="-0.174" upper="1.709" velocity="7"/>
    <parent link="link_1_0"/>
    <child link="link_2_0"/>
    <origin xyz="0 0 0.051"/>
    <dynamics damping="8" friction="10"/>
  </joint>
  <!-- [LINK 3, 7, 11] -->
  <link name="link_3_0">
    <visual>
      <geometry>
        <mesh filename="allegro_v5/meshes/l4.stl" scale="0.001 0.001 0.001"/>
      </geometry>
      <origin rpy="0 0 -1.57" xyz="-0.025 -0.019 0.0561"/>
      <material name="black"/>
    </visual>
    <collision>
      <geometry>
        <mesh filename="allegro_v5/meshes/l4.stl" scale="0.001 0.001 0.001"/>
      </geometry>
      <origin rpy="0 0 -1.57" xyz="-0.025 -0.019 0.0561"/>
    </collision>
    <inertial>
      <mass value="0.00569"/>
      <origin rpy="0 0 0" xyz="0 0 0"/>
      <inertia ixx="1.176928e-06" ixy="5.0891669e-03" ixz="0.000000e-06" iyy="2.40127e-06" iyz="-5.3128971e-11" izz="1.674842e-06"/>
    </inertial>
  </link>
  <joint name="joint_3_0" type="revolute">
    <axis xyz="0 1 0"/>
    <limit effort="15" lower="-0.227" upper="1.618" velocity="7"/>
    <parent link="link_2_0"/>
    <child link="link_3_0"/>
    <origin rpy="0 -0.15 0" xyz="0 0 0.0384"/>
    <dynamics damping="10" friction="12"/>
  </joint>
  <!-- [FINGER TIP] -->
  <link name="link_3_0_tip">
    <visual>
      <geometry>
        <mesh filename="allegro_v5/meshes/finger_tip.stl" scale="0.001 0.001 0.0012"/>
      </geometry>
      <origin rpy="0 0 -1.57" xyz="-0.05482 -0.01393 -0.00995"/>
      <material name="white">
        <color rgba=".9 .9 .9 1"/>
      </material>
    </visual>
    <collision>
      <geometry>
        <mesh filename="allegro_v5/meshes/finger_tip.stl" scale="0.001 0.001 0.0012"/>
      </geometry>
      <origin rpy="0 0 -1.57" xyz="-0.05482 -0.01393 -0.00995"/>
    </collision>
    <inertial>
      <mass value="0.00"/>
      <origin rpy="0 0 0" xyz="0 0 0"/>
      <inertia ixx="9.68e-07" ixy="0" ixz="0" iyy="9.68e-07" iyz="0" izz="9.68e-07"/>
    </inertial>
  </link>
  <joint name="joint_3_0_tip" type="fixed">
    <parent link="link_3_0"/>
    <child link="link_3_0_tip"/>
    <origin rpy="0 0 0" xyz="0 0 0.0267"/>
  </joint>
  <!-- [LINK 0, 4, 8] -->
  <link name="link_4_0">
    <visual>
      <geometry>
        <mesh filename="allegro_v5/meshes/l1.stl" scale="0.001 0.001 0.0012"/>
      </geometry>
      <origin rpy="0 0 -1.57" xyz="-0.025 -0.019 0.165"/>
      <material name="black"/>
    </visual>
    <collision>
      <geometry>
        <mesh filename="allegro_v5/meshes/l1.stl" scale="0.001 0.001 0.0012"/>
      </geometry>
      <origin rpy="0 0 -1.57" xyz="-0.025 -0.019 0.165"/>
    </collision>
    <inertial>
      <mass value="0.0176"/>
      <origin rpy="0 0 0" xyz="0 0 0"/>
      <inertia ixx="1.2854008e-05" ixy="2.04e-08" ixz="1.89e-06" iyy="1.225e-05" iyz="1.51e-07" izz="2.999e-06"/>
    </inertial>
  </link>
  <joint name="joint_4_0" type="revolute">
    <axis xyz="0 0 1"/>
    <limit effort="15" lower="-0.47" upper="0.47" velocity="7"/>
    <parent link="palm_link"/>
    <child link="link_4_0"/>
    <origin rpy="0.0 0 0" xyz="0 0.00 -0.0079"/>
    <dynamics damping="3" friction="10"/>
  </joint>
  <!-- [LINK 1, 5, 9] -->
  <link name="link_5_0">
    <visual>
      <geometry>
        <mesh filename="allegro_v5/meshes/l2.stl" scale="0.001 0.001 0.001"/>
      </geometry>
      <origin rpy="0 0 -1.57" xyz="-0.025 -0.019 0.145"/>
      <material name="black"/>
    </visual>
    <collision>
      <geometry>
        <mesh filename="allegro_v5/meshes/l2.stl" scale="0.001 0.001 0.001"/>
      </geometry>
      <origin rpy="0 0 -1.57" xyz="-0.025 -0.019 0.145"/>
    </collision>
    <inertial>
      <mass value="0.066"/>
      <origin rpy="0 0 0" xyz="0 0 0"/>
      <inertia ixx="6.2497616e-06" ixy="0.0000e-06" ixz="-1.892683e-06" iyy="3.1284129e-05" iyz="0.0000e-06" izz="2.9004797e-05"/>
    </inertial>
  </link>
  <joint name="joint_5_0" type="revolute">
    <limit effort="15" lower="-0.196" upper="1.8" velocity="7"/>
    <axis xyz="0 1 0"/>
    <parent link="link_4_0"/>
    <child link="link_5_0"/>
    <origin xyz="0 0 0.021"/>
    <dynamics damping="3" friction="5"/>
  </joint>
  <!-- [LINK 2, 6, 10]-->
  <link name="link_6_0">
    <visual>
      <geometry>
        <mesh filename="allegro_v5/meshes/l3.stl" scale="0.001 0.001 0.001"/>
      </geometry>
      <origin rpy="0 0 -1.57" xyz="-0.025 -0.019 0.0945"/>
      <material name="black"/>
    </visual>
    <collision>
      <geometry>
        <mesh filename="allegro_v5/meshes/l3.stl" scale="0.001 0.001 0.001"/>
      </geometry>
      <origin rpy="0 0 -1.57" xyz="-0.025 -0.019 0.0945"/>
    </collision>
    <inertial>
      <mass value="0.0366"/>
      <origin rpy="0 0 0" xyz="0 0 0"/>
      <inertia ixx="3.8070280e-06" ixy="5.7154287e-03" ixz="-9.9708657e-07" iyy="1.4547214e-05" iyz="2.632663e-04" izz="1.2905337e-05"/>
    </inertial>
  </link>
  <joint name="joint_6_0" type="revolute">
    <axis xyz="0 1 0"/>
    <limit effort="15" lower="-0.174" upper="1.709" velocity="7"/>
    <parent link="link_5_0"/>
    <child link="link_6_0"/>
    <origin xyz="0 0 0.051"/>
    <dynamics damping="8" friction="10"/>
  </joint>
  <!-- [LINK 3, 7, 11] -->
  <link name="link_7_0">
    <visual>
      <geometry>
        <mesh filename="allegro_v5/meshes/l4.stl" scale="0.001 0.001 0.001"/>
      </geometry>
      <origin rpy="0 0 -1.57" xyz="-0.025 -0.019 0.0561"/>
      <material name="black"/>
    </visual>
    <collision>
      <geometry>
        <mesh filename="allegro_v5/meshes/l4.stl" scale="0.001 0.001 0.001"/>
      </geometry>
      <origin rpy="0 0 -1.57" xyz="-0.025 -0.019 0.0561"/>
    </collision>
    <inertial>
      <mass value="0.00569"/>
      <origin rpy="0 0 0" xyz="0 0 0"/>
      <inertia ixx="1.176928e-06" ixy="5.0891669e-03" ixz="0.000000e-06" iyy="2.40127e-06" iyz="-5.3128971e-11" izz="1.674842e-06"/>
    </inertial>
  </link>
  <joint name="joint_7_0" type="revolute">
    <axis xyz="0 1 0"/>
    <limit effort="15" lower="-0.227" upper="1.618" velocity="7"/>
    <parent link="link_6_0"/>
    <child link="link_7_0"/>
    <origin rpy="0 -0.15 0" xyz="0 0 0.0384"/>
    <dynamics damping="10" friction="12"/>
  </joint>
  <!-- [FINGER TIP] -->
  <link name="link_7_0_tip">
    <visual>
      <geometry>
        <mesh filename="allegro_v5/meshes/finger_tip.stl" scale="0.001 0.001 0.0012"/>
      </geometry>
      <origin rpy="0 0 -1.57" xyz="-0.05482 -0.01393 -0.00995"/>
      <material name="white">
        <color rgba=".9 .9 .9 1"/>
      </material>
    </visual>
    <collision>
      <geometry>
        <mesh filename="allegro_v5/meshes/finger_tip.stl" scale="0.001 0.001 0.0012"/>
      </geometry>
      <origin rpy="0 0 -1.57" xyz="-0.05482 -0.01393 -0.00995"/>
    </collision>
    <inertial>
      <mass value="0.00"/>
      <origin rpy="0 0 0" xyz="0 0 0"/>
      <inertia ixx="9.68e-07" ixy="0" ixz="0" iyy="9.68e-07" iyz="0" izz="9.68e-07"/>
    </inertial>
  </link>
  <joint name="joint_7_0_tip" type="fixed">
    <parent link="link_7_0"/>
    <child link="link_7_0_tip"/>
    <origin rpy="0 0 0" xyz="0 0 0.0267"/>
  </joint>
  <!-- [LINK 0, 4, 8] -->
  <link name="link_8_0">
    <visual>
      <geometry>
        <mesh filename="allegro_v5/meshes/l1.stl" scale="0.001 0.001 0.0012"/>
      </geometry>
      <origin rpy="0 0 -1.57" xyz="-0.025 -0.019 0.165"/>
      <material name="black">
        <color rgba="0.2 0.2 0.2 1"/>
      </material>
    </visual>
    <collision>
      <geometry>
        <mesh filename="allegro_v5/meshes/l1.stl" scale="0.001 0.001 0.0012"/>
      </geometry>
      <origin rpy="0 0 -1.57" xyz="-0.025 -0.019 0.165"/>
    </collision>
    <inertial>
      <mass value="0.0176"/>
      <origin rpy="0 0 0" xyz="0 0 0"/>
      <inertia ixx="1.2854008e-05" ixy="2.04e-08" ixz="1.89e-06" iyy="1.225e-05" iyz="1.51e-07" izz="2.999e-06"/>
    </inertial>
  </link>
  <joint name="joint_8_0" type="revolute">
    <axis xyz="0 0 1"/>
    <limit effort="15" lower="-0.47" upper="0.47" velocity="7"/>
    <parent link="palm_link"/>
    <child link="link_8_0"/>
    <origin rpy="0.08726646255 0 0" xyz="0.0025 -0.0405 -0.00945"/>
    <dynamics damping="3" friction="10"/>
  </joint>
  <!-- [LINK 1, 5, 9] -->
  <link name="link_9_0">
    <visual>
      <geometry>
        <mesh filename="allegro_v5/meshes/l2.stl" scale="0.001 0.001 0.001"/>
      </geometry>
      <origin rpy="0 0 -1.57" xyz="-0.025 -0.019 0.145"/>
      <material name="black"/>
    </visual>
    <collision>
      <geometry>
        <mesh filename="allegro_v5/meshes/l2.stl" scale="0.001 0.001 0.001"/>
      </geometry>
      <origin rpy="0 0 -1.57" xyz="-0.025 -0.019 0.145"/>
    </collision>
    <inertial>
      <mass value="0.066"/>
      <origin rpy="0 0 0" xyz="0 0 0"/>
      <inertia ixx="6.2497616e-06" ixy="0.0000e-06" ixz="-1.892683e-06" iyy="3.1284129e-05" iyz="0.0000e-06" izz="2.9004797e-05"/>
    </inertial>
  </link>
  <joint name="joint_9_0" type="revolute">
    <limit effort="15" lower="-0.196" upper="1.8" velocity="7"/>
    <axis xyz="0 1 0"/>
    <parent link="link_8_0"/>
    <child link="link_9_0"/>
    <origin xyz="0 0 0.021"/>
    <dynamics damping="3" friction="5"/>
  </joint>
  <!-- [LINK 2, 6, 10]-->
  <link name="link_10_0">
    <visual>
      <geometry>
        <mesh filename="allegro_v5/meshes/l3.stl" scale="0.001 0.001 0.001"/>
      </geometry>
      <origin rpy="0 0 -1.57" xyz="-0.025 -0.019 0.0945"/>
      <material name="black"/>
    </visual>
    <collision>
      <geometry>
        <mesh filename="allegro_v5/meshes/l3.stl" scale="0.001 0.001 0.001"/>
      </geometry>
      <origin rpy="0 0 -1.57" xyz="-0.025 -0.019 0.0945"/>
    </collision>
    <inertial>
      <mass value="0.0366"/>
      <origin rpy="0 0 0" xyz="0 0 0"/>
      <inertia ixx="3.8070280e-06" ixy="5.7154287e-03" ixz="-9.9708657e-07" iyy="1.4547214e-05" iyz="2.632663e-04" izz="1.2905337e-05"/>
    </inertial>
  </link>
  <joint name="joint_10_0" type="revolute">
    <axis xyz="0 1 0"/>
    <limit effort="15" lower="-0.174" upper="1.709" velocity="7"/>
    <parent link="link_9_0"/>
    <child link="link_10_0"/>
    <origin xyz="0 0 0.051"/>
    <dynamics damping="8" friction="10"/>
  </joint>
  <!-- [LINK 3, 7, 11] -->
  <link name="link_11_0">
    <visual>
      <geometry>
        <mesh filename="allegro_v5/meshes/l4.stl" scale="0.001 0.001 0.001"/>
      </geometry>
      <origin rpy="0 0 -1.57" xyz="-0.025 -0.019 0.0561"/>
      <material name="black"/>
    </visual>
    <collision>
      <geometry>
        <mesh filename="allegro_v5/meshes/l4.stl" scale="0.001 0.001 0.001"/>
      </geometry>
      <origin rpy="0 0 -1.57" xyz="-0.025 -0.019 0.0561"/>
    </collision>
    <inertial>
      <mass value="0.00569"/>
      <origin rpy="0 0 0" xyz="0 0 0"/>
      <inertia ixx="1.176928e-06" ixy="5.0891669e-03" ixz="0.000000e-06" iyy="2.40127e-06" iyz="-5.3128971e-11" izz="1.674842e-06"/>
    </inertial>
  </link>
  <joint name="joint_11_0" type="revolute">
    <axis xyz="0 1 0"/>
    <limit effort="15" lower="-0.227" upper="1.618" velocity="7"/>
    <parent link="link_10_0"/>
    <child link="link_11_0"/>
    <origin rpy="0 -0.15 0" xyz="0 0 0.0384"/>
    <dynamics damping="10" friction="12"/>
  </joint>
  <!-- [FINGER TIP] -->
  <link name="link_11_0_tip">
    <visual>
      <geometry>
        <mesh filename="allegro_v5/meshes/finger_tip.stl" scale="0.001 0.001 0.0012"/>
      </geometry>
      <origin rpy="0 0 -1.57" xyz="-0.05482 -0.01393 -0.00995"/>
      <material name="white">
        <color rgba=".9 .9 .9 1"/>
      </material>
    </visual>
    <collision>
      <geometry>
        <mesh filename="allegro_v5/meshes/finger_tip.stl" scale="0.001 0.001 0.0012"/>
      </geometry>
      <origin rpy="0 0 -1.57" xyz="-0.05482 -0.01393 -0.00995"/>
    </collision>
    <inertial>
      <mass value="0.00"/>
      <origin rpy="0 0 0" xyz="0 0 0"/>
      <inertia ixx="9.68e-07" ixy="0" ixz="0" iyy="9.68e-07" iyz="0" izz="9.68e-07"/>
    </inertial>
  </link>
  <joint name="joint_11_0_tip" type="fixed">
    <parent link="link_11_0"/>
    <child link="link_11_0_tip"/>
    <origin rpy="0 0 0" xyz="0 0 0.0267"/>
  </joint>
  <!-- THUMB -->
  <!-- [LINK 12] -->
  <link name="link_12_0">
    <visual>
      <geometry>
        <mesh filename="allegro_v5/meshes/t1_set.stl" scale="0.001 0.001 0.001"/>
      </geometry>
      <origin rpy="3.926991 3.14 3.14" xyz="0.021 -0.1145 0.0725"/>
      <material name="black">
        <color rgba=".2 .2 .2 1"/>
      </material>
    </visual>
    <collision>
      <geometry>
        <mesh filename="allegro_v5/meshes/t1_set.stl" scale="0.001 0.001 0.001"/>
      </geometry>
      <origin rpy="3.926991 3.14 3.14" xyz="0.021 -0.1145 0.0725"/>
    </collision>
    <inertial>
      <mass value="0.0446"/>
      <origin rpy="0 0 0" xyz="0 0 0"/>
      <inertia ixx="5.44e-5" ixy="4.0e-07" ixz="-1.12e-07" iyy="9.19e-06" iyz="1.07e-05" izz="4.8e-05"/>
    </inertial>
  </link>
  <joint name="joint_12_0" type="revolute">
    <axis xyz="-1 0 0"/>
    <limit effort="15" lower="0.00" upper="1.78" velocity="7"/>
    <parent link="palm_link"/>
    <child link="link_12_0"/>
    <origin rpy="0 -1.65806278845 -1.5707963259" xyz="0.002 0.027 -0.06342"/>
    <dynamics damping="3" friction="10"/>
  </joint>
  <!-- [LINK 13] -->
  <link name="link_13_0">
    <visual>
      <geometry>
        <mesh filename="allegro_v5/meshes/t2_set.stl" scale="0.001 0.001 0.001"/>
      </geometry>
      <origin rpy="3.14 3.14 1.57" xyz="-0.138 -0.0605 0.2143"/>
      <material name="black">
        <color rgba=".2 .2 .2 1"/>
      </material>
    </visual>
    <collision>
      <geometry>
        <mesh filename="allegro_v5/meshes/t2_set.stl" scale="0.001 0.001 0.001"/>
      </geometry>
      <origin rpy="3.14 3.14 1.57" xyz="-0.138 -0.0605 0.2143"/>
    </collision>
    <inertial>
      <mass value="0.0173"/>
      <origin rpy="0 0 0" xyz="0 0 0"/>
      <inertia ixx="1.52e-05" ixy="-2.09e-08" ixz="-9.8e-09" iyy="1.3323e-05" iyz="-2.04e-06" izz="2.85e-06"/>
    </inertial>
  </link>
  <joint name="joint_13_0" type="revolute">
    <axis xyz="0 0 1"/>
    <limit effort="15" lower="-0.26" upper="1.78" velocity="7"/>
    <parent link="link_12_0"/>
    <child link="link_13_0"/>
    <origin xyz="-0.001 0.00 0.06874"/>
    <dynamics damping="3" friction="5"/>
  </joint>
  <!-- [LINK 14] -->
  <link name="link_14_0">
    <visual>
      <geometry>
        <mesh filename="allegro_v5/meshes/t3_set.stl" scale="0.001 0.001 0.001"/>
      </geometry>
      <origin rpy="3.14 3.14 1.57" xyz="-0.1265 -0.061 0.166"/>
      <material name="black">
      </material>
    </visual>
    <collision>
      <geometry>
        <mesh filename="allegro_v5/meshes/t3_set.stl" scale="0.001 0.001 0.001"/>
      </geometry>
      <origin rpy="3.14 3.14 1.57" xyz="-0.1265 -0.061 0.166"/>
    </collision>
    <inertial>
      <mass value="0.03607"/>
      <origin rpy="0 0 0" xyz="0 0 0"/>
      <inertia ixx="3.7e-06" ixy="2.43e-07" ixz="6.48e-07" iyy="1.54e-05" iyz="-3.11e-08" izz="1.388e-05"/>
    </inertial>
  </link>
  <joint name="joint_14_0" type="revolute">
    <axis xyz="0 1 0"/>
    <!--<limit effort="15" lower="-0.54" upper="1.53" velocity="7"/>-->
    <limit effort="15" lower="0.00" upper="1.9" velocity="7"/>
    <parent link="link_13_0"/>
    <child link="link_14_0"/>
    <origin rpy="0 -0.15 0" xyz="0 0 0.00"/>
    <dynamics damping="3" friction="10"/>
  </joint>
  <!-- [LINK 15] -->
  <link name="link_15_0">
    <visual>
      <geometry>
        <mesh filename="allegro_v5/meshes/t4_set.stl" scale="0.001 0.001 0.001"/>
      </geometry>
      <origin rpy="3.14 3.14 1.57" xyz="-0.149 -0.061 0.096"/>
      <material name="black">
      </material>
    </visual>
    <collision>
      <geometry>
        <mesh filename="allegro_v5/meshes/t4_set.stl" scale="0.001 0.001 0.001"/>
      </geometry>
      <origin rpy="3.14 3.14 1.57" xyz="-0.149 -0.061 0.096"/>
    </collision>
    <inertial>
      <mass value="0.0338"/>
      <origin rpy="0 0 0" xyz="0 0 0"/>
      <inertia ixx="2.94e-06" ixy="1.244e-07" ixz="3.52e-07" iyy="1.13e-05" iyz="-3.11e-08" izz="1.06e-05"/>
    </inertial>
  </link>
  <joint name="joint_15_0" type="revolute">
    <axis xyz="0 1 0"/>
    <limit effort="15" lower="-0.09" upper="1.80" velocity="7"/>
    <parent link="link_14_0"/>
    <child link="link_15_0"/>
    <origin xyz="0 0 0.038"/>
    <dynamics damping="3" friction="12"/>
  </joint>
  <!-- [FINGER TIP] -->
  <link name="link_15_0_tip">
    <visual>
      <geometry>
        <mesh filename="allegro_v5/meshes/finger_tip_silicon.stl" scale="0.001 0.001 0.0012"/>
      </geometry>
      <origin rpy="0 0 3.14" xyz="-0.014 0.0545 -0.0172"/>
      <material name="white">
        <color rgba=".9 .9 .9 1"/>
      </material>
    </visual>
    <collision>
      <geometry>
        <mesh filename="allegro_v5/meshes/finger_tip_silicon.stl" scale="0.001 0.001 0.001"/>
      </geometry>
      <origin rpy="0 0 3.14" xyz="-0.014 0.0545 -0.0172"/>
    </collision>
    <inertial>
      <mass value="0.00"/>
      <origin rpy="0 0 0" xyz="0 0 0"/>
      <inertia ixx="9.68e-07" ixy="0" ixz="0" iyy="9.68e-07" iyz="0" izz="9.68e-07"/>
    </inertial>
  </link>
  <joint name="joint_15_0_tip" type="fixed">
    <parent link="link_15_0"/>
    <child link="link_15_0_tip"/>
    <origin rpy="0 0 0" xyz="0 0 0.05"/>
  </joint>
  <!-- ============================================================================= -->
  <!-- THUMB MACRO -->
  <!-- END THUMB MACRO -->
  <!-- THREE FINGER MACRO -->
  <!-- [[END]] THREE FINGER MACRO -->
</robot>
