<robot name="xarm6">

    

    
  <material name="Black">
    <color rgba="0.0 0.0 0.0 1.0" />
  </material>
  <material name="Red">
    <color rgba="0.8 0.0 0.0 1.0" />
  </material>
  <material name="White">
    <color rgba="1.0 1.0 1.0 1.0" />
  </material>
  <material name="Silver">
    <color rgba="0.753 0.753 0.753 1.0" />
  </material>

    

  
  <link name="world" />
  <joint name="world_joint" type="fixed">
    <parent link="world" />
    <child link="link_base" />
    <origin rpy="0 0 0" xyz="0 0 0" />
  </joint>
  <link name="link_base">
    <visual>
      <geometry>
        <mesh filename="xarm/meshes/base.obj" />
      </geometry>
      <origin rpy="0 0 0" xyz="0 0 0" />
      <material name="White" />
    </visual>
    <collision>
      <geometry>
        <mesh filename="xarm/meshes/base.obj" />
      </geometry>
      <origin rpy="0 0 0" xyz="0 0 0" />
    </collision>
    <inertial>
      <origin rpy="0 0 0" xyz="0.0 0.0 0.09103" />
      <mass value="2.7" />
      <inertia ixx="0.00494875" ixy="-3.5E-06" ixz="1.25E-05" iyy="0.00494174" iyz="1.67E-06" izz="0.002219" />
    </inertial>
  </link>
  <link name="link1">
    <visual>
      <geometry>
        <mesh filename="xarm/meshes/link1.obj" />
      </geometry>
      <origin rpy="0 0 0" xyz="0 0 0" />
      <material name="White" />
    </visual>
    <collision>
      <geometry>
        <mesh filename="xarm/meshes/link1.obj" />
      </geometry>
      <origin rpy="0 0 0" xyz="0 0 0" />
    </collision>
    <inertial>
      <origin rpy="0 0 0" xyz="-0.002 0.02692 -0.01332" />
      <mass value="2.16" />
      <inertia ixx="0.00539427" ixy="1.095E-05" ixz="1.635E-06" iyy="0.0048979" iyz="0.000793" izz="0.00311573" />
    </inertial>
  </link>
  <joint name="joint1" type="revolute">
    <parent link="link_base" />
    <child link="link1" />
    <origin rpy="-0.002122362144 -0.002407404361 2.55469422e-06" xyz="-0.001549459761 0.0003137374879 0.2656630874" />
    <axis xyz="0 0 1" />
    <limit effort="500.0" lower="-6.28318530718" upper="6.28318530718" velocity="3.14" />
    <dynamics damping="0.0001" friction="0.01" />
  </joint>
  <link name="link2">
    <visual>
      <geometry>
        <mesh filename="xarm/meshes/link2.obj" />
      </geometry>
      <origin rpy="0 0 0" xyz="0 0 0" />
      <material name="White" />
    </visual>
    <collision>
      <geometry>
        <mesh filename="xarm/meshes/link2.obj" />
      </geometry>
      <origin rpy="0 0 0" xyz="0 0 0" />
    </collision>
    <inertial>
      <origin rpy="0 0 0" xyz="0.03531 -0.21398 0.03386" />
      <mass value="1.71" />
      <inertia ixx="0.0248674" ixy="-0.00430651" ixz="-0.00067797" iyy="0.00485548" iyz="0.00457245" izz="0.02387827" />
    </inertial>
  </link>
  <joint name="joint2" type="revolute">
    <parent link="link1" />
    <child link="link2" />
    <origin rpy="-1.570928454 0.002410640009 -0.003248984925" xyz="0.0001424681977 -4.629010846e-07 -5.750245766e-11" />
    <axis xyz="0 0 1" />
    <limit effort="50.0" lower="-2.059" upper="2.0944" velocity="3.14" />
    <dynamics damping="0.0001" friction="0.01" />
  </joint>
  <link name="link3">
    <visual>
      <geometry>
        <mesh filename="xarm/meshes/link3.obj" />
      </geometry>
      <origin rpy="0 0 0" xyz="0 0 0" />
      <material name="White" />
    </visual>
    <collision>
      <geometry>
        <mesh filename="xarm/meshes/link3.obj" />
      </geometry>
      <origin rpy="0 0 0" xyz="0 0 0" />
    </collision>
    <inertial>
      <origin rpy="0 0 0" xyz="0.06781 0.10749 0.01457" />
      <mass value="1.384" />
      <inertia ixx="0.0053694" ixy="0.0014185" ixz="-0.00092094" iyy="0.0032423" iyz="-0.00169178" izz="0.00501731" />
    </inertial>
  </link>
  <joint name="joint3" type="revolute">
    <parent link="link2" />
    <child link="link3" />
    <origin rpy="-0.001330370083 -0.001908135135 -3.037097713e-06" xyz="0.05299152806 -0.2844330966 5.917066301e-05" />
    <axis xyz="0 0 1" />
    <limit effort="32.0" lower="-3.927" upper="0.19198" velocity="3.14" />
    <dynamics damping="0.0001" friction="0.01" />
  </joint>
  <link name="link4">
    <visual>
      <geometry>
        <mesh filename="xarm/meshes/link4.obj" />
      </geometry>
      <origin rpy="0 0 0" xyz="0 0 0" />
      <material name="White" />
    </visual>
    <collision>
      <geometry>
        <mesh filename="xarm/meshes/link4.obj" />
      </geometry>
      <origin rpy="0 0 0" xyz="0 0 0" />
    </collision>
    <inertial>
      <origin rpy="0 0 0" xyz="-0.00021 0.02578 -0.02538" />
      <mass value="1.115" />
      <inertia ixx="0.00439263" ixy="5.028E-05" ixz="1.374E-05" iyy="0.0040077" iyz="0.00045338" izz="0.00110321" />
    </inertial>
  </link>
  <joint name="joint4" type="revolute">
    <parent link="link3" />
    <child link="link4" />
    <origin rpy="-1.57233882 -0.001340431976 -0.002912688535" xyz="0.07818619162 0.3414653838 -0.0005268830573" />
    <axis xyz="0 0 1" />
    <limit effort="32.0" lower="-6.28318530718" upper="6.28318530718" velocity="3.14" />
    <dynamics damping="0.0001" friction="0.01" />
  </joint>
  <link name="link5">
    <visual>
      <geometry>
        <mesh filename="xarm/meshes/link5.obj" />
      </geometry>
      <origin rpy="0 0 0" xyz="0 0 0" />
      <material name="White" />
    </visual>
    <collision>
      <geometry>
        <mesh filename="xarm/meshes/link5.obj" />
      </geometry>
      <origin rpy="0 0 0" xyz="0 0 0" />
    </collision>
    <inertial>
      <origin rpy="0 0 0" xyz="0.05428 0.01781 0.00543" />
      <mass value="1.275" />
      <inertia ixx="0.001202758" ixy="0.000492428" ixz="-0.00039147" iyy="0.0022876" iyz="-1.235E-04" izz="0.0026866" />
    </inertial>
  </link>
  <joint name="joint5" type="revolute">
    <parent link="link4" />
    <child link="link5" />
    <origin rpy="1.586496472 -0.002846868243 -0.006097148173" xyz="-0.0003658483038 -0.002068420639 -3.251171802e-05" />
    <axis xyz="0 0 1" />
    <limit effort="32.0" lower="-1.69297" upper="3.14159265359" velocity="3.14" />
    <dynamics damping="0.0001" friction="0.01" />
  </joint>
  <link name="link6">
    <visual>
      <geometry>
        <mesh filename="xarm/meshes/link6.obj" />
      </geometry>
      <origin rpy="0 0 0" xyz="0 0 0" />
      <material name="Silver" />
    </visual>
    <collision>
      <geometry>
        <mesh filename="xarm/meshes/link6.obj" />
      </geometry>
      <origin rpy="0 0 0" xyz="0 0 0" />
    </collision>
    <inertial>
      <origin rpy="0 0 0" xyz="0 0.00064 -0.00952" />
      <mass value="0.1096" />
      <inertia ixx="4.5293E-05" ixy="0" ixz="0" iyy="4.8111E-05" iyz="0" izz="7.9715E-05" />
    </inertial>
  </link>
  <joint name="joint6" type="revolute">
    <parent link="link5" />
    <child link="link6" />
    <origin rpy="-1.581605673 0.005988837685 -0.000228099816" xyz="0.07646542042 0.0960168317 -0.0008099220577" />
    <axis xyz="0 0 1" />
    <limit effort="20.0" lower="-6.28318530718" upper="6.28318530718" velocity="3.14" />
    <dynamics damping="0.0001" friction="0.01" />
  </joint>  
</robot>