<?xml version="1.0" encoding="utf-8"?>
<!-- =================================================================================== -->
<!-- |    This document was autogenerated from xarm.urdf and                         | -->
<!-- |    gripper_2f_85/urdf/robotiq_2f_85_macro.urdf.xacro.                         | -->
<!-- |    EDITING THIS FILE BY HAND IS NOT RECOMMENDED.                              | -->
<!-- =================================================================================== -->
<robot name="xarm_robotiq_2f_85">
  <material name="Black">
    <color rgba="0.0 0.0 0.0 1.0"/>
  </material>
  <material name="Red">
    <color rgba="0.8 0.0 0.0 1.0"/>
  </material>
  <material name="White">
    <color rgba="1.0 1.0 1.0 1.0"/>
  </material>
  <material name="Silver">
    <color rgba="0.753 0.753 0.753 1.0"/>
  </material>
  <link name="world"/>
  <joint name="world_joint" type="fixed">
    <parent link="world"/>
    <child link="link_base"/>
    <origin rpy="0 0 0" xyz="0 0 0"/>
  </joint>
  <link name="link_base">
    <visual>
      <geometry>
        <mesh filename="xarm/meshes/base.obj"/>
      </geometry>
      <origin rpy="0 0 0" xyz="0 0 0"/>
      <material name="White"/>
    </visual>
    <collision>
      <geometry>
        <mesh filename="xarm/meshes/base.obj"/>
      </geometry>
      <origin rpy="0 0 0" xyz="0 0 0"/>
    </collision>
    <inertial>
      <origin rpy="0 0 0" xyz="0.0 0.0 0.09103"/>
      <mass value="2.7"/>
      <inertia ixx="0.00494875" ixy="-3.5E-06" ixz="1.25E-05" iyy="0.00494174" iyz="1.67E-06" izz="0.002219"/>
    </inertial>
  </link>
  <link name="link1">
    <visual>
      <geometry>
        <mesh filename="xarm/meshes/link1.obj"/>
      </geometry>
      <origin rpy="0 0 0" xyz="0 0 0"/>
      <material name="White"/>
    </visual>
    <collision>
      <geometry>
        <mesh filename="xarm/meshes/link1.obj"/>
      </geometry>
      <origin rpy="0 0 0" xyz="0 0 0"/>
    </collision>
    <inertial>
      <origin rpy="0 0 0" xyz="-0.002 0.02692 -0.01332"/>
      <mass value="2.16"/>
      <inertia ixx="0.00539427" ixy="1.095E-05" ixz="1.635E-06" iyy="0.0048979" iyz="0.000793" izz="0.00311573"/>
    </inertial>
  </link>
  <joint name="joint1" type="revolute">
    <parent link="link_base"/>
    <child link="link1"/>
    <origin rpy="0.0029317450243979692 -0.0009082292672246695 -1.3313493809619104e-06" xyz="-0.0010697057005017996 -0.0004954295000061393 0.2672901153564453"/>
    <axis xyz="0 0 1"/>
    <limit effort="50.0" lower="-6.283185307179586" upper="6.283185307179586" velocity="3.14"/>
    <dynamics damping="1.0" friction="1.0"/>
  </joint>
  <link name="link2">
    <visual>
      <geometry>
        <mesh filename="xarm/meshes/link2.obj"/>
      </geometry>
      <origin rpy="0 0 0" xyz="0 0 0"/>
      <material name="White"/>
    </visual>
    <collision>
      <geometry>
        <mesh filename="xarm/meshes/link2.obj"/>
      </geometry>
      <origin rpy="0 0 0" xyz="0 0 0"/>
    </collision>
    <inertial>
      <origin rpy="0 0 0" xyz="0.03531 -0.21398 0.03386"/>
      <mass value="1.71"/>
      <inertia ixx="0.0248674" ixy="-0.00430651" ixz="-0.00067797" iyy="0.00485548" iyz="0.00457245" izz="0.02387827"/>
    </inertial>
  </link>
  <joint name="joint2" type="revolute">
    <parent link="link1"/>
    <child link="link2"/>
    <origin rpy="-1.569319725036621 0.0009085785131901503 0.00047865818487480283" xyz="0.0004169351886957884 1.990151190511824e-07 -9.557788588354654e-11"/>
    <axis xyz="0 0 1"/>
    <limit effort="50.0" lower="-2.059" upper="2.0944" velocity="3.14"/>
    <dynamics damping="1.0" friction="1.0"/>
  </joint>
  <link name="link3">
    <visual>
      <geometry>
        <mesh filename="xarm/meshes/link3.obj"/>
      </geometry>
      <origin rpy="0 0 0" xyz="0 0 0"/>
      <material name="White"/>
    </visual>
    <collision>
      <geometry>
        <mesh filename="xarm/meshes/link3.obj"/>
      </geometry>
      <origin rpy="0 0 0" xyz="0 0 0"/>
    </collision>
    <inertial>
      <origin rpy="0 0 0" xyz="0.06781 0.10749 0.01457"/>
      <mass value="1.384"/>
      <inertia ixx="0.0053694" ixy="0.0014185" ixz="-0.00092094" iyy="0.0032423" iyz="-0.00169178" izz="0.00501731"/>
    </inertial>
  </link>
  <joint name="joint3" type="revolute">
    <parent link="link2"/>
    <child link="link3"/>
    <origin rpy="0.0022015380673110485 0.0029121467377990484 -3.740997499335208e-06" xyz="0.05311902239918709 -0.28416889905929565 -0.0012295488268136978"/>
    <axis xyz="0 0 1"/>
    <limit effort="32.0" lower="-3.927" upper="0.19198" velocity="3.14"/>
    <dynamics damping="1.0" friction="1.0"/>
  </joint>
  <link name="link4">
    <visual>
      <geometry>
        <mesh filename="xarm/meshes/link4.obj"/>
      </geometry>
      <origin rpy="0 0 0" xyz="0 0 0"/>
      <material name="White"/>
    </visual>
    <collision>
      <geometry>
        <mesh filename="xarm/meshes/link4.obj"/>
      </geometry>
      <origin rpy="0 0 0" xyz="0 0 0"/>
    </collision>
    <inertial>
      <origin rpy="0 0 0" xyz="-0.00021 0.02578 -0.02538"/>
      <mass value="1.115"/>
      <inertia ixx="0.00439263" ixy="5.028E-05" ixz="1.374E-05" iyy="0.0040077" iyz="0.00045338" izz="0.00110321"/>
    </inertial>
  </link>
  <joint name="joint4" type="revolute">
    <parent link="link3"/>
    <child link="link4"/>
    <origin rpy="-1.574359655380249 -0.0024353251792490482 -0.0006168704712763429" xyz="0.07675719261169434 0.34063249826431274 -0.0012138120364397764"/>
    <axis xyz="0 0 1"/>
    <limit effort="32.0" lower="-6.283185307179586" upper="6.283185307179586" velocity="3.14"/>
    <dynamics damping="1.0" friction="1.0"/>
  </joint>
  <link name="link5">
    <visual>
      <geometry>
        <mesh filename="xarm/meshes/link5.obj"/>
      </geometry>
      <origin rpy="0 0 0" xyz="0 0 0"/>
      <material name="White"/>
    </visual>
    <collision>
      <geometry>
        <mesh filename="xarm/meshes/link5.obj"/>
      </geometry>
      <origin rpy="0 0 0" xyz="0 0 0"/>
    </collision>
    <inertial>
      <origin rpy="0 0 0" xyz="0.05428 0.01781 0.00543"/>
      <mass value="1.275"/>
      <inertia ixx="0.001202758" ixy="0.000492428" ixz="-0.00039147" iyy="0.0022876" iyz="-1.235E-04" izz="0.0026866"/>
    </inertial>
  </link>
  <joint name="joint5" type="revolute">
    <parent link="link4"/>
    <child link="link5"/>
    <origin rpy="1.5865709781646729 -0.0005549316992983222 -0.01099355798214674" xyz="-0.00036679222830571234 -0.0028716931119561195 -4.53642824140843e-05"/>
    <axis xyz="0 0 1"/>
    <limit effort="32.0" lower="-1.69297" upper="3.141592653589793" velocity="3.14"/>
    <dynamics damping="1.0" friction="1.0"/>
  </joint>
  <link name="link6">
    <visual>
      <geometry>
        <mesh filename="xarm/meshes/link6.obj"/>
      </geometry>
      <origin rpy="0 0 0" xyz="0 0 0"/>
      <material name="Silver"/>
    </visual>
    <collision>
      <geometry>
        <mesh filename="xarm/meshes/link6.obj"/>
      </geometry>
      <origin rpy="0 0 0" xyz="0 0 0"/>
    </collision>
    <inertial>
      <origin rpy="0 0 0" xyz="0 0.00064 -0.00952"/>
      <mass value="0.1096"/>
      <inertia ixx="4.5293E-05" ixy="0" ixz="0" iyy="4.8111E-05" iyz="0" izz="7.9715E-05"/>
    </inertial>
  </link>
  <joint name="joint6" type="revolute">
    <parent link="link5"/>
    <child link="link6"/>
    <origin rpy="-1.5900110006332397 0.011010788381099701 -0.0004998284275643528" xyz="0.07698416709899902 0.09629102051258087 -0.001671688398346305"/>
    <axis xyz="0 0 1"/>
    <limit effort="20.0" lower="-6.283185307179586" upper="6.283185307179586" velocity="3.14"/>
    <dynamics damping="1.0" friction="1.0"/>
  </joint>
  <!-- Robotiq 2F-85 expanded from gripper_2f_85/urdf/robotiq_2f_85_macro.urdf.xacro; ros2_control intentionally omitted. -->
  <link name="robotiq_85_base_link">
    <visual>
      <geometry>
        <mesh filename="gripper_2f_85/meshes/visual/2f_85/robotiq_base.dae"/>
      </geometry>
    </visual>
    <collision>
      <geometry>
        <mesh filename="gripper_2f_85/meshes/collision/2f_85/robotiq_base.stl"/>
      </geometry>
    </collision>
    <inertial>
      <origin xyz="0.0 2.274e-05 0.03232288" rpy="0 0 0"/>
      <mass value="6.6320197e-01"/>
      <inertia ixx="5.1617816e-04" iyy="5.8802208e-04" izz="3.9462776e-04" ixy="2.936e-8" ixz="0.0" iyz="-3.2296e-7"/>
    </inertial>
  </link>
  <link name="robotiq_85_left_knuckle_link">
    <visual>
      <geometry>
        <mesh filename="gripper_2f_85/meshes/visual/2f_85/left_knuckle.dae"/>
      </geometry>
    </visual>
    <collision>
      <geometry>
        <mesh filename="gripper_2f_85/meshes/collision/2f_85/left_knuckle.stl"/>
      </geometry>
    </collision>
    <inertial>
      <origin xyz="0.01213197 0.0002 -0.00058647" rpy="0 0 0"/>
      <mass value="1.384773208e-02"/>
      <inertia ixx="3.5232e-7" iyy="2.31944e-6" izz="2.23136e-6" ixy="0.0" ixz="1.1744e-7" iyz="0"/>
    </inertial>
  </link>
  <link name="robotiq_85_right_knuckle_link">
    <visual>
      <geometry>
        <mesh filename="gripper_2f_85/meshes/visual/2f_85/right_knuckle.dae"/>
      </geometry>
    </visual>
    <collision>
      <geometry>
        <mesh filename="gripper_2f_85/meshes/collision/2f_85/right_knuckle.stl"/>
      </geometry>
    </collision>
    <inertial>
      <origin xyz="-0.01213197 0.0002 -0.00058647" rpy="0 0 0"/>
      <mass value="1.384773208e-02"/>
      <inertia ixx="3.5232e-7" iyy="2.31944e-6" izz="2.23136e-6" ixy="0.0" ixz="-1.1744e-7" iyz="0.0"/>
    </inertial>
  </link>
  <link name="robotiq_85_left_finger_link">
    <visual>
      <geometry>
        <mesh filename="gripper_2f_85/meshes/visual/2f_85/left_finger.dae"/>
      </geometry>
    </visual>
    <collision>
      <geometry>
        <mesh filename="gripper_2f_85/meshes/collision/2f_85/left_finger.stl"/>
      </geometry>
    </collision>
    <inertial>
      <origin xyz="0.00346899 -0.00079447 0.01867121" rpy="0 0 0"/>
      <mass value="4.260376752e-02"/>
      <inertia ixx="1.385792000000000e-05" iyy="1.183208e-05" izz="5.19672e-06" ixy="0.0" ixz="-2.17264e-06" iyz="0.0"/>
    </inertial>
  </link>
  <link name="robotiq_85_right_finger_link">
    <visual>
      <geometry>
        <mesh filename="gripper_2f_85/meshes/visual/2f_85/right_finger.dae"/>
      </geometry>
    </visual>
    <collision>
      <geometry>
        <mesh filename="gripper_2f_85/meshes/collision/2f_85/right_finger.stl"/>
      </geometry>
    </collision>
    <inertial>
      <origin xyz="-0.00346899 -5.53e-06 0.01867121" rpy="0 0 0"/>
      <mass value="4.260376752000000e-02"/>
      <inertia ixx="1.385792e-05" iyy="1.183208e-05" izz="5.19672e-06" ixy="0.0" ixz="2.17264e-06" iyz="0.0"/>
    </inertial>
  </link>
  <link name="robotiq_85_left_inner_knuckle_link">
    <visual>
      <geometry>
        <mesh filename="gripper_2f_85/meshes/visual/2f_85/left_inner_knuckle.dae"/>
      </geometry>
    </visual>
    <collision>
      <geometry>
        <mesh filename="gripper_2f_85/meshes/collision/2f_85/left_inner_knuckle.stl"/>
      </geometry>
    </collision>
    <inertial>
      <origin xyz="0.01897699 0.00015001 0.02247101" rpy="0 0 0"/>
      <mass value="2.969376448e-02"/>
      <inertia ixx="9.57136e-06" iyy="8.69056e-06" izz="8.19144e-06" ixy="0.0" ixz="-3.93424e-06" iyz="0.0"/>
    </inertial>
  </link>
  <link name="robotiq_85_right_inner_knuckle_link">
    <visual>
      <geometry>
        <mesh filename="gripper_2f_85/meshes/visual/2f_85/right_inner_knuckle.dae"/>
      </geometry>
    </visual>
    <collision>
      <geometry>
        <mesh filename="gripper_2f_85/meshes/collision/2f_85/right_inner_knuckle.stl"/>
      </geometry>
    </collision>
    <inertial>
      <origin xyz="-0.01926824 5.001e-05 0.02222178" rpy="0 0 0"/>
      <mass value="2.969376448e-02"/>
      <inertia ixx="9.42456e-06" iyy="8.69056e-06" izz="8.33824e-06" ixy="0.0" ixz="3.9636e-06" iyz="0.0"/>
    </inertial>
  </link>
  <link name="robotiq_85_left_finger_tip_link">
    <visual>
      <geometry>
        <mesh filename="gripper_2f_85/meshes/visual/2f_85/left_finger_tip.dae"/>
      </geometry>
    </visual>
    <collision>
      <geometry>
        <mesh filename="gripper_2f_85/meshes/collision/2f_85/left_finger_tip.stl"/>
      </geometry>
      <surface>
        <friction>
          <ode>
            <mu1>100000.0</mu1>
            <mu2>100000.0</mu2>
          </ode>
        </friction>
        <contact>
          <ode>
            <kp>1e+5</kp>
            <kd>1</kd>
            <soft_cfm>0</soft_cfm>
            <soft_erp>0.2</soft_erp>
            <minDepth>0.002</minDepth>
            <maxVel>0</maxVel>
          </ode>
        </contact>
      </surface>
    </collision>
    <inertial>
      <origin xyz="-0.01456706 -0.0008 0.01649701" rpy="0 0 0"/>
      <mass value="4.268588744e-02"/>
      <inertia ixx="1.048152e-05" iyy="1.197888e-05" izz="4.22784e-06" ixy="0.0" ixz="3.5232e-6" iyz="0.0"/>
    </inertial>
  </link>
  <link name="robotiq_85_right_finger_tip_link">
    <visual>
      <geometry>
        <mesh filename="gripper_2f_85/meshes/visual/2f_85/right_finger_tip.dae"/>
      </geometry>
    </visual>
    <collision>
      <geometry>
        <mesh filename="gripper_2f_85/meshes/collision/2f_85/right_finger_tip.stl"/>
      </geometry>
      <surface>
        <friction>
          <ode>
            <mu1>100000.0</mu1>
            <mu2>100000.0</mu2>
          </ode>
        </friction>
        <contact>
          <ode>
            <kp>1e+5</kp>
            <kd>1</kd>
            <soft_cfm>0</soft_cfm>
            <soft_erp>0.2</soft_erp>
            <minDepth>0.002</minDepth>
            <maxVel>0</maxVel>
          </ode>
        </contact>
      </surface>
    </collision>
    <inertial>
      <origin xyz="0.01456706 5e-05 0.01649701" rpy="0 0 0"/>
      <mass value="4.268588744e-02"/>
      <inertia ixx="1.048152e-05" iyy="1.197888e-05" izz="4.22784e-06" ixy="0.0" ixz="-3.5232e-06" iyz="0.0"/>
    </inertial>
  </link>
  <joint name="robotiq_85_base_joint" type="fixed">
    <parent link="link6"/>
    <child link="robotiq_85_base_link"/>
    <origin xyz="0 0 0" rpy="0 0 0"/>
  </joint>
  <joint name="robotiq_85_left_knuckle_joint" type="revolute">
    <parent link="robotiq_85_base_link"/>
    <child link="robotiq_85_left_knuckle_link"/>
    <axis xyz="0 -1 0"/>
    <origin xyz="0.03060114 0.0 0.05490452" rpy="0 0 0"/>
    <limit lower="0.0" upper="0.8" velocity="0.5" effort="50"/>
  </joint>
  <joint name="robotiq_85_right_knuckle_joint" type="revolute">
    <parent link="robotiq_85_base_link"/>
    <child link="robotiq_85_right_knuckle_link"/>
    <axis xyz="0 -1 0"/>
    <origin xyz="-0.03060114 0.0 0.05490452" rpy="0 0 0"/>
    <limit lower="-0.8" upper="0.0" velocity="0.5" effort="50"/>
    <mimic joint="robotiq_85_left_knuckle_joint" multiplier="-1"/>
  </joint>
  <joint name="robotiq_85_left_finger_joint" type="fixed">
    <parent link="robotiq_85_left_knuckle_link"/>
    <child link="robotiq_85_left_finger_link"/>
    <origin xyz="0.03152616 0.0 -0.00376347" rpy="0 0 0"/>
  </joint>
  <joint name="robotiq_85_right_finger_joint" type="fixed">
    <parent link="robotiq_85_right_knuckle_link"/>
    <child link="robotiq_85_right_finger_link"/>
    <origin xyz="-0.03152616 0.0 -0.00376347" rpy="0 0 0"/>
  </joint>
  <joint name="robotiq_85_left_inner_knuckle_joint" type="revolute">
    <parent link="robotiq_85_base_link"/>
    <child link="robotiq_85_left_inner_knuckle_link"/>
    <axis xyz="0 -1 0"/>
    <origin xyz="0.0127 0.0 0.06142" rpy="0 0 0"/>
    <mimic joint="robotiq_85_left_knuckle_joint"/>
    <limit lower="0.0" upper="0.8" velocity="0.5" effort="50"/>
  </joint>
  <joint name="robotiq_85_right_inner_knuckle_joint" type="revolute">
    <parent link="robotiq_85_base_link"/>
    <child link="robotiq_85_right_inner_knuckle_link"/>
    <axis xyz="0 -1 0"/>
    <origin xyz="-0.0127 0.0 0.06142" rpy="0 0 0"/>
    <mimic joint="robotiq_85_left_knuckle_joint" multiplier="-1"/>
    <limit lower="-0.8" upper="0.0" velocity="0.5" effort="50"/>
  </joint>
  <joint name="robotiq_85_left_finger_tip_joint" type="revolute">
    <parent link="robotiq_85_left_finger_link"/>
    <child link="robotiq_85_left_finger_tip_link"/>
    <axis xyz="0 -1 0"/>
    <origin xyz="0.00563134 0.0 0.04718515" rpy="0 0 0"/>
    <mimic joint="robotiq_85_left_knuckle_joint" multiplier="-1"/>
    <limit lower="-0.8" upper="0.0" velocity="0.5" effort="50"/>
  </joint>
  <joint name="robotiq_85_right_finger_tip_joint" type="revolute">
    <parent link="robotiq_85_right_finger_link"/>
    <child link="robotiq_85_right_finger_tip_link"/>
    <axis xyz="0 -1 0"/>
    <origin xyz="-0.00563134 0.0 0.04718515" rpy="0 0 0"/>
    <mimic joint="robotiq_85_left_knuckle_joint"/>
    <limit lower="0.0" upper="0.8" velocity="0.5" effort="50"/>
  </joint>
</robot>
