<?xml version='1.0' encoding='utf-8'?>
<robot name="fr3_inspire_right">
  <material name="Black">
    <color rgba="0.0 0.0 0.0 1.0" />
  </material>
  <material name="Red">
    <color rgba="0.8 0.0 0.0 1.0" />
  </material>
  <material name="White">
    <color rgba="1.0 1.0 1.0 1.0" />
  </material>
  <material name="Silver">
    <color rgba="0.753 0.753 0.753 1.0" />
  </material>
  <link name="base" />
  <link name="fr3_link0">
    <visual name="fr3_link0_visual">
      <geometry>
        <mesh filename="./meshes/robot_arms/fr3/visual/link0.dae" />
      </geometry>
    </visual>
    <collision name="fr3_link0_collision">
      <geometry>
        <mesh filename="./meshes/robot_arms/fr3/collision/link0.stl" />
      </geometry>
    </collision>
    <inertial>
      <origin rpy="0 0 0" xyz="-0.0172 0.0004 0.0745" />
      <mass value="2.3966" />
      <inertia ixx="0.009" ixy="0.0" ixz="0.002" iyy="0.0115" iyz="0.0" izz="0.0085" />
    </inertial>
  </link>
  <link name="fr3_link1">
    <visual name="fr3_link1_visual">
      <geometry>
        <mesh filename="./meshes/robot_arms/fr3/visual/link1.dae" />
      </geometry>
    </visual>
    <collision name="fr3_link1_collision">
      <geometry>
        <mesh filename="./meshes/robot_arms/fr3/collision/link1.stl" />
      </geometry>
    </collision>
    <inertial>
      <origin rpy="0 0 0" xyz="0.0000004128 -0.0181251324 -0.0386035970" />
      <mass value="2.9274653454" />
      <inertia ixx="0.023927316485107913" ixy="1.3317903455714081e-05" ixz="-0.00011404774918616684" iyy="0.0224821613275756" iyz="-0.0019950320628240115" izz="0.006350098258530016" />
    </inertial>
  </link>
  <link name="fr3_link2">
    <visual name="fr3_link2_visual">
      <geometry>
        <mesh filename="./meshes/robot_arms/fr3/visual/link2.dae" />
      </geometry>
    </visual>
    <collision name="fr3_link2_collision">
      <geometry>
        <mesh filename="./meshes/robot_arms/fr3/collision/link2.stl" />
      </geometry>
    </collision>
    <inertial>
      <origin rpy="0 0 0" xyz="0.0031828864 -0.0743221644 0.0088146084" />
      <mass value="2.9355370338" />
      <inertia ixx="0.041938946257609425" ixy="0.00020257331521090626" ixz="0.004077784227179924" iyy="0.02514514885014724" iyz="-0.0042252158006570156" izz="0.06170214472888839" />
    </inertial>
  </link>
  <link name="fr3_link3">
    <visual name="fr3_link3_visual">
      <geometry>
        <mesh filename="./meshes/robot_arms/fr3/visual/link3.dae" />
      </geometry>
    </visual>
    <collision name="fr3_link3_collision">
      <geometry>
        <mesh filename="./meshes/robot_arms/fr3/collision/link3.stl" />
      </geometry>
    </collision>
    <inertial>
      <origin rpy="0 0 0" xyz="0.0407015686 -0.0048200565 -0.0289730823" />
      <mass value="2.2449013699" />
      <inertia ixx="0.02410142547240885" ixy="0.002404694559042109" ixz="-0.002856269270114313" iyy="0.01974053266708178" iyz="-0.002104212683891874" izz="0.019044494482244823" />
    </inertial>
  </link>
  <link name="fr3_link4">
    <visual name="fr3_link4_visual">
      <geometry>
        <mesh filename="./meshes/robot_arms/fr3/visual/link4.dae" />
      </geometry>
    </visual>
    <collision name="fr3_link4_collision">
      <geometry>
        <mesh filename="./meshes/robot_arms/fr3/collision/link4.stl" />
      </geometry>
    </collision>
    <inertial>
      <origin rpy="0 0 0" xyz="-0.0459100965 0.0630492960 -0.0085187868" />
      <mass value="2.6155955791" />
      <inertia ixx="0.03452998321913202" ixy="0.01322552265982813" ixz="0.01015142998484113" iyy="0.028881621933049058" iyz="-0.0009762833870704552" izz="0.04125471171146641" />
    </inertial>
  </link>
  <link name="fr3_link5">
    <visual name="fr3_link5_visual">
      <geometry>
        <mesh filename="./meshes/robot_arms/fr3/visual/link5.dae" />
      </geometry>
    </visual>
    <collision name="fr3_link5_collision">
      <geometry>
        <mesh filename="./meshes/robot_arms/fr3/collision/link5.stl" />
      </geometry>
    </collision>
    <inertial>
      <origin rpy="0 0 0" xyz="-0.0016039605 0.0292536262 -0.0972965990" />
      <mass value="2.3271207594" />
      <inertia ixx="0.051610278463662895" ixy="-0.005715173387783472" ixz="-0.0035673167625872135" iyy="0.04787729713371481" iyz="0.010673985108535986" izz="0.016423625579357254" />
    </inertial>
  </link>
  <link name="fr3_link6">
    <visual name="fr3_link6_visual">
      <geometry>
        <mesh filename="./meshes/robot_arms/fr3/visual/link6.dae" />
      </geometry>
    </visual>
    <collision name="fr3_link6_collision">
      <geometry>
        <mesh filename="./meshes/robot_arms/fr3/collision/link6.stl" />
      </geometry>
    </collision>
    <inertial>
      <origin rpy="0 0 0" xyz="0.0597131221 -0.0410294666 -0.0101692726" />
      <mass value="1.8170376524" />
      <inertia ixx="0.005412333594383447" ixy="0.006193456360285834" ixz="0.0014219289306117652" iyy="0.014058329545509979" iyz="-0.0013140753741120031" izz="0.016080817924212554" />
    </inertial>
  </link>
  <link name="fr3_link7">
    <visual name="fr3_link7_visual">
      <geometry>
        <mesh filename="./meshes/robot_arms/fr3/visual/link7.dae" />
      </geometry>
    </visual>
    <collision name="fr3_link7_collision">
      <geometry>
        <mesh filename="./meshes/robot_arms/fr3/collision/link7.stl" />
      </geometry>
    </collision>
    <inertial>
      <origin rpy="0 0 0" xyz="0.0045225817 0.0086261921 -0.0161633251" />
      <mass value="0.6271432862" />
      <inertia ixx="0.00021092389150104718" ixy="-2.433299114461931e-05" ixz="4.564480393778983e-05" iyy="0.00017718568002411474" iyz="8.744070223226438e-05" izz="5.993190599659971e-05" />
    </inertial>
  </link>
  <link name="fr3_link8" />
  <joint name="fr3_base_joint" type="fixed">
    <parent link="base" />
    <child link="fr3_link0" />
    <origin rpy="0 0 0" xyz="0 0 0" />
  </joint>
  <joint name="fr3_joint1" type="revolute">
    <origin rpy="0 0 0" xyz="0 0 0.333" />
    <parent link="fr3_link0" />
    <child link="fr3_link1" />
    <axis xyz="0 0 1" />
    <limit effort="87.0" lower="-2.9007" upper="2.9007" velocity="2.62" />
  </joint>
  <joint name="fr3_joint2" type="revolute">
    <origin rpy="-1.570796326794897 0 0" xyz="0 0 0" />
    <parent link="fr3_link1" />
    <child link="fr3_link2" />
    <axis xyz="0 0 1" />
    <limit effort="87.0" lower="-1.8361" upper="1.8361" velocity="2.62" />
  </joint>
  <joint name="fr3_joint3" type="revolute">
    <origin rpy="1.570796326794897 0 0" xyz="0 -0.316 0" />
    <parent link="fr3_link2" />
    <child link="fr3_link3" />
    <axis xyz="0 0 1" />
    <limit effort="87.0" lower="-2.9007" upper="2.9007" velocity="2.62" />
  </joint>
  <joint name="fr3_joint4" type="revolute">
    <origin rpy="1.570796326794897 0 0" xyz="0.0825 0 0" />
    <parent link="fr3_link3" />
    <child link="fr3_link4" />
    <axis xyz="0 0 1" />
    <limit effort="87.0" lower="-3.077" upper="-0.1169" velocity="2.62" />
  </joint>
  <joint name="fr3_joint5" type="revolute">
    <origin rpy="-1.570796326794897 0 0" xyz="-0.0825 0.384 0" />
    <parent link="fr3_link4" />
    <child link="fr3_link5" />
    <axis xyz="0 0 1" />
    <limit effort="12.0" lower="-2.8763" upper="2.8763" velocity="5.26" />
  </joint>
  <joint name="fr3_joint6" type="revolute">
    <origin rpy="1.570796326794897 0 0" xyz="0 0 0" />
    <parent link="fr3_link5" />
    <child link="fr3_link6" />
    <axis xyz="0 0 1" />
    <limit effort="12.0" lower="0.4398" upper="4.6216" velocity="4.18" />
  </joint>
  <joint name="fr3_joint7" type="revolute">
    <origin rpy="1.570796326794897 0 0" xyz="0.088 0 0" />
    <parent link="fr3_link6" />
    <child link="fr3_link7" />
    <axis xyz="0 0 1" />
    <limit effort="12.0" lower="-3.0508" upper="3.0508" velocity="5.26" />
  </joint>
  <joint name="fr3_joint8" type="fixed">
    <origin rpy="0 0 0" xyz="0 0 0.107" />
    <parent link="fr3_link7" />
    <child link="fr3_link8" />
  </joint>
  <joint name="flange_to_hand" type="fixed">
    <parent link="fr3_link8" />
    <child link="base_link" />
    <origin xyz="0 0 0.04" rpy="-3.14159 0 -0.7854" />
  </joint>
  <link name="base_link">
    <inertial>
      <origin rpy="0 0 0" xyz="-4.91696692515552E-05 -0.00297934158474353 -0.0724838074966582" />
      <mass value="0.260034351097693" />
      <inertia ixx="0.000240584294557413" ixy="1.12900341553271E-06" ixz="5.34716263010627E-07" iyy="0.000284423438713157" iyz="-1.41174524262487E-05" izz="0.000155854672271766" />
    </inertial>
    <visual>
      <origin rpy="0 0 0" xyz="0 0 0" />
      <geometry>
        <mesh filename="./meshes/inspire_right/base_link.STL" />
      </geometry>
      <material name="">
        <color rgba="1 1 1 1" />
      </material>
    </visual>
    <collision>
      <origin rpy="0 0 0" xyz="0 0 0" />
      <geometry>
        <mesh filename="./meshes/inspire_right/base_link.STL" />
      </geometry>
    </collision>
  </link>
  <link name="right_thumb_1">
    <inertial>
      <origin rpy="0 0 0" xyz="-0.00178423179132732 0.000649410769092404 0.00488589310434417" />
      <mass value="0.00115518743162309" />
      <inertia ixx="5.98911473694571E-08" ixy="-8.04324266712912E-09" ixz="-3.29346964287939E-09" iyy="4.07201940087006E-08" iyz="1.1987242259973E-09" izz="6.18161684388651E-08" />
    </inertial>
    <visual>
      <origin rpy="0 0 0" xyz="0 0 0" />
      <geometry>
        <mesh filename="./meshes/inspire_right/right_thumb_1.STL" />
      </geometry>
      <material name="">
        <color rgba="1 1 1 1" />
      </material>
    </visual>
    <collision>
      <origin rpy="0 0 0" xyz="0 0 0" />
      <geometry>
        <mesh filename="./meshes/inspire_right/right_thumb_1.STL" />
      </geometry>
    </collision>
  </link>
  <link name="right_thumb_2">
    <inertial>
      <origin rpy="0 0 0" xyz="0.0141071308121962 0.0132720367246953 -0.00905029680056009" />
      <mass value="0.016" />
      <inertia ixx="1.06573287501608E-06" ixy="-7.61985755293293E-08" ixz="-2.57609628655293E-11" iyy="1.06536320559038E-06" iyz="5.09603163270097E-12" izz="1.39688473195303E-06" />
    </inertial>
    <visual>
      <origin rpy="0 0 0" xyz="0 0 0" />
      <geometry>
        <mesh filename="./meshes/inspire_right/right_thumb_2.STL" />
      </geometry>
      <material name="">
        <color rgba="1 1 1 1" />
      </material>
    </visual>
    <collision>
      <origin rpy="0 0 0" xyz="0 0 0" />
      <geometry>
        <mesh filename="./meshes/inspire_right/right_thumb_2.STL" />
      </geometry>
    </collision>
  </link>
  <link name="right_thumb_3">
    <inertial>
      <origin rpy="0 0 0" xyz="0.00937843602210774 0.00404407714692963 -0.00753947150343212" />
      <mass value="0.012" />
      <inertia ixx="4.67837152048068E-07" ixy="-4.50034504480504E-08" ixz="-7.50604972036399E-11" iyy="3.98821847444202E-07" iyz="-2.80308780973008E-10" izz="4.24792779381109E-07" />
    </inertial>
    <visual>
      <origin rpy="0 0 0" xyz="0 0 0" />
      <geometry>
        <mesh filename="./meshes/inspire_right/right_thumb_3.STL" />
      </geometry>
      <material name="">
        <color rgba="1 1 1 1" />
      </material>
    </visual>
    <collision>
      <origin rpy="0 0 0" xyz="0 0 0" />
      <geometry>
        <mesh filename="./meshes/inspire_right/right_thumb_3.STL" />
      </geometry>
    </collision>
  </link>
  <link name="right_thumb_4">
    <inertial>
      <origin rpy="0 0 0" xyz="0.0109973997213043 0.00131062737520288 -0.0073435196000655" />
      <mass value="0.01" />
      <inertia ixx="6.43617695804108E-07" ixy="-2.57371067432159E-07" ixz="8.83834214745077E-10" iyy="7.63665185138253E-07" iyz="7.47494238463672E-10" izz="9.2568863295396E-07" />
    </inertial>
    <visual>
      <origin rpy="0 0 0" xyz="0 0 0" />
      <geometry>
        <mesh filename="./meshes/inspire_right/right_thumb_4.STL" />
      </geometry>
      <material name="">
        <color rgba="1 1 1 1" />
      </material>
    </visual>
    <collision>
      <origin rpy="0 0 0" xyz="0 0 0" />
      <geometry>
        <mesh filename="./meshes/inspire_right/right_thumb_4.STL" />
      </geometry>
    </collision>
  </link>
  <link name="right_index_1">
    <inertial>
      <origin rpy="0 0 0" xyz="-0.00183546255523356 0.0123552521861834 -0.00664922294778368" />
      <mass value="0.00719999389753264" />
      <inertia ixx="1.28371991025318E-06" ixy="4.21564829206078E-08" ixz="-4.10859703056649E-12" iyy="5.79478432222904E-07" iyz="6.39690407239206E-11" izz="1.32925246769088E-06" />
    </inertial>
    <visual>
      <origin rpy="0 0 0" xyz="0 0 0" />
      <geometry>
        <mesh filename="./meshes/inspire_right/right_index_1.STL" />
      </geometry>
      <material name="">
        <color rgba="1 1 1 1" />
      </material>
    </visual>
    <collision>
      <origin rpy="0 0 0" xyz="0 0 0" />
      <geometry>
        <mesh filename="./meshes/inspire_right/right_index_1.STL" />
      </geometry>
    </collision>
  </link>
  <link name="right_index_2">
    <inertial>
      <origin rpy="0 0 0" xyz="0.000405081354201142 0.0257028143581744 -0.00609275623125877" />
      <mass value="0.0096859422185797" />
      <inertia ixx="2.25513837942244E-06" ixy="4.11239564383381E-07" ixz="-3.94499739658711E-10" iyy="3.91290903748666E-07" iyz="2.79706871963245E-09" izz="2.30200483771215E-06" />
    </inertial>
    <visual>
      <origin rpy="0 0 0" xyz="0 0 0" />
      <geometry>
        <mesh filename="./meshes/inspire_right/right_index_2.STL" />
      </geometry>
      <material name="">
        <color rgba="1 1 1 1" />
      </material>
    </visual>
    <collision>
      <origin rpy="0 0 0" xyz="0 0 0" />
      <geometry>
        <mesh filename="./meshes/inspire_right/right_index_2.STL" />
      </geometry>
    </collision>
  </link>
  <link name="right_middle_1">
    <inertial>
      <origin rpy="0 0 0" xyz="-0.00229221489529491 0.0122787164691098 -0.00664923691414206" />
      <mass value="0.00719999454699651" />
      <inertia ixx="1.27961146095209E-06" ixy="6.81307502326408E-08" ixz="-6.13869092479439E-12" iyy="5.83570383259162E-07" iyz="6.33401074034573E-11" izz="1.32923656099557E-06" />
    </inertial>
    <visual>
      <origin rpy="0 0 0" xyz="0 0 0" />
      <geometry>
        <mesh filename="./meshes/inspire_right/right_middle_1.STL" />
      </geometry>
      <material name="">
        <color rgba="1 1 1 1" />
      </material>
    </visual>
    <collision>
      <origin rpy="0 0 0" xyz="0 0 0" />
      <geometry>
        <mesh filename="./meshes/inspire_right/right_middle_1.STL" />
      </geometry>
    </collision>
  </link>
  <link name="right_middle_2">
    <inertial>
      <origin rpy="0 0 0" xyz="7.55635061812504E-05 0.0274472409700489 -0.00610051225570537" />
      <mass value="0.0104603374357648" />
      <inertia ixx="2.75802690517233E-06" ixy="4.66354191789105E-07" ixz="-3.73412436067728E-12" iyy="4.22418749660047E-07" iyz="7.48571284682703E-11" izz="2.80694637912416E-06" />
    </inertial>
    <visual>
      <origin rpy="0 0 0" xyz="0 0 0" />
      <geometry>
        <mesh filename="./meshes/inspire_right/right_middle_2.STL" />
      </geometry>
      <material name="">
        <color rgba="1 1 1 1" />
      </material>
    </visual>
    <collision>
      <origin rpy="0 0 0" xyz="0 0 0" />
      <geometry>
        <mesh filename="./meshes/inspire_right/right_middle_2.STL" />
      </geometry>
    </collision>
  </link>
  <link name="right_ring_1">
    <inertial>
      <origin rpy="0 0 0" xyz="-0.00240481178777661 0.0122571709475593 -0.00664923625225445" />
      <mass value="0.00719998997814135" />
      <inertia ixx="1.27830103769765E-06" ixy="7.45073064952646E-08" ixz="-6.73880804360017E-12" iyy="5.84879553082369E-07" iyz="6.3350585052199E-11" izz="1.32923557625193E-06" />
    </inertial>
    <visual>
      <origin rpy="0 0 0" xyz="0 0 0" />
      <geometry>
        <mesh filename="./meshes/inspire_right/right_ring_1.STL" />
      </geometry>
      <material name="">
        <color rgba="1 1 1 1" />
      </material>
    </visual>
    <collision>
      <origin rpy="0 0 0" xyz="0 0 0" />
      <geometry>
        <mesh filename="./meshes/inspire_right/right_ring_1.STL" />
      </geometry>
    </collision>
  </link>
  <link name="right_ring_2">
    <inertial>
      <origin rpy="0 0 0" xyz="0.000666830906754845 0.0256973412492289 -0.0060927714564012" />
      <mass value="0.0096859390369724" />
      <inertia ixx="2.26332196405867E-06" ixy="3.92172318180451E-07" ixz="-3.65715440420713E-10" iyy="3.83108005467821E-07" iyz="2.80158649618184E-09" izz="2.30200501593561E-06" />
    </inertial>
    <visual>
      <origin rpy="0 0 0" xyz="0 0 0" />
      <geometry>
        <mesh filename="./meshes/inspire_right/right_ring_2.STL" />
      </geometry>
      <material name="">
        <color rgba="1 1 1 1" />
      </material>
    </visual>
    <collision>
      <origin rpy="0 0 0" xyz="0 0 0" />
      <geometry>
        <mesh filename="./meshes/inspire_right/right_ring_2.STL" />
      </geometry>
    </collision>
  </link>
  <link name="right_little_1">
    <inertial>
      <origin rpy="0 0 0" xyz="-0.00316844591541324 0.0120823779446085 -0.00664923024026526" />
      <mass value="0.00719994987013217" />
      <inertia ixx="1.26624415714453E-06" ixy="1.17303714016617E-07" ixz="-1.15327375313821E-11" iyy="5.96925804604496E-07" iyz="6.36110319315301E-11" izz="1.32922857962206E-06" />
    </inertial>
    <visual>
      <origin rpy="0 0 0" xyz="0 0 0" />
      <geometry>
        <mesh filename="./meshes/inspire_right/right_little_1.STL" />
      </geometry>
      <material name="">
        <color rgba="1 1 1 1" />
      </material>
    </visual>
    <collision>
      <origin rpy="0 0 0" xyz="0 0 0" />
      <geometry>
        <mesh filename="./meshes/inspire_right/right_little_1.STL" />
      </geometry>
    </collision>
  </link>
  <link name="right_little_2">
    <inertial>
      <origin rpy="0 0 0" xyz="0.0204417303421136 -0.00469494170410353 -0.00609999668427265" />
      <mass value="0.0075928240732547" />
      <inertia ixx="2.31546812157118E-07" ixy="-7.27021381773956E-08" ixz="2.3664966486269E-11" iyy="1.27663957628266E-06" iyz="-7.58283070676144E-12" izz="1.23909562166535E-06" />
    </inertial>
    <visual>
      <origin rpy="0 0 0" xyz="0 0 0" />
      <geometry>
        <mesh filename="./meshes/inspire_right/right_little_2.STL" />
      </geometry>
      <material name="">
        <color rgba="1 1 1 1" />
      </material>
    </visual>
    <collision>
      <origin rpy="0 0 0" xyz="0 0 0" />
      <geometry>
        <mesh filename="./meshes/inspire_right/right_little_2.STL" />
      </geometry>
    </collision>
  </link>
  <joint name="right_thumb_1_joint" type="revolute">
    <origin rpy="-3.1416 0 -3.1416" xyz="0.0269 0.02101 -0.069" />
    <parent link="base_link" />
    <child link="right_thumb_1" />
    <axis xyz="0 0 -1" />
    <limit effort="10" lower="0" upper="1.15" velocity="1" />
  </joint>
  <joint name="right_thumb_2_joint" type="revolute">
    <origin rpy="1.5708 0 2.7925" xyz="-0.0063016 0.011924 0.003" />
    <parent link="right_thumb_1" />
    <child link="right_thumb_2" />
    <axis xyz="0 0 1" />
    <limit effort="10" lower="0" upper="0.55" velocity="1" />
  </joint>
  <joint name="right_thumb_3_joint" type="revolute">
    <origin rpy="0 0 0" xyz="0.034968 0.021325 -0.0015" />
    <parent link="right_thumb_2" />
    <child link="right_thumb_3" />
    <axis xyz="0 0 1" />
    <limit effort="10" lower="0" upper="3.14" velocity="1" />
    <mimic joint="right_thumb_2_joint" multiplier="0.60" offset="0" />
  </joint>
  <joint name="right_thumb_4_joint" type="revolute">
    <origin rpy="0 0 0" xyz="0.018887 0.011501 -0.0002" />
    <parent link="right_thumb_3" />
    <child link="right_thumb_4" />
    <axis xyz="0 0 1" />
    <limit effort="10" lower="0" upper="3.14" velocity="1" />
    <mimic joint="right_thumb_2_joint" multiplier="0.8" offset="0" />
  </joint>
  <joint name="right_index_1_joint" type="revolute">
    <origin rpy="-1.5359 0 -1.5708" xyz="0.038679 0.00056467 -0.1564" />
    <parent link="base_link" />
    <child link="right_index_1" />
    <axis xyz="0 0 1" />
    <limit effort="10" lower="0" upper="1.6" velocity="1" />
  </joint>
  <joint name="right_index_2_joint" type="revolute">
    <origin rpy="0 0 0" xyz="-0.0016312 0.032734 -0.00055" />
    <parent link="right_index_1" />
    <child link="right_index_2" />
    <axis xyz="0 0 1" />
    <limit effort="10" lower="0" upper="3.14" velocity="1.1" />
    <mimic joint="right_index_1_joint" multiplier="1.05" offset="0" />
  </joint>
  <joint name="right_middle_1_joint" type="revolute">
    <origin rpy="-1.5708 0 -1.5708" xyz="0.0171 0.00056467 -0.157" />
    <parent link="base_link" />
    <child link="right_middle_1" />
    <axis xyz="0 0 1" />
    <limit effort="10" lower="0" upper="1.6" velocity="1" />
  </joint>
  <joint name="right_middle_2_joint" type="revolute">
    <origin rpy="0 0 0" xyz="-0.0028436 0.032651 -0.00055" />
    <parent link="right_middle_1" />
    <child link="right_middle_2" />
    <axis xyz="0 0 1" />
    <limit effort="10" lower="0" upper="3.14" velocity="1.1" />
    <mimic joint="right_middle_1_joint" multiplier="1.05" offset="0" />
  </joint>
  <joint name="right_ring_1_joint" type="revolute">
    <origin rpy="-1.6232 0 -1.5708" xyz="-0.0045302 0.00056467 -0.15683" />
    <parent link="base_link" />
    <child link="right_ring_1" />
    <axis xyz="0 0 1" />
    <limit effort="10" lower="0" upper="1.6" velocity="1" />
  </joint>
  <joint name="right_ring_2_joint" type="revolute">
    <origin rpy="0 0 0" xyz="-0.0031431 0.032624 -0.00055" />
    <parent link="right_ring_1" />
    <child link="right_ring_2" />
    <axis xyz="0 0 1" />
    <limit effort="10" lower="0" upper="3.14" velocity="1.1" />
    <mimic joint="right_ring_1_joint" multiplier="1.05" offset="0" />
  </joint>
  <joint name="right_little_1_joint" type="revolute">
    <origin rpy="-1.6755 0 -1.5708" xyz="-0.025916 0.00056467 -0.15365" />
    <parent link="base_link" />
    <child link="right_little_1" />
    <axis xyz="0 0 1" />
    <limit effort="10" lower="0" upper="1.6" velocity="1" />
  </joint>
  <joint name="right_little_2_joint" type="revolute">
    <origin rpy="0 0 1.5708" xyz="-0.005182 0.032363 -0.00055" />
    <parent link="right_little_1" />
    <child link="right_little_2" />
    <axis xyz="0 0 1" />
    <limit effort="10" lower="0" upper="3.14" velocity="1.2" />
    <mimic joint="right_little_1_joint" multiplier="1.18" offset="0" />
  </joint>
  <joint name="hand_tcp_joint" type="fixed">
    <parent link="base_link" />
    <child link="hand_tcp" />
    <origin xyz="0 0 -0.12" rpy="0 0 0" />
  </joint>
  <link name="hand_tcp" />
</robot>